Workbook

Sheet 00_Instrucciones
A1: UNIVERSIDAD DE HUÁNUCO · Ingeniería de Sistemas e Informática · Seminario de Tesis III · Sesión 5
A2: Plantilla de formatos – Implementación sistemática de la solución tecnológica
A3: Unidad II · Semana 5 · Indicador: demuestra que los participantes reciben la intervención con la duración, frecuencia e intensidad del protocolo.
A5: Leyenda
C6: Celda editable: escribe o selecciona aquí tus datos.
C7: Celda con fórmula: se calcula sola, no la modifiques.
C8: Resultado clave o resumen.
A10: Hojas y orden de llenado
A11: N.° | B11: Hoja | C11: Qué registras | D11: Frecuencia
A12: 1 | B12: 01_Ficha_Dosis | C12: Parámetros del protocolo: fechas, frecuencia, intensidad, sesión válida y metas | D12: Una vez (validar con el docente)
A13: 2 | B13: 02_Participantes | C13: Relación codificada de participantes (mismos del pretest) | D13: Al inicio y ante cambios
A14: 3 | B14: 03_Cronograma | C14: Sesiones programadas vs. ejecutadas y reprogramaciones | D14: Cada sesión
A15: 4 | B15: 04_Log_Accesos | C15: Exportación del log del sistema (una fila por acceso) | D15: Diaria
A16: 5 | B16: 05_Registro_Uso | C16: Consolidado automático de dosis por participante y semana | D16: Automático
A17: 6 | B17: 06_Bitacora | C17: Hechos observados, acciones tomadas y evidencias | D17: Diaria
A18: 7 | B18: 07_Soporte | C18: Incidencias por nivel (N1, N2, N3) y tiempos de atención | D18: Por incidencia
A19: 8 | B19: 08_Disponibilidad | C19: Horas programadas, horas de caída y checklist funcional | D19: Diaria
A20: 9 | B20: 09_Lista_Cotejo | C20: Verificación Sí/No del cumplimiento del protocolo | D20: Semanal y al cierre
A21: 10 | B21: 10_Rubrica | C21: Rúbrica de implementación (puntaje sobre 20) | D21: Al evaluar
A22: 11 | B22: 11_Portafolio | C22: Índice codificado de evidencias (E-###) | D22: Por evidencia
A23: 12 | B23: 12_Tablero | C23: Indicadores con semáforo y gráficos de seguimiento | D23: Automático
A24: 13 | B24: 13_Actas | C24: Actas de inicio y de cierre de la intervención | D24: Inicio y cierre
A26: Notas importantes
B27: • Las hojas 02, 03, 04, 06, 07, 08 y 11 traen DATOS DE EJEMPLO (app móvil de refuerzo, n = 25, 6 semanas). Reemplázalos por los de tu tesis.
B28: • Para borrar el ejemplo del log: selecciona las celdas amarillas de 04_Log_Accesos (columnas A:G) y presiona Suprimir. Las fórmulas se mantienen.
B29: • Si tu solución no trabaja por sesiones (p. ej., sistema de inventarios), usa el turno de trabajo como "sesión" y las transacciones como "actividades".
B30: • Los participantes se identifican SOLO por código (P01, P02…). No escribas nombres: protección de datos (Ley N.° 29733).
B31: • Nombre del archivo a entregar: S5_ApellidoNombre_Formatos.xlsx

Sheet 01_Ficha_Dosis
A1: UNIVERSIDAD DE HUÁNUCO · Ingeniería de Sistemas e Informática · Seminario de Tesis III · Sesión 5
A2: Formato 1 · Ficha de dosis de la intervención
A3: Completa las celdas amarillas ANTES de iniciar. Los parámetros alimentan todas las demás hojas. Validar con el docente.
B5: Campo | C5: Valor | D5: Nota / criterio
B6: A. Datos del estudio
B7: Título de la tesis | C7: Influencia de una aplicación web móvil con asistente conversacional inteligente en la experiencia de usuario de lectores de Tu Diario Huánuco, 2026 | D7: Idéntico al título aprobado
B8: Tesista | C8: Trujillo Avila, Marcel Alexander Javier; Godoy Condezo, Alejandro Jeanpier
B9: Asesor
B10: Diseño | C10: Preexperimental | D10: Preexperimental (G: O1 X O2) o Cuasiexperimental (GE/GC)
B11: Solución tecnológica (VI) | C11: Aplicación web móvil con asistente conversacional inteligente | D11: La X del diseño
B12: Variable dependiente (VD) | C12: Experiencia de usuario de los lectores | D12: Medida en pretest y postest
B13: B. Duración
B14: Fecha de inicio formal | C14: 46313 | D14: Según acta de inicio
B15: Fecha de cierre | C15: 46353 | D15: Según acta de cierre
B16: Número de semanas de intervención | C16: 6 | D16: Máximo 8 semanas en esta plantilla
B17: Duración en días calendario | C17: =C15-C14+1 -> 41 | D17: Calculado
B18: C. Frecuencia
B19: Sesiones programadas por semana | D19: Ej.: lunes, miércoles y viernes
B20: Días y horario | C20: Lun, Mié, Vie · 16:00–17:00 · Laboratorio 2 | D20: Mismo horario para todos
B21: D. Intensidad
B22: Minutos programados por sesión | D22: Tiempo de la sesión estándar
B23: Minutos mínimos para sesión válida | D23: Criterio definido a priori
B24: Actividades mínimas para sesión válida | D24: Ejercicios, tareas o transacciones
B25: E. Dosis planificada (calculada)
B26: Participantes activos del grupo experimental | C26: =COUNTIF('02_Participantes'!$C$6:$C$65,"GE") -> 0 | D26: Desde 02_Participantes (incluye retirados)
B27: Sesiones planificadas por participante | C27: =C16*C19 -> 0 | D27: Frecuencia × semanas
B28: Minutos planificados por participante | C28: =C27*C22 -> 0 | D28: Sesiones × minutos por sesión
B29: Sesiones planificadas totales | C29: =C27*C26 -> 0 | D29: Sesiones × participantes
B30: F. Metas del protocolo
B31: Umbral de dosis completa por participante | C31: 0.8 | D31: Fijado con el asesor antes de iniciar
B32: Meta: cumplimiento de sesiones | C32: 0.9
B33: Meta: participantes con dosis completa | C33: 0.85
B34: Meta: disponibilidad del sistema | C34: 0.95
B35: Meta: incidencias atendidas a tiempo | C35: 0.9
B36: Meta: periodo cumplido | C36: 1

Sheet 02_Participantes
A1: UNIVERSIDAD DE HUÁNUCO · Ingeniería de Sistemas e Informática · Seminario de Tesis III · Sesión 5
A2: Formato 2 · Relación codificada de participantes
A3: Solo códigos, nunca nombres. Deben ser los mismos participantes del pretest. Capacidad: 60 participantes.
A5: N.° | B5: Código | C5: Grupo | D5: Rindió pretest | E5: Estado | F5: Fecha de retiro | G5: Motivo del retiro | H5: Observación
A6: 1
A7: 2
A8: 3
A9: 4
A10: 5
A11: 6
A12: 7
A13: 8
A14: 9
A15: 10
A16: 11
A17: 12
... A65: 60

Sheet 03_Cronograma
A1: UNIVERSIDAD DE HUÁNUCO · Ingeniería de Sistemas e Informática · Seminario de Tesis III · Sesión 5
A2: Formato 3 · Cronograma de sesiones: programado vs. ejecutado
A3: Registra la fecha real y el estado de cada sesión. Una sesión perdida se reprograma dentro de la misma semana.
A5: Sesión | B5: Semana | C5: Fecha programada | D5: Día | E5: Fecha real | F5: Estado | G5: Motivo / observación | H5: Asistentes | I5: % asistencia
A6: 1 | B6: =IF(C6="","",INT((C6-'01_Ficha_Dosis'!$C$14)/7)+1) -> -2 | C6: 46293 | D6: =IF(C6="","",CHOOSE(WEEKDAY(C6,2),"lun","mar","mié","jue","vie","sáb","dom")) -> lun | I6: =IF(OR(H6="",'01_Ficha_Dosis'!$C$26=0),"",H6/'01_Ficha_Dosis'!$C$26)
A7: 2 | B7: =IF(C7="","",INT((C7-'01_Ficha_Dosis'!$C$14)/7)+1) -> -2 | C7: 46295 | D7: =IF(C7="","",CHOOSE(WEEKDAY(C7,2),"lun","mar","mié","jue","vie","sáb","dom")) -> mié | I7: =IF(OR(H7="",'01_Ficha_Dosis'!$C$26=0),"",H7/'01_Ficha_Dosis'!$C$26)
A8: 3 | B8: =IF(C8="","",INT((C8-'01_Ficha_Dosis'!$C$14)/7)+1) -> -2 | C8: 46297 | D8: =IF(C8="","",CHOOSE(WEEKDAY(C8,2),"lun","mar","mié","jue","vie","sáb","dom")) -> vie | I8: =IF(OR(H8="",'01_Ficha_Dosis'!$C$26=0),"",H8/'01_Ficha_Dosis'!$C$26)
A9: 4 | B9: =IF(C9="","",INT((C9-'01_Ficha_Dosis'!$C$14)/7)+1) -> -1 | C9: 46300 | D9: =IF(C9="","",CHOOSE(WEEKDAY(C9,2),"lun","mar","mié","jue","vie","sáb","dom")) -> lun | I9: =IF(OR(H9="",'01_Ficha_Dosis'!$C$26=0),"",H9/'01_Ficha_Dosis'!$C$26)
A10: 5 | B10: =IF(C10="","",INT((C10-'01_Ficha_Dosis'!$C$14)/7)+1) -> -1 | C10: 46302 | D10: =IF(C10="","",CHOOSE(WEEKDAY(C10,2),"lun","mar","mié","jue","vie","sáb","dom")) -> mié | I10: =IF(OR(H10="",'01_Ficha_Dosis'!$C$26=0),"",H10/'01_Ficha_Dosis'!$C$26)
A11: 6 | B11: =IF(C11="","",INT((C11-'01_Ficha_Dosis'!$C$14)/7)+1) -> -1 | C11: 46304 | D11: =IF(C11="","",CHOOSE(WEEKDAY(C11,2),"lun","mar","mié","jue","vie","sáb","dom")) -> vie | I11: =IF(OR(H11="",'01_Ficha_Dosis'!$C$26=0),"",H11/'01_Ficha_Dosis'!$C$26)
A12: 7 | B12: =IF(C12="","",INT((C12-'01_Ficha_Dosis'!$C$14)/7)+1) -> 0 | C12: 46307 | D12: =IF(C12="","",CHOOSE(WEEKDAY(C12,2),"lun","mar","mié","jue","vie","sáb","dom")) -> lun | I12: =IF(OR(H12="",'01_Ficha_Dosis'!$C$26=0),"",H12/'01_Ficha_Dosis'!$C$26)
A13: 8 | B13: =IF(C13="","",INT((C13-'01_Ficha_Dosis'!$C$14)/7)+1) -> 0 | C13: 46309 | D13: =IF(C13="","",CHOOSE(WEEKDAY(C13,2),"lun","mar","mié","jue","vie","sáb","dom")) -> mié | I13: =IF(OR(H13="",'01_Ficha_Dosis'!$C$26=0),"",H13/'01_Ficha_Dosis'!$C$26)
A14: 9 | B14: =IF(C14="","",INT((C14-'01_Ficha_Dosis'!$C$14)/7)+1) -> 0 | C14: 46311 | D14: =IF(C14="","",CHOOSE(WEEKDAY(C14,2),"lun","mar","mié","jue","vie","sáb","dom")) -> vie | I14: =IF(OR(H14="",'01_Ficha_Dosis'!$C$26=0),"",H14/'01_Ficha_Dosis'!$C$26)
A15: 10 | B15: =IF(C15="","",INT((C15-'01_Ficha_Dosis'!$C$14)/7)+1) -> 1 | C15: 46314 | D15: =IF(C15="","",CHOOSE(WEEKDAY(C15,2),"lun","mar","mié","jue","vie","sáb","dom")) -> lun | I15: =IF(OR(H15="",'01_Ficha_Dosis'!$C$26=0),"",H15/'01_Ficha_Dosis'!$C$26)
A16: 11 | B16: =IF(C16="","",INT((C16-'01_Ficha_Dosis'!$C$14)/7)+1) -> 1 | C16: 46316 | D16: =IF(C16="","",CHOOSE(WEEKDAY(C16,2),"lun","mar","mié","jue","vie","sáb","dom")) -> mié | I16: =IF(OR(H16="",'01_Ficha_Dosis'!$C$26=0),"",H16/'01_Ficha_Dosis'!$C$26)
A17: 12 | B17: =IF(C17="","",INT((C17-'01_Ficha_Dosis'!$C$14)/7)+1) -> 1 | C17: 46318 | D17: =IF(C17="","",CHOOSE(WEEKDAY(C17,2),"lun","mar","mié","jue","vie","sáb","dom")) -> vie | I17: =IF(OR(H17="",'01_Ficha_Dosis'!$C$26=0),"",H17/'01_Ficha_Dosis'!$C$26)
... A23: 18 | B23: =IF(C23="","",INT((C23-'01_Ficha_Dosis'!$C$14)/7)+1) -> 3 | C23: 46332 | D23: =IF(C23="","",CHOOSE(WEEKDAY(C23,2),"lun","mar","mié","jue","vie","sáb","dom")) -> vie | I23: =IF(OR(H23="",'01_Ficha_Dosis'!$C$26=0),"",H23/'01_Ficha_Dosis'!$C$26)
A24: 19 | B24: =IF(C24="","",INT((C24-'01_Ficha_Dosis'!$C$14)/7)+1) | D24: =IF(C24="","",CHOOSE(WEEKDAY(C24,2),"lun","mar","mié","jue","vie","sáb","dom")) | I24: =IF(OR(H24="",'01_Ficha_Dosis'!$C$26=0),"",H24/'01_Ficha_Dosis'!$C$26)
A25: 20 | B25: =IF(C25="","",INT((C25-'01_Ficha_Dosis'!$C$14)/7)+1) | D25: =IF(C25="","",CHOOSE(WEEKDAY(C25,2),"lun","mar","mié","jue","vie","sáb","dom")) | I25: =IF(OR(H25="",'01_Ficha_Dosis'!$C$26=0),"",H25/'01_Ficha_Dosis'!$C$26)
A26: 21 | B26: =IF(C26="","",INT((C26-'01_Ficha_Dosis'!$C$14)/7)+1) | D26: =IF(C26="","",CHOOSE(WEEKDAY(C26,2),"lun","mar","mié","jue","vie","sáb","dom")) | I26: =IF(OR(H26="",'01_Ficha_Dosis'!$C$26=0),"",H26/'01_Ficha_Dosis'!$C$26)
A27: 22 | B27: =IF(C27="","",INT((C27-'01_Ficha_Dosis'!$C$14)/7)+1) | D27: =IF(C27="","",CHOOSE(WEEKDAY(C27,2),"lun","mar","mié","jue","vie","sáb","dom")) | I27: =IF(OR(H27="",'01_Ficha_Dosis'!$C$26=0),"",H27/'01_Ficha_Dosis'!$C$26)
A28: 23 | B28: =IF(C28="","",INT((C28-'01_Ficha_Dosis'!$C$14)/7)+1) | D28: =IF(C28="","",CHOOSE(WEEKDAY(C28,2),"lun","mar","mié","jue","vie","sáb","dom")) | I28: =IF(OR(H28="",'01_Ficha_Dosis'!$C$26=0),"",H28/'01_Ficha_Dosis'!$C$26)
A29: 24 | B29: =IF(C29="","",INT((C29-'01_Ficha_Dosis'!$C$14)/7)+1) | D29: =IF(C29="","",CHOOSE(WEEKDAY(C29,2),"lun","mar","mié","jue","vie","sáb","dom")) | I29: =IF(OR(H29="",'01_Ficha_Dosis'!$C$26=0),"",H29/'01_Ficha_Dosis'!$C$26)
A30: 25 | B30: =IF(C30="","",INT((C30-'01_Ficha_Dosis'!$C$14)/7)+1) | D30: =IF(C30="","",CHOOSE(WEEKDAY(C30,2),"lun","mar","mié","jue","vie","sáb","dom")) | I30: =IF(OR(H30="",'01_Ficha_Dosis'!$C$26=0),"",H30/'01_Ficha_Dosis'!$C$26)
A31: 26 | B31: =IF(C31="","",INT((C31-'01_Ficha_Dosis'!$C$14)/7)+1) | D31: =IF(C31="","",CHOOSE(WEEKDAY(C31,2),"lun","mar","mié","jue","vie","sáb","dom")) | I31: =IF(OR(H31="",'01_Ficha_Dosis'!$C$26=0),"",H31/'01_Ficha_Dosis'!$C$26)
A32: 27 | B32: =IF(C32="","",INT((C32-'01_Ficha_Dosis'!$C$14)/7)+1) | D32: =IF(C32="","",CHOOSE(WEEKDAY(C32,2),"lun","mar","mié","jue","vie","sáb","dom")) | I32: =IF(OR(H32="",'01_Ficha_Dosis'!$C$26=0),"",H32/'01_Ficha_Dosis'!$C$26)
A33: 28 | B33: =IF(C33="","",INT((C33-'01_Ficha_Dosis'!$C$14)/7)+1) | D33: =IF(C33="","",CHOOSE(WEEKDAY(C33,2),"lun","mar","mié","jue","vie","sáb","dom")) | I33: =IF(OR(H33="",'01_Ficha_Dosis'!$C$26=0),"",H33/'01_Ficha_Dosis'!$C$26)
A34: 29 | B34: =IF(C34="","",INT((C34-'01_Ficha_Dosis'!$C$14)/7)+1) | D34: =IF(C34="","",CHOOSE(WEEKDAY(C34,2),"lun","mar","mié","jue","vie","sáb","dom")) | I34: =IF(OR(H34="",'01_Ficha_Dosis'!$C$26=0),"",H34/'01_Ficha_Dosis'!$C$26)
A35: 30 | B35: =IF(C35="","",INT((C35-'01_Ficha_Dosis'!$C$14)/7)+1) | D35: =IF(C35="","",CHOOSE(WEEKDAY(C35,2),"lun","mar","mié","jue","vie","sáb","dom")) | I35: =IF(OR(H35="",'01_Ficha_Dosis'!$C$26=0),"",H35/'01_Ficha_Dosis'!$C$26)
... A45: 40 | B45: =IF(C45="","",INT((C45-'01_Ficha_Dosis'!$C$14)/7)+1) | D45: =IF(C45="","",CHOOSE(WEEKDAY(C45,2),"lun","mar","mié","jue","vie","sáb","dom")) | I45: =IF(OR(H45="",'01_Ficha_Dosis'!$C$26=0),"",H45/'01_Ficha_Dosis'!$C$26)

Sheet 04_Log_Accesos
A1: UNIVERSIDAD DE HUÁNUCO · Ingeniería de Sistemas e Informática · Seminario de Tesis III · Sesión 5
A2: Formato 4 · Registro de accesos (log del sistema)
A3: Pega aquí la exportación de tu log (A:G). Las columnas H:L se calculan. Hora del servidor. Capacidad: 700 registros.
A5: ID | B5: Código | C5: Inicio (fecha-hora) | D5: Fin (fecha-hora) | E5: Módulo | F5: Actividades | G5: Estado | H5: Fecha | I5: Semana | J5: Minutos | K5: ¿Válida? (1/0) | L5: Min. válidos
H6: =IF(C6="","",INT(C6)) | I6: =IF(C6="","",INT((INT(C6)-'01_Ficha_Dosis'!$C$14)/7)+1) | J6: =IF(OR(C6="",D6=""),"",ROUND((D6-C6)*1440,0)) | K6: =IF(J6="","",IF(AND(G6="OK",J6>='01_Ficha_Dosis'!$C$23,F6>='01_Ficha_Dosis'!$C$24,H6>='01_Ficha_Dosis'!$C$14,H6<='01_Ficha_Dosis'!$C$15),1,0)) | L6: =IF(K6=1,J6,0) -> 0
H7: =IF(C7="","",INT(C7)) | I7: =IF(C7="","",INT((INT(C7)-'01_Ficha_Dosis'!$C$14)/7)+1) | J7: =IF(OR(C7="",D7=""),"",ROUND((D7-C7)*1440,0)) | K7: =IF(J7="","",IF(AND(G7="OK",J7>='01_Ficha_Dosis'!$C$23,F7>='01_Ficha_Dosis'!$C$24,H7>='01_Ficha_Dosis'!$C$14,H7<='01_Ficha_Dosis'!$C$15),1,0)) | L7: =IF(K7=1,J7,0) -> 0
H8: =IF(C8="","",INT(C8)) | I8: =IF(C8="","",INT((INT(C8)-'01_Ficha_Dosis'!$C$14)/7)+1) | J8: =IF(OR(C8="",D8=""),"",ROUND((D8-C8)*1440,0)) | K8: =IF(J8="","",IF(AND(G8="OK",J8>='01_Ficha_Dosis'!$C$23,F8>='01_Ficha_Dosis'!$C$24,H8>='01_Ficha_Dosis'!$C$14,H8<='01_Ficha_Dosis'!$C$15),1,0)) | L8: =IF(K8=1,J8,0) -> 0
H9: =IF(C9="","",INT(C9)) | I9: =IF(C9="","",INT((INT(C9)-'01_Ficha_Dosis'!$C$14)/7)+1) | J9: =IF(OR(C9="",D9=""),"",ROUND((D9-C9)*1440,0)) | K9: =IF(J9="","",IF(AND(G9="OK",J9>='01_Ficha_Dosis'!$C$23,F9>='01_Ficha_Dosis'!$C$24,H9>='01_Ficha_Dosis'!$C$14,H9<='01_Ficha_Dosis'!$C$15),1,0)) | L9: =IF(K9=1,J9,0) -> 0
H10: =IF(C10="","",INT(C10)) | I10: =IF(C10="","",INT((INT(C10)-'01_Ficha_Dosis'!$C$14)/7)+1) | J10: =IF(OR(C10="",D10=""),"",ROUND((D10-C10)*1440,0)) | K10: =IF(J10="","",IF(AND(G10="OK",J10>='01_Ficha_Dosis'!$C$23,F10>='01_Ficha_Dosis'!$C$24,H10>='01_Ficha_Dosis'!$C$14,H10<='01_Ficha_Dosis'!$C$15),1,0)) | L10: =IF(K10=1,J10,0) -> 0
H11: =IF(C11="","",INT(C11)) | I11: =IF(C11="","",INT((INT(C11)-'01_Ficha_Dosis'!$C$14)/7)+1) | J11: =IF(OR(C11="",D11=""),"",ROUND((D11-C11)*1440,0)) | K11: =IF(J11="","",IF(AND(G11="OK",J11>='01_Ficha_Dosis'!$C$23,F11>='01_Ficha_Dosis'!$C$24,H11>='01_Ficha_Dosis'!$C$14,H11<='01_Ficha_Dosis'!$C$15),1,0)) | L11: =IF(K11=1,J11,0) -> 0
H12: =IF(C12="","",INT(C12)) | I12: =IF(C12="","",INT((INT(C12)-'01_Ficha_Dosis'!$C$14)/7)+1) | J12: =IF(OR(C12="",D12=""),"",ROUND((D12-C12)*1440,0)) | K12: =IF(J12="","",IF(AND(G12="OK",J12>='01_Ficha_Dosis'!$C$23,F12>='01_Ficha_Dosis'!$C$24,H12>='01_Ficha_Dosis'!$C$14,H12<='01_Ficha_Dosis'!$C$15),1,0)) | L12: =IF(K12=1,J12,0) -> 0
H13: =IF(C13="","",INT(C13)) | I13: =IF(C13="","",INT((INT(C13)-'01_Ficha_Dosis'!$C$14)/7)+1) | J13: =IF(OR(C13="",D13=""),"",ROUND((D13-C13)*1440,0)) | K13: =IF(J13="","",IF(AND(G13="OK",J13>='01_Ficha_Dosis'!$C$23,F13>='01_Ficha_Dosis'!$C$24,H13>='01_Ficha_Dosis'!$C$14,H13<='01_Ficha_Dosis'!$C$15),1,0)) | L13: =IF(K13=1,J13,0) -> 0
H14: =IF(C14="","",INT(C14)) | I14: =IF(C14="","",INT((INT(C14)-'01_Ficha_Dosis'!$C$14)/7)+1) | J14: =IF(OR(C14="",D14=""),"",ROUND((D14-C14)*1440,0)) | K14: =IF(J14="","",IF(AND(G14="OK",J14>='01_Ficha_Dosis'!$C$23,F14>='01_Ficha_Dosis'!$C$24,H14>='01_Ficha_Dosis'!$C$14,H14<='01_Ficha_Dosis'!$C$15),1,0)) | L14: =IF(K14=1,J14,0) -> 0
H15: =IF(C15="","",INT(C15)) | I15: =IF(C15="","",INT((INT(C15)-'01_Ficha_Dosis'!$C$14)/7)+1) | J15: =IF(OR(C15="",D15=""),"",ROUND((D15-C15)*1440,0)) | K15: =IF(J15="","",IF(AND(G15="OK",J15>='01_Ficha_Dosis'!$C$23,F15>='01_Ficha_Dosis'!$C$24,H15>='01_Ficha_Dosis'!$C$14,H15<='01_Ficha_Dosis'!$C$15),1,0)) | L15: =IF(K15=1,J15,0) -> 0
H16: =IF(C16="","",INT(C16)) | I16: =IF(C16="","",INT((INT(C16)-'01_Ficha_Dosis'!$C$14)/7)+1) | J16: =IF(OR(C16="",D16=""),"",ROUND((D16-C16)*1440,0)) | K16: =IF(J16="","",IF(AND(G16="OK",J16>='01_Ficha_Dosis'!$C$23,F16>='01_Ficha_Dosis'!$C$24,H16>='01_Ficha_Dosis'!$C$14,H16<='01_Ficha_Dosis'!$C$15),1,0)) | L16: =IF(K16=1,J16,0) -> 0
H17: =IF(C17="","",INT(C17)) | I17: =IF(C17="","",INT((INT(C17)-'01_Ficha_Dosis'!$C$14)/7)+1) | J17: =IF(OR(C17="",D17=""),"",ROUND((D17-C17)*1440,0)) | K17: =IF(J17="","",IF(AND(G17="OK",J17>='01_Ficha_Dosis'!$C$23,F17>='01_Ficha_Dosis'!$C$24,H17>='01_Ficha_Dosis'!$C$14,H17<='01_Ficha_Dosis'!$C$15),1,0)) | L17: =IF(K17=1,J17,0) -> 0
... H705: =IF(C705="","",INT(C705)) | I705: =IF(C705="","",INT((INT(C705)-'01_Ficha_Dosis'!$C$14)/7)+1) | J705: =IF(OR(C705="",D705=""),"",ROUND((D705-C705)*1440,0)) | K705: =IF(J705="","",IF(AND(G705="OK",J705>='01_Ficha_Dosis'!$C$23,F705>='01_Ficha_Dosis'!$C$24,H705>='01_Ficha_Dosis'!$C$14,H705<='01_Ficha_Dosis'!$C$15),1,0)) | L705: =IF(K705=1,J705,0) -> 0

Sheet 05_Registro_Uso
A1: UNIVERSIDAD DE HUÁNUCO · Ingeniería de Sistemas e Informática · Seminario de Tesis III · Sesión 5
A2: Formato 5 · Registro de uso consolidado (dosis por participante)
A3: Hoja automática: cuenta solo sesiones válidas del log. Semanas fuera del periodo aparecen vacías.
A5: Código | B5: Grupo | C5: Sem 1 | D5: Sem 2 | E5: Sem 3 | F5: Sem 4 | G5: Sem 5 | H5: Sem 6 | I5: Sem 7 | J5: Sem 8 | K5: Sesiones válidas | L5: Minutos válidos | M5: Intensidad (min/ses.) | N5: % cumplimiento | O5: Estado
A6: =IF('02_Participantes'!B6="","",'02_Participantes'!B6) | B6: =IF(A6="","",'02_Participantes'!C6) | C6: =IF(OR(A6="",1>'01_Ficha_Dosis'!$C$16),"",COUNTIFS('04_Log_Accesos'!$B$6:$B$705,A6,'04_Log_Accesos'!$I$6:$I$705,1,'04_Log_Accesos'!$K$6:$K$705,1)) | D6: =IF(OR(A6="",2>'01_Ficha_Dosis'!$C$16),"",COUNTIFS('04_Log_Accesos'!$B$6:$B$705,A6,'04_Log_Accesos'!$I$6:$I$705,2,'04_Log_Accesos'!$K$6:$K$705,1)) | E6: =IF(OR(A6="",3>'01_Ficha_Dosis'!$C$16),"",COUNTIFS('04_Log_Accesos'!$B$6:$B$705,A6,'04_Log_Accesos'!$I$6:$I$705,3,'04_Log_Accesos'!$K$6:$K$705,1)) | F6: =IF(OR(A6="",4>'01_Ficha_Dosis'!$C$16),"",COUNTIFS('04_Log_Accesos'!$B$6:$B$705,A6,'04_Log_Accesos'!$I$6:$I$705,4,'04_Log_Accesos'!$K$6:$K$705,1)) | G6: =IF(OR(A6="",5>'01_Ficha_Dosis'!$C$16),"",COUNTIFS('04_Log_Accesos'!$B$6:$B$705,A6,'04_Log_Accesos'!$I$6:$I$705,5,'04_Log_Accesos'!$K$6:$K$705,1)) | H6: =IF(OR(A6="",6>'01_Ficha_Dosis'!$C$16),"",COUNTIFS('04_Log_Accesos'!$B$6:$B$705,A6,'04_Log_Accesos'!$I$6:$I$705,6,'04_Log_Accesos'!$K$6:$K$705,1)) | I6: =IF(OR(A6="",7>'01_Ficha_Dosis'!$C$16),"",COUNTIFS('04_Log_Accesos'!$B$6:$B$705,A6,'04_Log_Accesos'!$I$6:$I$705,7,'04_Log_Accesos'!$K$6:$K$705,1)) | J6: =IF(OR(A6="",8>'01_Ficha_Dosis'!$C$16),"",COUNTIFS('04_Log_Accesos'!$B$6:$B$705,A6,'04_Log_Accesos'!$I$6:$I$705,8,'04_Log_Accesos'!$K$6:$K$705,1)) | K6: =IF(A6="","",SUM(C6:J6)) | L6: =IF(A6="","",SUMIFS('04_Log_Accesos'!$L$6:$L$705,'04_Log_Accesos'!$B$6:$B$705,A6)) | M6: =IF(OR(A6="",K6=0),"",L6/K6) | N6: =IF(OR(A6="",B6<>"GE"),"",K6/'01_Ficha_Dosis'!$C$27) | O6: =IF(N6="","",IF(N6>='01_Ficha_Dosis'!$C$31,"Dosis completa","Bajo umbral"))
A7: =IF('02_Participantes'!B7="","",'02_Participantes'!B7) | B7: =IF(A7="","",'02_Participantes'!C7) | C7: =IF(OR(A7="",1>'01_Ficha_Dosis'!$C$16),"",COUNTIFS('04_Log_Accesos'!$B$6:$B$705,A7,'04_Log_Accesos'!$I$6:$I$705,1,'04_Log_Accesos'!$K$6:$K$705,1)) | D7: =IF(OR(A7="",2>'01_Ficha_Dosis'!$C$16),"",COUNTIFS('04_Log_Accesos'!$B$6:$B$705,A7,'04_Log_Accesos'!$I$6:$I$705,2,'04_Log_Accesos'!$K$6:$K$705,1)) | E7: =IF(OR(A7="",3>'01_Ficha_Dosis'!$C$16),"",COUNTIFS('04_Log_Accesos'!$B$6:$B$705,A7,'04_Log_Accesos'!$I$6:$I$705,3,'04_Log_Accesos'!$K$6:$K$705,1)) | F7: =IF(OR(A7="",4>'01_Ficha_Dosis'!$C$16),"",COUNTIFS('04_Log_Accesos'!$B$6:$B$705,A7,'04_Log_Accesos'!$I$6:$I$705,4,'04_Log_Accesos'!$K$6:$K$705,1)) | G7: =IF(OR(A7="",5>'01_Ficha_Dosis'!$C$16),"",COUNTIFS('04_Log_Accesos'!$B$6:$B$705,A7,'04_Log_Accesos'!$I$6:$I$705,5,'04_Log_Accesos'!$K$6:$K$705,1)) | H7: =IF(OR(A7="",6>'01_Ficha_Dosis'!$C$16),"",COUNTIFS('04_Log_Accesos'!$B$6:$B$705,A7,'04_Log_Accesos'!$I$6:$I$705,6,'04_Log_Accesos'!$K$6:$K$705,1)) | I7: =IF(OR(A7="",7>'01_Ficha_Dosis'!$C$16),"",COUNTIFS('04_Log_Accesos'!$B$6:$B$705,A7,'04_Log_Accesos'!$I$6:$I$705,7,'04_Log_Accesos'!$K$6:$K$705,1)) | J7: =IF(OR(A7="",8>'01_Ficha_Dosis'!$C$16),"",COUNTIFS('04_Log_Accesos'!$B$6:$B$705,A7,'04_Log_Accesos'!$I$6:$I$705,8,'04_Log_Accesos'!$K$6:$K$705,1)) | K7: =IF(A7="","",SUM(C7:J7)) | L7: =IF(A7="","",SUMIFS('04_Log_Accesos'!$L$6:$L$705,'04_Log_Accesos'!$B$6:$B$705,A7)) | M7: =IF(OR(A7="",K7=0),"",L7/K7) | N7: =IF(OR(A7="",B7<>"GE"),"",K7/'01_Ficha_Dosis'!$C$27) | O7: =IF(N7="","",IF(N7>='01_Ficha_Dosis'!$C$31,"Dosis completa","Bajo umbral"))
A8: =IF('02_Participantes'!B8="","",'02_Participantes'!B8) | B8: =IF(A8="","",'02_Participantes'!C8) | C8: =IF(OR(A8="",1>'01_Ficha_Dosis'!$C$16),"",COUNTIFS('04_Log_Accesos'!$B$6:$B$705,A8,'04_Log_Accesos'!$I$6:$I$705,1,'04_Log_Accesos'!$K$6:$K$705,1)) | D8: =IF(OR(A8="",2>'01_Ficha_Dosis'!$C$16),"",COUNTIFS('04_Log_Accesos'!$B$6:$B$705,A8,'04_Log_Accesos'!$I$6:$I$705,2,'04_Log_Accesos'!$K$6:$K$705,1)) | E8: =IF(OR(A8="",3>'01_Ficha_Dosis'!$C$16),"",COUNTIFS('04_Log_Accesos'!$B$6:$B$705,A8,'04_Log_Accesos'!$I$6:$I$705,3,'04_Log_Accesos'!$K$6:$K$705,1)) | F8: =IF(OR(A8="",4>'01_Ficha_Dosis'!$C$16),"",COUNTIFS('04_Log_Accesos'!$B$6:$B$705,A8,'04_Log_Accesos'!$I$6:$I$705,4,'04_Log_Accesos'!$K$6:$K$705,1)) | G8: =IF(OR(A8="",5>'01_Ficha_Dosis'!$C$16),"",COUNTIFS('04_Log_Accesos'!$B$6:$B$705,A8,'04_Log_Accesos'!$I$6:$I$705,5,'04_Log_Accesos'!$K$6:$K$705,1)) | H8: =IF(OR(A8="",6>'01_Ficha_Dosis'!$C$16),"",COUNTIFS('04_Log_Accesos'!$B$6:$B$705,A8,'04_Log_Accesos'!$I$6:$I$705,6,'04_Log_Accesos'!$K$6:$K$705,1)) | I8: =IF(OR(A8="",7>'01_Ficha_Dosis'!$C$16),"",COUNTIFS('04_Log_Accesos'!$B$6:$B$705,A8,'04_Log_Accesos'!$I$6:$I$705,7,'04_Log_Accesos'!$K$6:$K$705,1)) | J8: =IF(OR(A8="",8>'01_Ficha_Dosis'!$C$16),"",COUNTIFS('04_Log_Accesos'!$B$6:$B$705,A8,'04_Log_Accesos'!$I$6:$I$705,8,'04_Log_Accesos'!$K$6:$K$705,1)) | K8: =IF(A8="","",SUM(C8:J8)) | L8: =IF(A8="","",SUMIFS('04_Log_Accesos'!$L$6:$L$705,'04_Log_Accesos'!$B$6:$B$705,A8)) | M8: =IF(OR(A8="",K8=0),"",L8/K8) | N8: =IF(OR(A8="",B8<>"GE"),"",K8/'01_Ficha_Dosis'!$C$27) | O8: =IF(N8="","",IF(N8>='01_Ficha_Dosis'!$C$31,"Dosis completa","Bajo umbral"))
A9: =IF('02_Participantes'!B9="","",'02_Participantes'!B9) | B9: =IF(A9="","",'02_Participantes'!C9) | C9: =IF(OR(A9="",1>'01_Ficha_Dosis'!$C$16),"",COUNTIFS('04_Log_Accesos'!$B$6:$B$705,A9,'04_Log_Accesos'!$I$6:$I$705,1,'04_Log_Accesos'!$K$6:$K$705,1)) | D9: =IF(OR(A9="",2>'01_Ficha_Dosis'!$C$16),"",COUNTIFS('04_Log_Accesos'!$B$6:$B$705,A9,'04_Log_Accesos'!$I$6:$I$705,2,'04_Log_Accesos'!$K$6:$K$705,1)) | E9: =IF(OR(A9="",3>'01_Ficha_Dosis'!$C$16),"",COUNTIFS('04_Log_Accesos'!$B$6:$B$705,A9,'04_Log_Accesos'!$I$6:$I$705,3,'04_Log_Accesos'!$K$6:$K$705,1)) | F9: =IF(OR(A9="",4>'01_Ficha_Dosis'!$C$16),"",COUNTIFS('04_Log_Accesos'!$B$6:$B$705,A9,'04_Log_Accesos'!$I$6:$I$705,4,'04_Log_Accesos'!$K$6:$K$705,1)) | G9: =IF(OR(A9="",5>'01_Ficha_Dosis'!$C$16),"",COUNTIFS('04_Log_Accesos'!$B$6:$B$705,A9,'04_Log_Accesos'!$I$6:$I$705,5,'04_Log_Accesos'!$K$6:$K$705,1)) | H9: =IF(OR(A9="",6>'01_Ficha_Dosis'!$C$16),"",COUNTIFS('04_Log_Accesos'!$B$6:$B$705,A9,'04_Log_Accesos'!$I$6:$I$705,6,'04_Log_Accesos'!$K$6:$K$705,1)) | I9: =IF(OR(A9="",7>'01_Ficha_Dosis'!$C$16),"",COUNTIFS('04_Log_Accesos'!$B$6:$B$705,A9,'04_Log_Accesos'!$I$6:$I$705,7,'04_Log_Accesos'!$K$6:$K$705,1)) | J9: =IF(OR(A9="",8>'01_Ficha_Dosis'!$C$16),"",COUNTIFS('04_Log_Accesos'!$B$6:$B$705,A9,'04_Log_Accesos'!$I$6:$I$705,8,'04_Log_Accesos'!$K$6:$K$705,1)) | K9: =IF(A9="","",SUM(C9:J9)) | L9: =IF(A9="","",SUMIFS('04_Log_Accesos'!$L$6:$L$705,'04_Log_Accesos'!$B$6:$B$705,A9)) | M9: =IF(OR(A9="",K9=0),"",L9/K9) | N9: =IF(OR(A9="",B9<>"GE"),"",K9/'01_Ficha_Dosis'!$C$27) | O9: =IF(N9="","",IF(N9>='01_Ficha_Dosis'!$C$31,"Dosis completa","Bajo umbral"))
A10: =IF('02_Participantes'!B10="","",'02_Participantes'!B10) | B10: =IF(A10="","",'02_Participantes'!C10) | C10: =IF(OR(A10="",1>'01_Ficha_Dosis'!$C$16),"",COUNTIFS('04_Log_Accesos'!$B$6:$B$705,A10,'04_Log_Accesos'!$I$6:$I$705,1,'04_Log_Accesos'!$K$6:$K$705,1)) | D10: =IF(OR(A10="",2>'01_Ficha_Dosis'!$C$16),"",COUNTIFS('04_Log_Accesos'!$B$6:$B$705,A10,'04_Log_Accesos'!$I$6:$I$705,2,'04_Log_Accesos'!$K$6:$K$705,1)) | E10: =IF(OR(A10="",3>'01_Ficha_Dosis'!$C$16),"",COUNTIFS('04_Log_Accesos'!$B$6:$B$705,A10,'04_Log_Accesos'!$I$6:$I$705,3,'04_Log_Accesos'!$K$6:$K$705,1)) | F10: =IF(OR(A10="",4>'01_Ficha_Dosis'!$C$16),"",COUNTIFS('04_Log_Accesos'!$B$6:$B$705,A10,'04_Log_Accesos'!$I$6:$I$705,4,'04_Log_Accesos'!$K$6:$K$705,1)) | G10: =IF(OR(A10="",5>'01_Ficha_Dosis'!$C$16),"",COUNTIFS('04_Log_Accesos'!$B$6:$B$705,A10,'04_Log_Accesos'!$I$6:$I$705,5,'04_Log_Accesos'!$K$6:$K$705,1)) | H10: =IF(OR(A10="",6>'01_Ficha_Dosis'!$C$16),"",COUNTIFS('04_Log_Accesos'!$B$6:$B$705,A10,'04_Log_Accesos'!$I$6:$I$705,6,'04_Log_Accesos'!$K$6:$K$705,1)) | I10: =IF(OR(A10="",7>'01_Ficha_Dosis'!$C$16),"",COUNTIFS('04_Log_Accesos'!$B$6:$B$705,A10,'04_Log_Accesos'!$I$6:$I$705,7,'04_Log_Accesos'!$K$6:$K$705,1)) | J10: =IF(OR(A10="",8>'01_Ficha_Dosis'!$C$16),"",COUNTIFS('04_Log_Accesos'!$B$6:$B$705,A10,'04_Log_Accesos'!$I$6:$I$705,8,'04_Log_Accesos'!$K$6:$K$705,1)) | K10: =IF(A10="","",SUM(C10:J10)) | L10: =IF(A10="","",SUMIFS('04_Log_Accesos'!$L$6:$L$705,'04_Log_Accesos'!$B$6:$B$705,A10)) | M10: =IF(OR(A10="",K10=0),"",L10/K10) | N10: =IF(OR(A10="",B10<>"GE"),"",K10/'01_Ficha_Dosis'!$C$27) | O10: =IF(N10="","",IF(N10>='01_Ficha_Dosis'!$C$31,"Dosis completa","Bajo umbral"))
A11: =IF('02_Participantes'!B11="","",'02_Participantes'!B11) | B11: =IF(A11="","",'02_Participantes'!C11) | C11: =IF(OR(A11="",1>'01_Ficha_Dosis'!$C$16),"",COUNTIFS('04_Log_Accesos'!$B$6:$B$705,A11,'04_Log_Accesos'!$I$6:$I$705,1,'04_Log_Accesos'!$K$6:$K$705,1)) | D11: =IF(OR(A11="",2>'01_Ficha_Dosis'!$C$16),"",COUNTIFS('04_Log_Accesos'!$B$6:$B$705,A11,'04_Log_Accesos'!$I$6:$I$705,2,'04_Log_Accesos'!$K$6:$K$705,1)) | E11: =IF(OR(A11="",3>'01_Ficha_Dosis'!$C$16),"",COUNTIFS('04_Log_Accesos'!$B$6:$B$705,A11,'04_Log_Accesos'!$I$6:$I$705,3,'04_Log_Accesos'!$K$6:$K$705,1)) | F11: =IF(OR(A11="",4>'01_Ficha_Dosis'!$C$16),"",COUNTIFS('04_Log_Accesos'!$B$6:$B$705,A11,'04_Log_Accesos'!$I$6:$I$705,4,'04_Log_Accesos'!$K$6:$K$705,1)) | G11: =IF(OR(A11="",5>'01_Ficha_Dosis'!$C$16),"",COUNTIFS('04_Log_Accesos'!$B$6:$B$705,A11,'04_Log_Accesos'!$I$6:$I$705,5,'04_Log_Accesos'!$K$6:$K$705,1)) | H11: =IF(OR(A11="",6>'01_Ficha_Dosis'!$C$16),"",COUNTIFS('04_Log_Accesos'!$B$6:$B$705,A11,'04_Log_Accesos'!$I$6:$I$705,6,'04_Log_Accesos'!$K$6:$K$705,1)) | I11: =IF(OR(A11="",7>'01_Ficha_Dosis'!$C$16),"",COUNTIFS('04_Log_Accesos'!$B$6:$B$705,A11,'04_Log_Accesos'!$I$6:$I$705,7,'04_Log_Accesos'!$K$6:$K$705,1)) | J11: =IF(OR(A11="",8>'01_Ficha_Dosis'!$C$16),"",COUNTIFS('04_Log_Accesos'!$B$6:$B$705,A11,'04_Log_Accesos'!$I$6:$I$705,8,'04_Log_Accesos'!$K$6:$K$705,1)) | K11: =IF(A11="","",SUM(C11:J11)) | L11: =IF(A11="","",SUMIFS('04_Log_Accesos'!$L$6:$L$705,'04_Log_Accesos'!$B$6:$B$705,A11)) | M11: =IF(OR(A11="",K11=0),"",L11/K11) | N11: =IF(OR(A11="",B11<>"GE"),"",K11/'01_Ficha_Dosis'!$C$27) | O11: =IF(N11="","",IF(N11>='01_Ficha_Dosis'!$C$31,"Dosis completa","Bajo umbral"))
A12: =IF('02_Participantes'!B12="","",'02_Participantes'!B12) | B12: =IF(A12="","",'02_Participantes'!C12) | C12: =IF(OR(A12="",1>'01_Ficha_Dosis'!$C$16),"",COUNTIFS('04_Log_Accesos'!$B$6:$B$705,A12,'04_Log_Accesos'!$I$6:$I$705,1,'04_Log_Accesos'!$K$6:$K$705,1)) | D12: =IF(OR(A12="",2>'01_Ficha_Dosis'!$C$16),"",COUNTIFS('04_Log_Accesos'!$B$6:$B$705,A12,'04_Log_Accesos'!$I$6:$I$705,2,'04_Log_Accesos'!$K$6:$K$705,1)) | E12: =IF(OR(A12="",3>'01_Ficha_Dosis'!$C$16),"",COUNTIFS('04_Log_Accesos'!$B$6:$B$705,A12,'04_Log_Accesos'!$I$6:$I$705,3,'04_Log_Accesos'!$K$6:$K$705,1)) | F12: =IF(OR(A12="",4>'01_Ficha_Dosis'!$C$16),"",COUNTIFS('04_Log_Accesos'!$B$6:$B$705,A12,'04_Log_Accesos'!$I$6:$I$705,4,'04_Log_Accesos'!$K$6:$K$705,1)) | G12: =IF(OR(A12="",5>'01_Ficha_Dosis'!$C$16),"",COUNTIFS('04_Log_Accesos'!$B$6:$B$705,A12,'04_Log_Accesos'!$I$6:$I$705,5,'04_Log_Accesos'!$K$6:$K$705,1)) | H12: =IF(OR(A12="",6>'01_Ficha_Dosis'!$C$16),"",COUNTIFS('04_Log_Accesos'!$B$6:$B$705,A12,'04_Log_Accesos'!$I$6:$I$705,6,'04_Log_Accesos'!$K$6:$K$705,1)) | I12: =IF(OR(A12="",7>'01_Ficha_Dosis'!$C$16),"",COUNTIFS('04_Log_Accesos'!$B$6:$B$705,A12,'04_Log_Accesos'!$I$6:$I$705,7,'04_Log_Accesos'!$K$6:$K$705,1)) | J12: =IF(OR(A12="",8>'01_Ficha_Dosis'!$C$16),"",COUNTIFS('04_Log_Accesos'!$B$6:$B$705,A12,'04_Log_Accesos'!$I$6:$I$705,8,'04_Log_Accesos'!$K$6:$K$705,1)) | K12: =IF(A12="","",SUM(C12:J12)) | L12: =IF(A12="","",SUMIFS('04_Log_Accesos'!$L$6:$L$705,'04_Log_Accesos'!$B$6:$B$705,A12)) | M12: =IF(OR(A12="",K12=0),"",L12/K12) | N12: =IF(OR(A12="",B12<>"GE"),"",K12/'01_Ficha_Dosis'!$C$27) | O12: =IF(N12="","",IF(N12>='01_Ficha_Dosis'!$C$31,"Dosis completa","Bajo umbral"))
A13: =IF('02_Participantes'!B13="","",'02_Participantes'!B13) | B13: =IF(A13="","",'02_Participantes'!C13) | C13: =IF(OR(A13="",1>'01_Ficha_Dosis'!$C$16),"",COUNTIFS('04_Log_Accesos'!$B$6:$B$705,A13,'04_Log_Accesos'!$I$6:$I$705,1,'04_Log_Accesos'!$K$6:$K$705,1)) | D13: =IF(OR(A13="",2>'01_Ficha_Dosis'!$C$16),"",COUNTIFS('04_Log_Accesos'!$B$6:$B$705,A13,'04_Log_Accesos'!$I$6:$I$705,2,'04_Log_Accesos'!$K$6:$K$705,1)) | E13: =IF(OR(A13="",3>'01_Ficha_Dosis'!$C$16),"",COUNTIFS('04_Log_Accesos'!$B$6:$B$705,A13,'04_Log_Accesos'!$I$6:$I$705,3,'04_Log_Accesos'!$K$6:$K$705,1)) | F13: =IF(OR(A13="",4>'01_Ficha_Dosis'!$C$16),"",COUNTIFS('04_Log_Accesos'!$B$6:$B$705,A13,'04_Log_Accesos'!$I$6:$I$705,4,'04_Log_Accesos'!$K$6:$K$705,1)) | G13: =IF(OR(A13="",5>'01_Ficha_Dosis'!$C$16),"",COUNTIFS('04_Log_Accesos'!$B$6:$B$705,A13,'04_Log_Accesos'!$I$6:$I$705,5,'04_Log_Accesos'!$K$6:$K$705,1)) | H13: =IF(OR(A13="",6>'01_Ficha_Dosis'!$C$16),"",COUNTIFS('04_Log_Accesos'!$B$6:$B$705,A13,'04_Log_Accesos'!$I$6:$I$705,6,'04_Log_Accesos'!$K$6:$K$705,1)) | I13: =IF(OR(A13="",7>'01_Ficha_Dosis'!$C$16),"",COUNTIFS('04_Log_Accesos'!$B$6:$B$705,A13,'04_Log_Accesos'!$I$6:$I$705,7,'04_Log_Accesos'!$K$6:$K$705,1)) | J13: =IF(OR(A13="",8>'01_Ficha_Dosis'!$C$16),"",COUNTIFS('04_Log_Accesos'!$B$6:$B$705,A13,'04_Log_Accesos'!$I$6:$I$705,8,'04_Log_Accesos'!$K$6:$K$705,1)) | K13: =IF(A13="","",SUM(C13:J13)) | L13: =IF(A13="","",SUMIFS('04_Log_Accesos'!$L$6:$L$705,'04_Log_Accesos'!$B$6:$B$705,A13)) | M13: =IF(OR(A13="",K13=0),"",L13/K13) | N13: =IF(OR(A13="",B13<>"GE"),"",K13/'01_Ficha_Dosis'!$C$27) | O13: =IF(N13="","",IF(N13>='01_Ficha_Dosis'!$C$31,"Dosis completa","Bajo umbral"))
A14: =IF('02_Participantes'!B14="","",'02_Participantes'!B14) | B14: =IF(A14="","",'02_Participantes'!C14) | C14: =IF(OR(A14="",1>'01_Ficha_Dosis'!$C$16),"",COUNTIFS('04_Log_Accesos'!$B$6:$B$705,A14,'04_Log_Accesos'!$I$6:$I$705,1,'04_Log_Accesos'!$K$6:$K$705,1)) | D14: =IF(OR(A14="",2>'01_Ficha_Dosis'!$C$16),"",COUNTIFS('04_Log_Accesos'!$B$6:$B$705,A14,'04_Log_Accesos'!$I$6:$I$705,2,'04_Log_Accesos'!$K$6:$K$705,1)) | E14: =IF(OR(A14="",3>'01_Ficha_Dosis'!$C$16),"",COUNTIFS('04_Log_Accesos'!$B$6:$B$705,A14,'04_Log_Accesos'!$I$6:$I$705,3,'04_Log_Accesos'!$K$6:$K$705,1)) | F14: =IF(OR(A14="",4>'01_Ficha_Dosis'!$C$16),"",COUNTIFS('04_Log_Accesos'!$B$6:$B$705,A14,'04_Log_Accesos'!$I$6:$I$705,4,'04_Log_Accesos'!$K$6:$K$705,1)) | G14: =IF(OR(A14="",5>'01_Ficha_Dosis'!$C$16),"",COUNTIFS('04_Log_Accesos'!$B$6:$B$705,A14,'04_Log_Accesos'!$I$6:$I$705,5,'04_Log_Accesos'!$K$6:$K$705,1)) | H14: =IF(OR(A14="",6>'01_Ficha_Dosis'!$C$16),"",COUNTIFS('04_Log_Accesos'!$B$6:$B$705,A14,'04_Log_Accesos'!$I$6:$I$705,6,'04_Log_Accesos'!$K$6:$K$705,1)) | I14: =IF(OR(A14="",7>'01_Ficha_Dosis'!$C$16),"",COUNTIFS('04_Log_Accesos'!$B$6:$B$705,A14,'04_Log_Accesos'!$I$6:$I$705,7,'04_Log_Accesos'!$K$6:$K$705,1)) | J14: =IF(OR(A14="",8>'01_Ficha_Dosis'!$C$16),"",COUNTIFS('04_Log_Accesos'!$B$6:$B$705,A14,'04_Log_Accesos'!$I$6:$I$705,8,'04_Log_Accesos'!$K$6:$K$705,1)) | K14: =IF(A14="","",SUM(C14:J14)) | L14: =IF(A14="","",SUMIFS('04_Log_Accesos'!$L$6:$L$705,'04_Log_Accesos'!$B$6:$B$705,A14)) | M14: =IF(OR(A14="",K14=0),"",L14/K14) | N14: =IF(OR(A14="",B14<>"GE"),"",K14/'01_Ficha_Dosis'!$C$27) | O14: =IF(N14="","",IF(N14>='01_Ficha_Dosis'!$C$31,"Dosis completa","Bajo umbral"))
A15: =IF('02_Participantes'!B15="","",'02_Participantes'!B15) | B15: =IF(A15="","",'02_Participantes'!C15) | C15: =IF(OR(A15="",1>'01_Ficha_Dosis'!$C$16),"",COUNTIFS('04_Log_Accesos'!$B$6:$B$705,A15,'04_Log_Accesos'!$I$6:$I$705,1,'04_Log_Accesos'!$K$6:$K$705,1)) | D15: =IF(OR(A15="",2>'01_Ficha_Dosis'!$C$16),"",COUNTIFS('04_Log_Accesos'!$B$6:$B$705,A15,'04_Log_Accesos'!$I$6:$I$705,2,'04_Log_Accesos'!$K$6:$K$705,1)) | E15: =IF(OR(A15="",3>'01_Ficha_Dosis'!$C$16),"",COUNTIFS('04_Log_Accesos'!$B$6:$B$705,A15,'04_Log_Accesos'!$I$6:$I$705,3,'04_Log_Accesos'!$K$6:$K$705,1)) | F15: =IF(OR(A15="",4>'01_Ficha_Dosis'!$C$16),"",COUNTIFS('04_Log_Accesos'!$B$6:$B$705,A15,'04_Log_Accesos'!$I$6:$I$705,4,'04_Log_Accesos'!$K$6:$K$705,1)) | G15: =IF(OR(A15="",5>'01_Ficha_Dosis'!$C$16),"",COUNTIFS('04_Log_Accesos'!$B$6:$B$705,A15,'04_Log_Accesos'!$I$6:$I$705,5,'04_Log_Accesos'!$K$6:$K$705,1)) | H15: =IF(OR(A15="",6>'01_Ficha_Dosis'!$C$16),"",COUNTIFS('04_Log_Accesos'!$B$6:$B$705,A15,'04_Log_Accesos'!$I$6:$I$705,6,'04_Log_Accesos'!$K$6:$K$705,1)) | I15: =IF(OR(A15="",7>'01_Ficha_Dosis'!$C$16),"",COUNTIFS('04_Log_Accesos'!$B$6:$B$705,A15,'04_Log_Accesos'!$I$6:$I$705,7,'04_Log_Accesos'!$K$6:$K$705,1)) | J15: =IF(OR(A15="",8>'01_Ficha_Dosis'!$C$16),"",COUNTIFS('04_Log_Accesos'!$B$6:$B$705,A15,'04_Log_Accesos'!$I$6:$I$705,8,'04_Log_Accesos'!$K$6:$K$705,1)) | K15: =IF(A15="","",SUM(C15:J15)) | L15: =IF(A15="","",SUMIFS('04_Log_Accesos'!$L$6:$L$705,'04_Log_Accesos'!$B$6:$B$705,A15)) | M15: =IF(OR(A15="",K15=0),"",L15/K15) | N15: =IF(OR(A15="",B15<>"GE"),"",K15/'01_Ficha_Dosis'!$C$27) | O15: =IF(N15="","",IF(N15>='01_Ficha_Dosis'!$C$31,"Dosis completa","Bajo umbral"))
A16: =IF('02_Participantes'!B16="","",'02_Participantes'!B16) | B16: =IF(A16="","",'02_Participantes'!C16) | C16: =IF(OR(A16="",1>'01_Ficha_Dosis'!$C$16),"",COUNTIFS('04_Log_Accesos'!$B$6:$B$705,A16,'04_Log_Accesos'!$I$6:$I$705,1,'04_Log_Accesos'!$K$6:$K$705,1)) | D16: =IF(OR(A16="",2>'01_Ficha_Dosis'!$C$16),"",COUNTIFS('04_Log_Accesos'!$B$6:$B$705,A16,'04_Log_Accesos'!$I$6:$I$705,2,'04_Log_Accesos'!$K$6:$K$705,1)) | E16: =IF(OR(A16="",3>'01_Ficha_Dosis'!$C$16),"",COUNTIFS('04_Log_Accesos'!$B$6:$B$705,A16,'04_Log_Accesos'!$I$6:$I$705,3,'04_Log_Accesos'!$K$6:$K$705,1)) | F16: =IF(OR(A16="",4>'01_Ficha_Dosis'!$C$16),"",COUNTIFS('04_Log_Accesos'!$B$6:$B$705,A16,'04_Log_Accesos'!$I$6:$I$705,4,'04_Log_Accesos'!$K$6:$K$705,1)) | G16: =IF(OR(A16="",5>'01_Ficha_Dosis'!$C$16),"",COUNTIFS('04_Log_Accesos'!$B$6:$B$705,A16,'04_Log_Accesos'!$I$6:$I$705,5,'04_Log_Accesos'!$K$6:$K$705,1)) | H16: =IF(OR(A16="",6>'01_Ficha_Dosis'!$C$16),"",COUNTIFS('04_Log_Accesos'!$B$6:$B$705,A16,'04_Log_Accesos'!$I$6:$I$705,6,'04_Log_Accesos'!$K$6:$K$705,1)) | I16: =IF(OR(A16="",7>'01_Ficha_Dosis'!$C$16),"",COUNTIFS('04_Log_Accesos'!$B$6:$B$705,A16,'04_Log_Accesos'!$I$6:$I$705,7,'04_Log_Accesos'!$K$6:$K$705,1)) | J16: =IF(OR(A16="",8>'01_Ficha_Dosis'!$C$16),"",COUNTIFS('04_Log_Accesos'!$B$6:$B$705,A16,'04_Log_Accesos'!$I$6:$I$705,8,'04_Log_Accesos'!$K$6:$K$705,1)) | K16: =IF(A16="","",SUM(C16:J16)) | L16: =IF(A16="","",SUMIFS('04_Log_Accesos'!$L$6:$L$705,'04_Log_Accesos'!$B$6:$B$705,A16)) | M16: =IF(OR(A16="",K16=0),"",L16/K16) | N16: =IF(OR(A16="",B16<>"GE"),"",K16/'01_Ficha_Dosis'!$C$27) | O16: =IF(N16="","",IF(N16>='01_Ficha_Dosis'!$C$31,"Dosis completa","Bajo umbral"))
A17: =IF('02_Participantes'!B17="","",'02_Participantes'!B17) | B17: =IF(A17="","",'02_Participantes'!C17) | C17: =IF(OR(A17="",1>'01_Ficha_Dosis'!$C$16),"",COUNTIFS('04_Log_Accesos'!$B$6:$B$705,A17,'04_Log_Accesos'!$I$6:$I$705,1,'04_Log_Accesos'!$K$6:$K$705,1)) | D17: =IF(OR(A17="",2>'01_Ficha_Dosis'!$C$16),"",COUNTIFS('04_Log_Accesos'!$B$6:$B$705,A17,'04_Log_Accesos'!$I$6:$I$705,2,'04_Log_Accesos'!$K$6:$K$705,1)) | E17: =IF(OR(A17="",3>'01_Ficha_Dosis'!$C$16),"",COUNTIFS('04_Log_Accesos'!$B$6:$B$705,A17,'04_Log_Accesos'!$I$6:$I$705,3,'04_Log_Accesos'!$K$6:$K$705,1)) | F17: =IF(OR(A17="",4>'01_Ficha_Dosis'!$C$16),"",COUNTIFS('04_Log_Accesos'!$B$6:$B$705,A17,'04_Log_Accesos'!$I$6:$I$705,4,'04_Log_Accesos'!$K$6:$K$705,1)) | G17: =IF(OR(A17="",5>'01_Ficha_Dosis'!$C$16),"",COUNTIFS('04_Log_Accesos'!$B$6:$B$705,A17,'04_Log_Accesos'!$I$6:$I$705,5,'04_Log_Accesos'!$K$6:$K$705,1)) | H17: =IF(OR(A17="",6>'01_Ficha_Dosis'!$C$16),"",COUNTIFS('04_Log_Accesos'!$B$6:$B$705,A17,'04_Log_Accesos'!$I$6:$I$705,6,'04_Log_Accesos'!$K$6:$K$705,1)) | I17: =IF(OR(A17="",7>'01_Ficha_Dosis'!$C$16),"",COUNTIFS('04_Log_Accesos'!$B$6:$B$705,A17,'04_Log_Accesos'!$I$6:$I$705,7,'04_Log_Accesos'!$K$6:$K$705,1)) | J17: =IF(OR(A17="",8>'01_Ficha_Dosis'!$C$16),"",COUNTIFS('04_Log_Accesos'!$B$6:$B$705,A17,'04_Log_Accesos'!$I$6:$I$705,8,'04_Log_Accesos'!$K$6:$K$705,1)) | K17: =IF(A17="","",SUM(C17:J17)) | L17: =IF(A17="","",SUMIFS('04_Log_Accesos'!$L$6:$L$705,'04_Log_Accesos'!$B$6:$B$705,A17)) | M17: =IF(OR(A17="",K17=0),"",L17/K17) | N17: =IF(OR(A17="",B17<>"GE"),"",K17/'01_Ficha_Dosis'!$C$27) | O17: =IF(N17="","",IF(N17>='01_Ficha_Dosis'!$C$31,"Dosis completa","Bajo umbral"))
... A65: =IF('02_Participantes'!B65="","",'02_Participantes'!B65) | B65: =IF(A65="","",'02_Participantes'!C65) | C65: =IF(OR(A65="",1>'01_Ficha_Dosis'!$C$16),"",COUNTIFS('04_Log_Accesos'!$B$6:$B$705,A65,'04_Log_Accesos'!$I$6:$I$705,1,'04_Log_Accesos'!$K$6:$K$705,1)) | D65: =IF(OR(A65="",2>'01_Ficha_Dosis'!$C$16),"",COUNTIFS('04_Log_Accesos'!$B$6:$B$705,A65,'04_Log_Accesos'!$I$6:$I$705,2,'04_Log_Accesos'!$K$6:$K$705,1)) | E65: =IF(OR(A65="",3>'01_Ficha_Dosis'!$C$16),"",COUNTIFS('04_Log_Accesos'!$B$6:$B$705,A65,'04_Log_Accesos'!$I$6:$I$705,3,'04_Log_Accesos'!$K$6:$K$705,1)) | F65: =IF(OR(A65="",4>'01_Ficha_Dosis'!$C$16),"",COUNTIFS('04_Log_Accesos'!$B$6:$B$705,A65,'04_Log_Accesos'!$I$6:$I$705,4,'04_Log_Accesos'!$K$6:$K$705,1)) | G65: =IF(OR(A65="",5>'01_Ficha_Dosis'!$C$16),"",COUNTIFS('04_Log_Accesos'!$B$6:$B$705,A65,'04_Log_Accesos'!$I$6:$I$705,5,'04_Log_Accesos'!$K$6:$K$705,1)) | H65: =IF(OR(A65="",6>'01_Ficha_Dosis'!$C$16),"",COUNTIFS('04_Log_Accesos'!$B$6:$B$705,A65,'04_Log_Accesos'!$I$6:$I$705,6,'04_Log_Accesos'!$K$6:$K$705,1)) | I65: =IF(OR(A65="",7>'01_Ficha_Dosis'!$C$16),"",COUNTIFS('04_Log_Accesos'!$B$6:$B$705,A65,'04_Log_Accesos'!$I$6:$I$705,7,'04_Log_Accesos'!$K$6:$K$705,1)) | J65: =IF(OR(A65="",8>'01_Ficha_Dosis'!$C$16),"",COUNTIFS('04_Log_Accesos'!$B$6:$B$705,A65,'04_Log_Accesos'!$I$6:$I$705,8,'04_Log_Accesos'!$K$6:$K$705,1)) | K65: =IF(A65="","",SUM(C65:J65)) | L65: =IF(A65="","",SUMIFS('04_Log_Accesos'!$L$6:$L$705,'04_Log_Accesos'!$B$6:$B$705,A65)) | M65: =IF(OR(A65="",K65=0),"",L65/K65) | N65: =IF(OR(A65="",B65<>"GE"),"",K65/'01_Ficha_Dosis'!$C$27) | O65: =IF(N65="","",IF(N65>='01_Ficha_Dosis'!$C$31,"Dosis completa","Bajo umbral"))

Sheet 06_Bitacora
A1: UNIVERSIDAD DE HUÁNUCO · Ingeniería de Sistemas e Informática · Seminario de Tesis III · Sesión 5
A2: Formato 6 · Bitácora de intervención
A3: Escribe el mismo día, hechos observables (no opiniones). Toda ayuda adicional, cambio o evento externo va aquí.
A5: Fecha | B5: Hora | C5: Semana | D5: Tipo de registro | E5: Participantes | F5: Hecho observado | G5: Acción tomada | H5: Responsable | I5: Cód. evidencia
A6: 46293 | B6: 16:00 | C6: =IF(A6="","",INT((A6-'01_Ficha_Dosis'!$C$14)/7)+1) -> -2 | D6: Sesión | E6: 25 / 25 | F6: Inicio formal de la intervención. Se leyó el guion único de orientación. | G6: Se entregó guía rápida y se explicó el canal de consultas. | H6: Tesista | I6: E-001
A7: 46295 | B7: 16:20 | C7: =IF(A7="","",INT((A7-'01_Ficha_Dosis'!$C$14)/7)+1) -> -2 | D7: Consulta de usuario | E7: P05 | F7: Consulta sobre cómo filtrar ejercicios por tema. | G7: Se remitió a la guía rápida p. 2 (mismo apoyo para todos). | H7: Tesista | I7: C-001
A8: 46300 | B8: 18:30 | C8: =IF(A8="","",INT((A8-'01_Ficha_Dosis'!$C$14)/7)+1) -> -1 | D8: Reunión de seguimiento | E8: Asesor | F8: Revisión del tablero de la semana 1: 75/75 sesiones. | G8: Se mantiene el protocolo sin cambios. | H8: Tesista / asesor | I8: R-001
A9: 46316 | B9: 16:05 | C9: =IF(A9="","",INT((A9-'01_Ficha_Dosis'!$C$14)/7)+1) -> 1 | D9: Incidencia técnica | E9: 25 / 25 | F9: Caída del servidor (error 500) durante 2 h; no se pudo realizar la sesión. | G9: Incidencia N3; sesión reprogramada al jueves 22/10. | H9: Tesista | I9: E-014
A10: 46321 | B10: 17:10 | C10: =IF(A10="","",INT((A10-'01_Ficha_Dosis'!$C$14)/7)+1) -> 2 | D10: Seguimiento de participante | E10: P12 | F10: P12 acumula baja dosis por inasistencias. | G10: Contacto por el canal oficial; se registra la causa (motivos laborales). | H10: Tesista | I10: C-009
C11: =IF(A11="","",INT((A11-'01_Ficha_Dosis'!$C$14)/7)+1)
C12: =IF(A12="","",INT((A12-'01_Ficha_Dosis'!$C$14)/7)+1)
C13: =IF(A13="","",INT((A13-'01_Ficha_Dosis'!$C$14)/7)+1)
C14: =IF(A14="","",INT((A14-'01_Ficha_Dosis'!$C$14)/7)+1)
C15: =IF(A15="","",INT((A15-'01_Ficha_Dosis'!$C$14)/7)+1)
C16: =IF(A16="","",INT((A16-'01_Ficha_Dosis'!$C$14)/7)+1)
C17: =IF(A17="","",INT((A17-'01_Ficha_Dosis'!$C$14)/7)+1)
C18: =IF(A18="","",INT((A18-'01_Ficha_Dosis'!$C$14)/7)+1)
C19: =IF(A19="","",INT((A19-'01_Ficha_Dosis'!$C$14)/7)+1)
C20: =IF(A20="","",INT((A20-'01_Ficha_Dosis'!$C$14)/7)+1)
C21: =IF(A21="","",INT((A21-'01_Ficha_Dosis'!$C$14)/7)+1)
C22: =IF(A22="","",INT((A22-'01_Ficha_Dosis'!$C$14)/7)+1)
... C105: =IF(A105="","",INT((A105-'01_Ficha_Dosis'!$C$14)/7)+1)

Sheet 07_Soporte
A1: UNIVERSIDAD DE HUÁNUCO · Ingeniería de Sistemas e Informática · Seminario de Tesis III · Sesión 5
A2: Formato 7 · Registro de soporte técnico e incidencias
A3: Metas de respuesta: N1 ≤ 0,5 h · N2 ≤ 4 h · N3 ≤ 24 h. Si una falla impide una sesión, reprográmala en la misma semana.
A5: ID | B5: Reporte (fecha-hora) | C5: Código | D5: Nivel | E5: Síntoma / descripción | F5: Solución aplicada | G5: Solución (fecha-hora) | H5: Tiempo (h) | I5: Meta (h) | J5: ¿A tiempo? | K5: ¿Afectó sesión? | L5: ¿Reprogramada?
A6: INC-01 | B6: 46293.672 | C6: P03 | D6: N1 | E6: Olvidó su contraseña | F6: Restablecimiento de contraseña | G6: 46293.677 | H6: =IF(OR(B6="",G6=""),"",ROUND((G6-B6)*24,2)) -> 0.12 | I6: =IF(D6="","",IF(D6="N1",0.5,IF(D6="N2",4,24))) -> 0.5 | J6: =IF(OR(H6="",I6=""),"",IF(H6<=I6,"Sí","No")) -> Sí | K6: No | L6: No aplica
A7: INC-02 | B7: 46297.674 | C7: P18 | D7: N2 | E7: Módulo de ejercicios no muestra el tema 3 | F7: Corrección de permisos del tema en el panel | G7: 46297.736 | H7: =IF(OR(B7="",G7=""),"",ROUND((G7-B7)*24,2)) -> 1.5 | I7: =IF(D7="","",IF(D7="N1",0.5,IF(D7="N2",4,24))) -> 4 | J7: =IF(OR(H7="",I7=""),"",IF(H7<=I7,"Sí","No")) -> Sí | K7: No | L7: No aplica
A8: INC-03 | B8: 46316.67 | C8: Todos | D8: N3 | E8: Caída del servidor (error 500) | F8: Reinicio del servicio y ampliación de memoria | G8: 46316.753 | H8: =IF(OR(B8="",G8=""),"",ROUND((G8-B8)*24,2)) -> 2 | I8: =IF(D8="","",IF(D8="N1",0.5,IF(D8="N2",4,24))) -> 24 | J8: =IF(OR(H8="",I8=""),"",IF(H8<=I8,"Sí","No")) -> Sí | K8: Sí | L8: Sí
A9: INC-04 | B9: 46323.668 | C9: P09 | D9: N1 | E9: No recibe notificaciones | F9: Activación de notificaciones en el celular | G9: 46323.701 | H9: =IF(OR(B9="",G9=""),"",ROUND((G9-B9)*24,2)) -> 0.8 | I9: =IF(D9="","",IF(D9="N1",0.5,IF(D9="N2",4,24))) -> 0.5 | J9: =IF(OR(H9="",I9=""),"",IF(H9<=I9,"Sí","No")) -> No | K9: No | L9: No aplica
H10: =IF(OR(B10="",G10=""),"",ROUND((G10-B10)*24,2)) | I10: =IF(D10="","",IF(D10="N1",0.5,IF(D10="N2",4,24))) | J10: =IF(OR(H10="",I10=""),"",IF(H10<=I10,"Sí","No"))
H11: =IF(OR(B11="",G11=""),"",ROUND((G11-B11)*24,2)) | I11: =IF(D11="","",IF(D11="N1",0.5,IF(D11="N2",4,24))) | J11: =IF(OR(H11="",I11=""),"",IF(H11<=I11,"Sí","No"))
H12: =IF(OR(B12="",G12=""),"",ROUND((G12-B12)*24,2)) | I12: =IF(D12="","",IF(D12="N1",0.5,IF(D12="N2",4,24))) | J12: =IF(OR(H12="",I12=""),"",IF(H12<=I12,"Sí","No"))
H13: =IF(OR(B13="",G13=""),"",ROUND((G13-B13)*24,2)) | I13: =IF(D13="","",IF(D13="N1",0.5,IF(D13="N2",4,24))) | J13: =IF(OR(H13="",I13=""),"",IF(H13<=I13,"Sí","No"))
H14: =IF(OR(B14="",G14=""),"",ROUND((G14-B14)*24,2)) | I14: =IF(D14="","",IF(D14="N1",0.5,IF(D14="N2",4,24))) | J14: =IF(OR(H14="",I14=""),"",IF(H14<=I14,"Sí","No"))
H15: =IF(OR(B15="",G15=""),"",ROUND((G15-B15)*24,2)) | I15: =IF(D15="","",IF(D15="N1",0.5,IF(D15="N2",4,24))) | J15: =IF(OR(H15="",I15=""),"",IF(H15<=I15,"Sí","No"))
H16: =IF(OR(B16="",G16=""),"",ROUND((G16-B16)*24,2)) | I16: =IF(D16="","",IF(D16="N1",0.5,IF(D16="N2",4,24))) | J16: =IF(OR(H16="",I16=""),"",IF(H16<=I16,"Sí","No"))
H17: =IF(OR(B17="",G17=""),"",ROUND((G17-B17)*24,2)) | I17: =IF(D17="","",IF(D17="N1",0.5,IF(D17="N2",4,24))) | J17: =IF(OR(H17="",I17=""),"",IF(H17<=I17,"Sí","No"))
H18: =IF(OR(B18="",G18=""),"",ROUND((G18-B18)*24,2)) | I18: =IF(D18="","",IF(D18="N1",0.5,IF(D18="N2",4,24))) | J18: =IF(OR(H18="",I18=""),"",IF(H18<=I18,"Sí","No"))
H19: =IF(OR(B19="",G19=""),"",ROUND((G19-B19)*24,2)) | I19: =IF(D19="","",IF(D19="N1",0.5,IF(D19="N2",4,24))) | J19: =IF(OR(H19="",I19=""),"",IF(H19<=I19,"Sí","No"))
H20: =IF(OR(B20="",G20=""),"",ROUND((G20-B20)*24,2)) | I20: =IF(D20="","",IF(D20="N1",0.5,IF(D20="N2",4,24))) | J20: =IF(OR(H20="",I20=""),"",IF(H20<=I20,"Sí","No"))
H21: =IF(OR(B21="",G21=""),"",ROUND((G21-B21)*24,2)) | I21: =IF(D21="","",IF(D21="N1",0.5,IF(D21="N2",4,24))) | J21: =IF(OR(H21="",I21=""),"",IF(H21<=I21,"Sí","No"))
... H65: =IF(OR(B65="",G65=""),"",ROUND((G65-B65)*24,2)) | I65: =IF(D65="","",IF(D65="N1",0.5,IF(D65="N2",4,24))) | J65: =IF(OR(H65="",I65=""),"",IF(H65<=I65,"Sí","No"))

Sheet 08_Disponibilidad
A1: UNIVERSIDAD DE HUÁNUCO · Ingeniería de Sistemas e Informática · Seminario de Tesis III · Sesión 5
A2: Formato 8 · Control diario de disponibilidad y funcionalidad
A3: Horas programadas = horario en que el sistema debe estar disponible. Checklist: Sí/No antes de cada sesión.
A5: Fecha | B5: Semana | C5: Horas programadas | D5: Horas de caída | E5: Disponibilidad | F5: Servidor y BD en línea | G5: Login de prueba | H5: Funciones críticas | I5: Logs activos | J5: Respaldo del día | K5: Tiempo de respuesta OK | L5: Observación
A6: 46293 | B6: =IF(A6="","",INT((A6-'01_Ficha_Dosis'!$C$14)/7)+1) -> -2 | C6: 15 | D6: 0 | E6: =IF(OR(C6="",C6=0),"",(C6-D6)/C6) -> 1 | F6: Sí | G6: Sí | H6: Sí | I6: Sí | J6: Sí | K6: Sí
A7: 46294 | B7: =IF(A7="","",INT((A7-'01_Ficha_Dosis'!$C$14)/7)+1) -> -2 | C7: 15 | D7: 0 | E7: =IF(OR(C7="",C7=0),"",(C7-D7)/C7) -> 1 | F7: Sí | G7: Sí | H7: Sí | I7: Sí | J7: Sí | K7: Sí
A8: 46295 | B8: =IF(A8="","",INT((A8-'01_Ficha_Dosis'!$C$14)/7)+1) -> -2 | C8: 15 | D8: 0 | E8: =IF(OR(C8="",C8=0),"",(C8-D8)/C8) -> 1 | F8: Sí | G8: Sí | H8: Sí | I8: Sí | J8: Sí | K8: Sí
A9: 46296 | B9: =IF(A9="","",INT((A9-'01_Ficha_Dosis'!$C$14)/7)+1) -> -2 | C9: 15 | D9: 0 | E9: =IF(OR(C9="",C9=0),"",(C9-D9)/C9) -> 1 | F9: Sí | G9: Sí | H9: Sí | I9: Sí | J9: Sí | K9: Sí
A10: 46297 | B10: =IF(A10="","",INT((A10-'01_Ficha_Dosis'!$C$14)/7)+1) -> -2 | C10: 15 | D10: 0 | E10: =IF(OR(C10="",C10=0),"",(C10-D10)/C10) -> 1 | F10: Sí | G10: Sí | H10: Sí | I10: Sí | J10: Sí | K10: Sí
A11: 46300 | B11: =IF(A11="","",INT((A11-'01_Ficha_Dosis'!$C$14)/7)+1) -> -1 | C11: 15 | D11: 0 | E11: =IF(OR(C11="",C11=0),"",(C11-D11)/C11) -> 1 | F11: Sí | G11: Sí | H11: Sí | I11: Sí | J11: Sí | K11: Sí
A12: 46301 | B12: =IF(A12="","",INT((A12-'01_Ficha_Dosis'!$C$14)/7)+1) -> -1 | C12: 15 | D12: 0 | E12: =IF(OR(C12="",C12=0),"",(C12-D12)/C12) -> 1 | F12: Sí | G12: Sí | H12: Sí | I12: Sí | J12: Sí | K12: Sí
A13: 46302 | B13: =IF(A13="","",INT((A13-'01_Ficha_Dosis'!$C$14)/7)+1) -> -1 | C13: 15 | D13: 0 | E13: =IF(OR(C13="",C13=0),"",(C13-D13)/C13) -> 1 | F13: Sí | G13: Sí | H13: Sí | I13: Sí | J13: Sí | K13: Sí
A14: 46303 | B14: =IF(A14="","",INT((A14-'01_Ficha_Dosis'!$C$14)/7)+1) -> -1 | C14: 15 | D14: 0 | E14: =IF(OR(C14="",C14=0),"",(C14-D14)/C14) -> 1 | F14: Sí | G14: Sí | H14: Sí | I14: Sí | J14: Sí | K14: Sí
A15: 46304 | B15: =IF(A15="","",INT((A15-'01_Ficha_Dosis'!$C$14)/7)+1) -> -1 | C15: 15 | D15: 0 | E15: =IF(OR(C15="",C15=0),"",(C15-D15)/C15) -> 1 | F15: Sí | G15: Sí | H15: Sí | I15: Sí | J15: Sí | K15: Sí
A16: 46307 | B16: =IF(A16="","",INT((A16-'01_Ficha_Dosis'!$C$14)/7)+1) -> 0 | C16: 15 | D16: 0 | E16: =IF(OR(C16="",C16=0),"",(C16-D16)/C16) -> 1 | F16: Sí | G16: Sí | H16: Sí | I16: Sí | J16: Sí | K16: Sí
A17: 46308 | B17: =IF(A17="","",INT((A17-'01_Ficha_Dosis'!$C$14)/7)+1) -> 0 | C17: 15 | D17: 0 | E17: =IF(OR(C17="",C17=0),"",(C17-D17)/C17) -> 1 | F17: Sí | G17: Sí | H17: Sí | I17: Sí | J17: Sí | K17: Sí
... A22: 46315 | B22: =IF(A22="","",INT((A22-'01_Ficha_Dosis'!$C$14)/7)+1) -> 1 | C22: 15 | D22: 0 | E22: =IF(OR(C22="",C22=0),"",(C22-D22)/C22) -> 1 | F22: Sí | G22: Sí | H22: Sí | I22: Sí | J22: Sí | K22: Sí
A23: 46316 | B23: =IF(A23="","",INT((A23-'01_Ficha_Dosis'!$C$14)/7)+1) -> 1 | C23: 15 | D23: 2 | E23: =IF(OR(C23="",C23=0),"",(C23-D23)/C23) -> 0.86666667 | F23: No | G23: No | H23: No | I23: Sí | J23: Sí | K23: Sí | L23: Caída del servidor 16:05–18:05 (INC-03)
A24: 46317 | B24: =IF(A24="","",INT((A24-'01_Ficha_Dosis'!$C$14)/7)+1) -> 1 | C24: 15 | D24: 0 | E24: =IF(OR(C24="",C24=0),"",(C24-D24)/C24) -> 1 | F24: Sí | G24: Sí | H24: Sí | I24: Sí | J24: Sí | K24: Sí
A25: 46318 | B25: =IF(A25="","",INT((A25-'01_Ficha_Dosis'!$C$14)/7)+1) -> 1 | C25: 15 | D25: 0 | E25: =IF(OR(C25="",C25=0),"",(C25-D25)/C25) -> 1 | F25: Sí | G25: Sí | H25: Sí | I25: Sí | J25: Sí | K25: Sí
A26: 46321 | B26: =IF(A26="","",INT((A26-'01_Ficha_Dosis'!$C$14)/7)+1) -> 2 | C26: 15 | D26: 0 | E26: =IF(OR(C26="",C26=0),"",(C26-D26)/C26) -> 1 | F26: Sí | G26: Sí | H26: Sí | I26: Sí | J26: Sí | K26: Sí
A27: 46322 | B27: =IF(A27="","",INT((A27-'01_Ficha_Dosis'!$C$14)/7)+1) -> 2 | C27: 15 | D27: 0 | E27: =IF(OR(C27="",C27=0),"",(C27-D27)/C27) -> 1 | F27: Sí | G27: Sí | H27: Sí | I27: Sí | J27: Sí | K27: Sí
A28: 46323 | B28: =IF(A28="","",INT((A28-'01_Ficha_Dosis'!$C$14)/7)+1) -> 2 | C28: 15 | D28: 0 | E28: =IF(OR(C28="",C28=0),"",(C28-D28)/C28) -> 1 | F28: Sí | G28: Sí | H28: Sí | I28: Sí | J28: Sí | K28: Sí
A29: 46324 | B29: =IF(A29="","",INT((A29-'01_Ficha_Dosis'!$C$14)/7)+1) -> 2 | C29: 15 | D29: 0 | E29: =IF(OR(C29="",C29=0),"",(C29-D29)/C29) -> 1 | F29: Sí | G29: Sí | H29: Sí | I29: Sí | J29: Sí | K29: Sí
A30: 46325 | B30: =IF(A30="","",INT((A30-'01_Ficha_Dosis'!$C$14)/7)+1) -> 2 | C30: 15 | D30: 0 | E30: =IF(OR(C30="",C30=0),"",(C30-D30)/C30) -> 1 | F30: Sí | G30: Sí | H30: Sí | I30: Sí | J30: Sí | K30: Sí
A31: 46328 | B31: =IF(A31="","",INT((A31-'01_Ficha_Dosis'!$C$14)/7)+1) -> 3 | C31: 15 | D31: 0 | E31: =IF(OR(C31="",C31=0),"",(C31-D31)/C31) -> 1 | F31: Sí | G31: Sí | H31: Sí | I31: Sí | J31: Sí | K31: Sí
A32: 46329 | B32: =IF(A32="","",INT((A32-'01_Ficha_Dosis'!$C$14)/7)+1) -> 3 | C32: 15 | D32: 0 | E32: =IF(OR(C32="",C32=0),"",(C32-D32)/C32) -> 1 | F32: Sí | G32: Sí | H32: Sí | I32: Sí | J32: Sí | K32: Sí
A33: 46330 | B33: =IF(A33="","",INT((A33-'01_Ficha_Dosis'!$C$14)/7)+1) -> 3 | C33: 15 | D33: 0 | E33: =IF(OR(C33="",C33=0),"",(C33-D33)/C33) -> 1 | F33: Sí | G33: Sí | H33: Sí | I33: Sí | J33: Sí | K33: Sí
A34: 46331 | B34: =IF(A34="","",INT((A34-'01_Ficha_Dosis'!$C$14)/7)+1) -> 3 | C34: 15 | D34: 0 | E34: =IF(OR(C34="",C34=0),"",(C34-D34)/C34) -> 1 | F34: Sí | G34: Sí | H34: Sí | I34: Sí | J34: Sí | K34: Sí
A35: 46332 | B35: =IF(A35="","",INT((A35-'01_Ficha_Dosis'!$C$14)/7)+1) -> 3 | C35: 15 | D35: 0 | E35: =IF(OR(C35="",C35=0),"",(C35-D35)/C35) -> 1 | F35: Sí | G35: Sí | H35: Sí | I35: Sí | J35: Sí | K35: Sí
B36: =IF(A36="","",INT((A36-'01_Ficha_Dosis'!$C$14)/7)+1) | E36: =IF(OR(C36="",C36=0),"",(C36-D36)/C36)
B37: =IF(A37="","",INT((A37-'01_Ficha_Dosis'!$C$14)/7)+1) | E37: =IF(OR(C37="",C37=0),"",(C37-D37)/C37)
B38: =IF(A38="","",INT((A38-'01_Ficha_Dosis'!$C$14)/7)+1) | E38: =IF(OR(C38="",C38=0),"",(C38-D38)/C38)
B39: =IF(A39="","",INT((A39-'01_Ficha_Dosis'!$C$14)/7)+1) | E39: =IF(OR(C39="",C39=0),"",(C39-D39)/C39)
B40: =IF(A40="","",INT((A40-'01_Ficha_Dosis'!$C$14)/7)+1) | E40: =IF(OR(C40="",C40=0),"",(C40-D40)/C40)
B41: =IF(A41="","",INT((A41-'01_Ficha_Dosis'!$C$14)/7)+1) | E41: =IF(OR(C41="",C41=0),"",(C41-D41)/C41)
B42: =IF(A42="","",INT((A42-'01_Ficha_Dosis'!$C$14)/7)+1) | E42: =IF(OR(C42="",C42=0),"",(C42-D42)/C42)
B43: =IF(A43="","",INT((A43-'01_Ficha_Dosis'!$C$14)/7)+1) | E43: =IF(OR(C43="",C43=0),"",(C43-D43)/C43)
B44: =IF(A44="","",INT((A44-'01_Ficha_Dosis'!$C$14)/7)+1) | E44: =IF(OR(C44="",C44=0),"",(C44-D44)/C44)
B45: =IF(A45="","",INT((A45-'01_Ficha_Dosis'!$C$14)/7)+1) | E45: =IF(OR(C45="",C45=0),"",(C45-D45)/C45)
...

Sheet 09_Lista_Cotejo
A1: UNIVERSIDAD DE HUÁNUCO · Ingeniería de Sistemas e Informática · Seminario de Tesis III · Sesión 5
A2: Formato 9 · Lista de cotejo de cumplimiento del protocolo
A3: Marca Sí / No / No aplica. Cada "No" requiere observación y acción correctiva.
A4: Semana evaluada: | C4: 1
A5: N.° | B5: Criterio de cumplimiento | C5: Cumple | D5: Evidencia | E5: Observación / acción correctiva
A6: 1 | B6: La intervención inició y avanza según las fechas del protocolo | C6: Sí | D6: Acta de inicio, 03_Cronograma
A7: 2 | B7: Se ejecutó la frecuencia programada de sesiones | C7: Sí | D7: 05_Registro_Uso
A8: 3 | B8: Cada sesión cumplió la duración e intensidad mínimas | C8: Sí | D8: 04_Log_Accesos
A9: 4 | B9: Los participantes son los mismos del pretest (códigos) | C9: Sí | D9: 02_Participantes
A10: 5 | B10: Se aplicó el guion único de orientación a todos | C10: Sí | D10: 06_Bitacora
A11: 6 | B11: El sistema estuvo disponible al menos el 95 % del tiempo | C11: Sí | D11: 08_Disponibilidad
A12: 7 | B12: Las incidencias se registraron y atendieron | C12: Sí | D12: 07_Soporte
A13: 8 | B13: Las sesiones perdidas se reprogramaron en la misma semana | C13: Sí | D13: 03_Cronograma, 06_Bitacora
A14: 9 | B14: Las evidencias están codificadas en el portafolio | C14: Sí | D14: 11_Portafolio
A15: 10 | B15: El GC no tuvo acceso a la solución (solo cuasiexperimental) | C15: No aplica | D15: Control de cuentas
B17: Nivel de cumplimiento (Sí ÷ criterios aplicables) | C17: =IFERROR(COUNTIF(C6:C15,"Sí")/(COUNTA(C6:C15)-COUNTIF(C6:C15,"No aplica")),"") -> 1
B19: Firma del tesista: ______________________ Firma del docente/asesor: ______________________

Sheet 10_Rubrica
A1: UNIVERSIDAD DE HUÁNUCO · Ingeniería de Sistemas e Informática · Seminario de Tesis III · Sesión 5
A2: Formato 10 · Rúbrica de implementación (20 puntos)
A3: Selecciona el nivel alcanzado en cada criterio. Logrado = 5 · En proceso = 3 · Inicio = 1.
A5: Criterio | B5: Logrado (5) | C5: En proceso (3) | D5: Inicio (1) | E5: Nivel alcanzado | F5: Puntaje
A6: Dosis | B6: Duración, frecuencia e intensidad demostradas con datos y cálculo por participante | C6: Demostradas parcialmente o sin cálculo | D6: No se demuestra la dosis | F6: =IF(E6="Logrado",5,IF(E6="En proceso",3,IF(E6="Inicio",1,"")))
A7: Registro | B7: Logs, registro de uso y bitácora completos, coherentes y trazables | C7: Registros incompletos o no coinciden | D7: Sin registros sistemáticos | F7: =IF(E7="Logrado",5,IF(E7="En proceso",3,IF(E7="Inicio",1,"")))
A8: Soporte y funcionamiento | B8: Disponibilidad medida; incidencias clasificadas, atendidas y documentadas | C8: Atención sin documentar | D8: Fallas sin atender | F8: =IF(E8="Logrado",5,IF(E8="En proceso",3,IF(E8="Inicio",1,"")))
A9: Actitud profesional | B9: Puntual, empático, perseverante y orientado al usuario en todas las sesiones | C9: Cumple con observaciones | D9: Incumple compromisos | F9: =IF(E9="Logrado",5,IF(E9="En proceso",3,IF(E9="Inicio",1,"")))
E11: Nota (0–20) | F11: =SUM(F6:F9) -> 0
A13: Retroalimentación del docente:

Sheet 11_Portafolio
A1: UNIVERSIDAD DE HUÁNUCO · Ingeniería de Sistemas e Informática · Seminario de Tesis III · Sesión 5
A2: Formato 11 · Índice del portafolio de evidencias
A3: Codifica cada evidencia (E-###, C-### consultas, R-### reuniones). Fotos y videos solo con autorización y sin datos personales.
A5: Código | B5: Tipo | C5: Descripción | D5: Fecha | E5: Carpeta | F5: Nombre del archivo | G5: Autorización
A6: E-001 | B6: Acta | C6: Acta de inicio de la intervención firmada | D6: 46293 | E6: 01_Protocolo | F6: E-001_acta_inicio.pdf | G6: No aplica
A7: E-002 | B7: Log | C7: Exportación semanal del log (semana 1) | D7: 46297 | E7: 02_Registros | F7: E-002_log_sem1.csv | G7: No aplica
A8: C-001 | B8: Captura | C8: Consulta de P05 en el canal oficial | D8: 46295 | E8: 03_Bitacora | F8: C-001_consulta.png | G8: No aplica
A9: E-014 | B9: Captura | C9: Error 500 del servidor (INC-03) | D9: 46316 | E9: 04_Soporte | F9: E-014_error500.png | G9: No aplica
A10: E-020 | B10: Foto | C10: Sesión en laboratorio 2 (sin rostros) | D10: 46302 | E10: 05_Evidencias | F10: E-020_sesion.jpg | G10: Sí
A11: R-001 | B11: Acta | C11: Reunión de seguimiento semana 1 | D11: 46300 | E11: 03_Bitacora | F11: R-001_reunion.pdf | G11: No aplica

Sheet 12_Tablero
A1: UNIVERSIDAD DE HUÁNUCO · Ingeniería de Sistemas e Informática · Seminario de Tesis III · Sesión 5
A2: Formato 12 · Tablero de seguimiento del cumplimiento del protocolo
A3: Hoja automática. Evidencia directa del indicador de logro. Verde: cumple la meta · Ámbar: hasta 10 puntos debajo · Rojo: acción correctiva.
A5: Indicador | B5: Fórmula | C5: Resultado | D5: Meta | E5: Semáforo
A6: Cumplimiento de sesiones | B6: Sesiones válidas ÷ sesiones planificadas × 100 | C6: =IFERROR(SUM('05_Registro_Uso'!$K$6:$K$65)/'01_Ficha_Dosis'!$C$29,0) -> 0 | D6: ='01_Ficha_Dosis'!$C$32 -> 0.9 | E6: =IF(C6>=D6,"VERDE",IF(C6>=D6-0.1,"ÁMBAR","ROJO")) -> ROJO
A7: Participantes con dosis completa | B7: Participantes ≥ umbral ÷ total GE × 100 | C7: =IFERROR(COUNTIF('05_Registro_Uso'!$N$6:$N$65,">="&'01_Ficha_Dosis'!$C$31)/'01_Ficha_Dosis'!$C$26,0) -> 0 | D7: ='01_Ficha_Dosis'!$C$33 -> 0.85 | E7: =IF(C7>=D7,"VERDE",IF(C7>=D7-0.1,"ÁMBAR","ROJO")) -> ROJO
A8: Intensidad media por sesión (min) | B8: Minutos válidos ÷ sesiones válidas | C8: =IFERROR(SUM('05_Registro_Uso'!$L$6:$L$65)/SUM('05_Registro_Uso'!$K$6:$K$65),0) -> 0 | D8: ='01_Ficha_Dosis'!$C$23 | E8: =IF(C8>=D8,"VERDE",IF(C8>=D8*0.9,"ÁMBAR","ROJO")) -> VERDE
A9: Disponibilidad del sistema | B9: (Horas programadas − caída) ÷ horas programadas × 100 | C9: =IFERROR((SUM('08_Disponibilidad'!$C$6:$C$65)-SUM('08_Disponibilidad'!$D$6:$D$65))/SUM('08_Disponibilidad'!$C$6:$C$65),0) -> 0.99555556 | D9: ='01_Ficha_Dosis'!$C$34 -> 0.95 | E9: =IF(C9>=D9,"VERDE",IF(C9>=D9-0.1,"ÁMBAR","ROJO")) -> VERDE
A10: Incidencias atendidas a tiempo | B10: Incidencias a tiempo ÷ total × 100 | C10: =IFERROR(COUNTIF('07_Soporte'!$J$6:$J$65,"Sí")/COUNTA('07_Soporte'!$A$6:$A$65),0) -> 0.75 | D10: ='01_Ficha_Dosis'!$C$35 -> 0.9 | E10: =IF(C10>=D10,"VERDE",IF(C10>=D10-0.1,"ÁMBAR","ROJO")) -> ROJO
A11: Periodo cumplido (sesiones del cronograma) | B11: Sesiones realizadas o reprogramadas ÷ programadas × 100 | C11: =IFERROR((COUNTIF('03_Cronograma'!$F$6:$F$45,"Realizada")+COUNTIF('03_Cronograma'!$F$6:$F$45,"Reprogramada"))/COUNT('03_Cronograma'!$C$6:$C$45),0) -> 0 | D11: ='01_Ficha_Dosis'!$C$36 -> 1 | E11: =IF(C11>=D11,"VERDE",IF(C11>=D11-0.1,"ÁMBAR","ROJO")) -> ROJO
A14: Sesiones por semana
A15: Semana | B15: Programadas | C15: Válidas | D15: % semana
A16: Sem 1 | B16: =IF(1>'01_Ficha_Dosis'!$C$16,0,'01_Ficha_Dosis'!$C$26*'01_Ficha_Dosis'!$C$19) -> 0 | C16: =COUNTIFS('04_Log_Accesos'!$I$6:$I$705,1,'04_Log_Accesos'!$K$6:$K$705,1) -> 0 | D16: =IF(B16=0,"",C16/B16)
