Workbook

Sheet Inicio
A1: Cuaderno de registros · Sesión 7 · Cierre de la intervención y aplicación del postest
A2: Seminario de Tesis III · 2026-II · Programa Académico de Ingeniería de Sistemas e Informática · Universidad de Huánuco
A4: Datos de la tesis (complete las celdas amarillas)
B5: Título de la tesis | C5: Aplicación multiplataforma de búsqueda semántica conversacional y su influencia en la experiencia de los lectores de Tu Diario Huánuco, 2026
B6: Tesista | C6: Trujillo Ávila, Marcel Alexander Javier; Godoy Condezo, Alejandro Jeanpier
B7: Asesor(a) de tesis | C7: Rodríguez Meléndez, Fabio
B8: Institución donde se ejecuta | C8: Imprenta Editorial LS & JB S.A.C. (Tu Diario Huánuco), Huánuco
B9: Diseño de investigación | C9: Preexperimental (G: O₁ X O₂)
B10: Variable dependiente e indicador | C10: Experiencia de los lectores: usabilidad percibida (puntaje SUS); se registran además tiempo de búsqueda, clics y satisfacción (hoja 6b). El puntaje SUS del postest en la hoja 6 es simulado; no es O2 de campo.
B11: Unidad de medida de la VD | C11: Puntos SUS (0 a 100)
B12: Instrumento de medición y versión | C12: Cuestionario SUS, cuestionario de satisfacción y ficha de tiempos y clics (versión validada, octubre 2026)
A14: Parámetros del protocolo
B15: Umbral mínimo de adherencia | C15: 0.8
B16: Umbral mínimo de fidelidad | C16: 0.8
B17: Ventana del postest (días hábiles tras el cierre) | C17: 5
B18: Rango válido de la VD: valor mínimo | C18: 0
B19: Rango válido de la VD: valor máximo | C19: 100
B20: Fecha de inicio prevista del postest | C20: 46321
B21: Fecha de fin prevista del postest | C21: 46326
B22: Los umbrales provienen del protocolo de ejecución de la tesis (Sesión 01): uso libre durante 7 días con al menos 3 días con sesiones de consulta.
A24: Leyenda
B25: Celda amarilla con texto azul | C25: Dato que completa el tesista.
B26: Texto negro sobre fondo blanco | C26: Fórmula: no editar (se recalcula sola).
B27: Texto verde | C27: Enlace a otra hoja del cuaderno.
B28: Registros del grupo único (G): 114 lectores con pretest, códigos GU-TDH-###. Solo códigos: nunca nombres ni DNI. Datos simulados por indicación de la docente del curso (ejercicio de Seminario de Tesis III).
A30: Hojas del cuaderno y paso del protocolo al que corresponden
B31: Hoja | C31: Paso | D31: Qué registra o calcula
B32: 1_Periodo | C32: Paso 1 | D32: Programado frente a ejecutado; adherencia acumulada y semanal (con gráfico); fidelidad; decisión de cierre.
B33: 2_Participantes | C33: Pasos 2 y 5 | D33: Registro de control de participantes: pretest, estado al cierre, convocatoria, confirmación y postest por código.
B34: 3_Mortalidad | C34: Paso 5 | D34: Mortalidad experimental por grupo, pérdida total, diferencial GE–GC, motivos y flujo de participantes (con gráfico).
B35: 4_Equivalencia | C35: Paso 3 | D35: Lista de cotejo de equivalencia de condiciones pretest–postest (12 condiciones).
B36: 5_Incidencias | C36: Paso 5 | D36: Registro de incidencias del cierre y del postest, con resumen por tipo y estado.
B37: 6_Base_Postest | C37: Paso 6 | D37: Base consolidada pretest–postest por código, verificación de correspondencia, calidad y descriptivos.
B38: 7_ListaCotejo | C38: Paso 4 | D38: Lista de cotejo de aplicación del postest (12 ítems) con resultado automático.
B39: 8_Acta | C39: Paso 6 | D39: Acta de cierre de la intervención, con los datos calculados en las demás hojas.
B40: Diccionario | C40: Paso 6 | D40: Diccionario de variables de la base consolidada.

Sheet 1_Periodo
A1: Paso 1 · Verificación del cumplimiento del periodo de intervención
A2: Compare lo programado en el protocolo con lo ejecutado según la bitácora y los registros de uso. Celdas amarillas: datos de su tesis.
A4: Periodo y dosis: programado frente a ejecutado
B5: Parámetro | C5: Programado | D5: Ejecutado | E5: Cumple | F5: Fuente de verificación
B6: Fecha de inicio | C6: 46314 | D6: 46314 | E6: =IF(D6="","",IF(D6<=C6,"Sí","No")) | F6: Acta de inicio (18/10/2026)
B7: Fecha de cierre | C7: 46320 | D7: 46320 | E7: =IF(D7="","",IF(D7>=C7,"Sí","No")) | F7: Acta de cierre (25/10/2026)
B8: Semanas de intervención | C8: =IF(OR(C6="",C7=""),"",ROUNDUP((C7-C6+1)/7,0)) | D8: =IF(OR(D6="",D7=""),"",ROUNDUP((D7-D6+1)/7,0)) | E8: =IF(D8="","",IF(D8>=C8,"Sí","No")) | F8: Protocolo (Sesión 01, hoja 3, actividad 11) y telemetría
B9: Usuarios de la solución (n) | C9: 108 | D9: =C9 | E9: — | F9: Libro de códigos: 108 lectores válidos tras el pretest
B10: Días de uso por semana (mínimo con sesión de consulta) | C10: 3 | D10: =IF(OR(D11="",D9=0,D8=""),"",D11/D9/D8) | E10: =IF(D10="","",IF(D10>=C10,"Sí","Parcial")) | F10: Frecuencia = días-usuario con uso efectivo (máx. 3 por lector) ÷ usuarios ÷ semanas
B11: Días-usuario | C11: =IF(OR(C8="",C9="",C10=""),"",C8*C9*C10) | D11: =IF(COUNT(D18:D25)=0,"",SUM(D18:D25)) | E11: — | F11: Programados = semanas × usuarios × días; ejecutados = suma de la tabla semanal
B12: Intensidad: % de lectores con al menos 3 sesiones de consulta | C12: 1 | D12: 0.97222222 | E12: =IF(D12="","",IF(D12>=C12,"Sí","Parcial")) | F12: Telemetría de la aplicación (sesiones por código)
B13: Adherencia acumulada | C13: =Inicio!C15 | D13: =IF(OR(D11="",C11="",C11=0),"",D11/C11) | E13: =IF(D13="","",IF(D13>=C13,"Sí","No")) | F13: Adherencia = días-usuario con uso efectivo ÷ programados × 100
B14: El umbral de adherencia se toma de la hoja Inicio (parámetros del protocolo).
A16: Adherencia semanal (días-usuario)
B17: Semana | C17: Programados | D17: Con uso efectivo | E17: Adherencia | F17: Observación de la bitácora
B18: Semana 1 | C18: =IF(D18="","",$C$9*$C$10) | D18: 315 | E18: =IF(OR(D18="",C18=""),"",D18/C18) | F18: Intervención de 7 días (19/10 al 25/10). 105 de 108 cumplieron 3 sesiones: 315 días-usuario. No es el conteo de filas del log. Tres retiros sin postest: GU-TDH-015, GU-TDH-033 y GU-TDH-053.
B19: Semana 2 | C19: =IF(D19="","",$C$9*$C$10) | E19: =IF(OR(D19="",C19=""),"",D19/C19)
B20: Semana 3 | C20: =IF(D20="","",$C$9*$C$10) | E20: =IF(OR(D20="",C20=""),"",D20/C20)
B21: Semana 4 | C21: =IF(D21="","",$C$9*$C$10) | E21: =IF(OR(D21="",C21=""),"",D21/C21)
B22: Semana 5 | C22: =IF(D22="","",$C$9*$C$10) | E22: =IF(OR(D22="",C22=""),"",D22/C22)
B23: Semana 6 | C23: =IF(D23="","",$C$9*$C$10) | E23: =IF(OR(D23="",C23=""),"",D23/C23)
B24: Semana 7 | C24: =IF(D24="","",$C$9*$C$10) | E24: =IF(OR(D24="",C24=""),"",D24/C24)
B25: Semana 8 | C25: =IF(D25="","",$C$9*$C$10) | E25: =IF(OR(D25="",C25=""),"",D25/C25)
B26: La intervención dura 7 días (una semana). Programados = 108 usuarios × 3 días con uso efectivo.
A28: Fidelidad de implementación
B29: Componente del protocolo | C29: ¿Se cumple? | D29: Evidencia
B30: Guía rápida de uso disponible para todos los lectores al iniciar | C30: Sí | D30: Guía dentro de la aplicación y mensaje de bienvenida (18/10/2026)
B31: Uso con la frecuencia programada (≥ 3 días) | C31: Sí | D31: Telemetría: sesiones por código y por día
B32: Uso con la intensidad programada (consultas al asistente) | C32: Sí | D32: Telemetría: consultas registradas por sesión
B33: Soporte técnico disponible y registrado (WhatsApp) | C33: Sí | D33: Bitácora de soporte (Formato 7)
B34: Registros de uso e incidencias al día | C34: Sí | D34: Bitácora y registro de incidencias
B35: Versión congelada sin cambios durante la intervención (v1.0.0-frozen-2026-10-18) | C35: Sí | D35: Tag de referencia v1.0.0-frozen-2026-10-18, congelada el 18/10/2026.
B36: Noticias de las tareas del postest disponibles y sin modificar | C36: Sí | D36: Copia de las cuatro noticias y sus enlaces
B38: Fidelidad de implementación | C38: =IF(COUNTA(B30:B36)=0,"",COUNTIF(C30:C36,"Sí")/COUNTA(B30:B36))
B39: Umbral mínimo de fidelidad | C39: =Inicio!C16
B40: Cumple | C40: =IF(C38="","",IF(C38>=C39,"Sí","No"))
A42: Decisión de cierre
B43: ¿Se cumplió el periodo programado? | C43: =IF(E7="","",E7)
B44: ¿Adherencia ≥ umbral? | C44: =IF(E13="","",E13)
B45: ¿Fidelidad ≥ umbral? | C45: =IF(C40="","",C40)
...

Sheet 2_Participantes
A1: Pasos 2 y 5 · Registro de control de participantes
A2: Un participante por fila, solo códigos. Estado al cierre: Activo / Retirado / Excluido. Confirmación: Confirmado / Reprogramado / Pérdida muestral.
A3: Registrados | B3: =COUNTA(A6:A305) | C3: Con pretest | D3: =COUNTIF(C6:C305,"Sí") | E3: Con postest | F3: =COUNTIF(K6:K305,"Sí") | G3: Pares analizados | H3: =SUM(M6:M305) | I3: Retirados | J3: =COUNTIF(F6:F305,"Retirado") | K3: Excluidos | L3: =COUNTIF(F6:F305,"Excluido")
A5: Código | B5: Grupo | C5: Pretest rendido | D5: Fecha del pretest | E5: Adherencia individual (%) | F5: Estado al cierre | G5: Fecha de retiro o exclusión | H5: Motivo | I5: Convocatoria (fecha) | J5: Confirmación | K5: Postest rendido | L5: Fecha del postest | M5: Par pretest–postest | N5: Observaciones
A6: GU-TDH-002 | B6: G | C6: Sí | D6: 46308 | E6: 100 | F6: Activo | I6: 46320 | J6: Confirmado | K6: Sí | L6: 46322 | M6: =IF(A6="","",IF(AND(C6="Sí",K6="Sí",F6<>"Excluido"),1,0))
A7: GU-TDH-003 | B7: G | C7: Sí | D7: 46307 | E7: 100 | F7: Activo | I7: 46320 | J7: Confirmado | K7: Sí | L7: 46321 | M7: =IF(A7="","",IF(AND(C7="Sí",K7="Sí",F7<>"Excluido"),1,0))
A8: GU-TDH-004 | B8: G | C8: Sí | D8: 46307 | E8: 100 | F8: Activo | I8: 46320 | J8: Confirmado | K8: Sí | L8: 46321 | M8: =IF(A8="","",IF(AND(C8="Sí",K8="Sí",F8<>"Excluido"),1,0))
A9: GU-TDH-006 | B9: G | C9: Sí | D9: 46310 | E9: 100 | F9: Activo | I9: 46320 | J9: Confirmado | K9: Sí | L9: 46324 | M9: =IF(A9="","",IF(AND(C9="Sí",K9="Sí",F9<>"Excluido"),1,0)) | N9: Usó la aplicación 0 día(s); no respondió a tres recordatorios ni a la reprogramación de 72 h.
A10: GU-TDH-007 | B10: G | C10: Sí | D10: 46307 | E10: 100 | F10: Activo | I10: 46320 | J10: Confirmado | K10: Sí | L10: 46321 | M10: =IF(A10="","",IF(AND(C10="Sí",K10="Sí",F10<>"Excluido"),1,0))
A11: GU-TDH-008 | B11: G | C11: Sí | D11: 46308 | E11: 100 | F11: Activo | I11: 46320 | J11: Confirmado | K11: Sí | L11: 46322 | M11: =IF(A11="","",IF(AND(C11="Sí",K11="Sí",F11<>"Excluido"),1,0))
A12: GU-TDH-009 | B12: G | C12: Sí | D12: 46310 | E12: 100 | F12: Activo | I12: 46320 | J12: Confirmado | K12: Sí | L12: 46324 | M12: =IF(A12="","",IF(AND(C12="Sí",K12="Sí",F12<>"Excluido"),1,0)) | N12: Reprogramado dentro de la ventana, en la misma franja horaria.
A13: GU-TDH-010 | B13: G | C13: Sí | D13: 46307 | E13: 100 | F13: Activo | I13: 46320 | J13: Confirmado | K13: Sí | L13: 46321 | M13: =IF(A13="","",IF(AND(C13="Sí",K13="Sí",F13<>"Excluido"),1,0))
A14: GU-TDH-011 | B14: G | C14: Sí | D14: 46308 | E14: 67 | F14: Activo | I14: 46320 | J14: Confirmado | K14: Sí | L14: 46322 | M14: =IF(A14="","",IF(AND(C14="Sí",K14="Sí",F14<>"Excluido"),1,0))
A15: GU-TDH-012 | B15: G | C15: Sí | D15: 46308 | E15: 100 | F15: Activo | I15: 46320 | J15: Confirmado | K15: Sí | L15: 46322 | M15: =IF(A15="","",IF(AND(C15="Sí",K15="Sí",F15<>"Excluido"),1,0))
A16: GU-TDH-014 | B16: G | C16: Sí | D16: 46307 | E16: 100 | F16: Activo | I16: 46320 | J16: Confirmado | K16: Sí | L16: 46321 | M16: =IF(A16="","",IF(AND(C16="Sí",K16="Sí",F16<>"Excluido"),1,0))
A17: GU-TDH-015 | B17: G | C17: Sí | D17: 46310 | E17: 0 | F17: Retirado | G17: 46316 | H17: Inasistencia fuera de la ventana | I17: 46320 | J17: Pérdida muestral | K17: No | M17: =IF(A17="","",IF(AND(C17="Sí",K17="Sí",F17<>"Excluido"),1,0))
A18: GU-TDH-016 | B18: G | C18: Sí | D18: 46308 | E18: 100 | F18: Activo | I18: 46320 | J18: Confirmado | K18: Sí | L18: 46322 | M18: =IF(A18="","",IF(AND(C18="Sí",K18="Sí",F18<>"Excluido"),1,0))
A19: GU-TDH-017 | B19: G | C19: Sí | D19: 46308 | E19: 100 | F19: Activo | I19: 46320 | J19: Confirmado | K19: Sí | L19: 46322 | M19: =IF(A19="","",IF(AND(C19="Sí",K19="Sí",F19<>"Excluido"),1,0))
A20: GU-TDH-019 | B20: G | C20: Sí | D20: 46307 | E20: 100 | F20: Activo | I20: 46320 | J20: Confirmado | K20: Sí | L20: 46321 | M20: =IF(A20="","",IF(AND(C20="Sí",K20="Sí",F20<>"Excluido"),1,0))
A21: GU-TDH-020 | B21: G | C21: Sí | D21: 46309 | E21: 100 | F21: Activo | I21: 46320 | J21: Confirmado | K21: Sí | L21: 46323 | M21: =IF(A21="","",IF(AND(C21="Sí",K21="Sí",F21<>"Excluido"),1,0))
A22: GU-TDH-021 | B22: G | C22: Sí | D22: 46307 | E22: 100 | F22: Activo | I22: 46320 | J22: Confirmado | K22: Sí | L22: 46321 | M22: =IF(A22="","",IF(AND(C22="Sí",K22="Sí",F22<>"Excluido"),1,0))
A23: GU-TDH-022 | B23: G | C23: Sí | D23: 46309 | E23: 100 | F23: Activo | I23: 46320 | J23: Confirmado | K23: Sí | L23: 46323 | M23: =IF(A23="","",IF(AND(C23="Sí",K23="Sí",F23<>"Excluido"),1,0))
A24: GU-TDH-023 | B24: G | C24: Sí | D24: 46311 | E24: 100 | F24: Activo | I24: 46320 | J24: Confirmado | K24: Sí | L24: 46325 | M24: =IF(A24="","",IF(AND(C24="Sí",K24="Sí",F24<>"Excluido"),1,0))
A25: GU-TDH-024 | B25: G | C25: Sí | D25: 46309 | E25: 100 | F25: Activo | I25: 46320 | J25: Confirmado | K25: Sí | L25: 46323 | M25: =IF(A25="","",IF(AND(C25="Sí",K25="Sí",F25<>"Excluido"),1,0))
A26: GU-TDH-025 | B26: G | C26: Sí | D26: 46311 | E26: 100 | F26: Activo | I26: 46320 | J26: Confirmado | K26: Sí | L26: 46325 | M26: =IF(A26="","",IF(AND(C26="Sí",K26="Sí",F26<>"Excluido"),1,0))
A27: GU-TDH-026 | B27: G | C27: Sí | D27: 46312 | E27: 100 | F27: Activo | I27: 46320 | J27: Confirmado | K27: Sí | L27: 46326 | M27: =IF(A27="","",IF(AND(C27="Sí",K27="Sí",F27<>"Excluido"),1,0))
A28: GU-TDH-027 | B28: G | C28: Sí | D28: 46310 | E28: 100 | F28: Activo | I28: 46320 | J28: Confirmado | K28: Sí | L28: 46324 | M28: =IF(A28="","",IF(AND(C28="Sí",K28="Sí",F28<>"Excluido"),1,0))
A29: GU-TDH-028 | B29: G | C29: Sí | D29: 46307 | E29: 100 | F29: Activo | I29: 46320 | J29: Confirmado | K29: Sí | L29: 46321 | M29: =IF(A29="","",IF(AND(C29="Sí",K29="Sí",F29<>"Excluido"),1,0))
... A32: GU-TDH-032 | B32: G | C32: Sí | D32: 46312 | E32: 100 | F32: Activo | I32: 46320 | J32: Confirmado | K32: Sí | L32: 46326 | M32: =IF(A32="","",IF(AND(C32="Sí",K32="Sí",F32<>"Excluido"),1,0))
A33: GU-TDH-033 | B33: G | C33: Sí | D33: 46311 | E33: 0 | F33: Retirado | G33: 46316 | H33: Inasistencia fuera de la ventana | I33: 46320 | J33: Pérdida muestral | K33: No | M33: =IF(A33="","",IF(AND(C33="Sí",K33="Sí",F33<>"Excluido"),1,0))
A34: GU-TDH-034 | B34: G | C34: Sí | D34: 46308 | E34: 100 | F34: Activo | I34: 46320 | J34: Confirmado | K34: Sí | L34: 46322 | M34: =IF(A34="","",IF(AND(C34="Sí",K34="Sí",F34<>"Excluido"),1,0))
A35: GU-TDH-035 | B35: G | C35: Sí | D35: 46312 | E35: 100 | F35: Activo | I35: 46320 | J35: Confirmado | K35: Sí | L35: 46326 | M35: =IF(A35="","",IF(AND(C35="Sí",K35="Sí",F35<>"Excluido"),1,0)) | N35: Reprogramado dentro de la ventana, en la misma franja horaria.
A36: GU-TDH-036 | B36: G | C36: Sí | D36: 46307 | E36: 100 | F36: Activo | I36: 46320 | J36: Confirmado | K36: Sí | L36: 46321 | M36: =IF(A36="","",IF(AND(C36="Sí",K36="Sí",F36<>"Excluido"),1,0))
A37: GU-TDH-038 | B37: G | C37: Sí | D37: 46310 | E37: 100 | F37: Activo | I37: 46320 | J37: Confirmado | K37: Sí | L37: 46324 | M37: =IF(A37="","",IF(AND(C37="Sí",K37="Sí",F37<>"Excluido"),1,0))
A38: GU-TDH-039 | B38: G | C38: Sí | D38: 46309 | E38: 100 | F38: Activo | I38: 46320 | J38: Confirmado | K38: Sí | L38: 46323 | M38: =IF(A38="","",IF(AND(C38="Sí",K38="Sí",F38<>"Excluido"),1,0))
A39: GU-TDH-040 | B39: G | C39: Sí | D39: 46311 | E39: 100 | F39: Activo | I39: 46320 | J39: Confirmado | K39: Sí | L39: 46325 | M39: =IF(A39="","",IF(AND(C39="Sí",K39="Sí",F39<>"Excluido"),1,0))
A40: GU-TDH-041 | B40: G | C40: Sí | D40: 46311 | E40: 100 | F40: Activo | I40: 46320 | J40: Confirmado | K40: Sí | L40: 46325 | M40: =IF(A40="","",IF(AND(C40="Sí",K40="Sí",F40<>"Excluido"),1,0))
A41: GU-TDH-042 | B41: G | C41: Sí | D41: 46307 | E41: 100 | F41: Activo | I41: 46320 | J41: Confirmado | K41: Sí | L41: 46321 | M41: =IF(A41="","",IF(AND(C41="Sí",K41="Sí",F41<>"Excluido"),1,0))
A42: GU-TDH-043 | B42: G | C42: Sí | D42: 46309 | E42: 100 | F42: Activo | I42: 46320 | J42: Confirmado | K42: Sí | L42: 46323 | M42: =IF(A42="","",IF(AND(C42="Sí",K42="Sí",F42<>"Excluido"),1,0))
A43: GU-TDH-045 | B43: G | C43: Sí | D43: 46308 | E43: 100 | F43: Activo | I43: 46320 | J43: Confirmado | K43: Sí | L43: 46322 | M43: =IF(A43="","",IF(AND(C43="Sí",K43="Sí",F43<>"Excluido"),1,0))
...

Sheet 3_Mortalidad
A1: Paso 5 · Mortalidad experimental, pérdida total y flujo de participantes
A2: Se calcula automáticamente a partir de la hoja 2_Participantes. Mortalidad experimental = retirados ÷ n pretest; pérdida total incluye además a los excluidos.
A4: Resumen por grupo
A5: Grupo | B5: n pretest | C5: Retirados | D5: Excluidos | E5: Postest rendido | F5: Pares analizados | G5: Mortalidad experimental | H5: Clasificación | I5: Pérdida total | J5: Clasificación de la pérdida total | L5: Grupo | M5: Pretest (n) | N5: Postest (n)
A6: GE · experimental | B6: =COUNTIFS('2_Participantes'!$B$6:$B$305,"GE",'2_Participantes'!$C$6:$C$305,"Sí") | C6: =COUNTIFS('2_Participantes'!$B$6:$B$305,"GE",'2_Participantes'!$F$6:$F$305,"Retirado") | D6: =COUNTIFS('2_Participantes'!$B$6:$B$305,"GE",'2_Participantes'!$F$6:$F$305,"Excluido") | E6: =COUNTIFS('2_Participantes'!$B$6:$B$305,"GE",'2_Participantes'!$K$6:$K$305,"Sí") | F6: =SUMIFS('2_Participantes'!$M$6:$M$305,'2_Participantes'!$B$6:$B$305,"GE") | G6: =IF(B6=0,"",C6/B6) | H6: =IF(G6="","",IF(G6<0.05,"Baja",IF(G6<=0.2,"Moderada","Alta"))) | I6: =IF(B6=0,"",(B6-F6)/B6) | J6: =IF(I6="","",IF(I6<0.05,"Baja",IF(I6<=0.2,"Moderada","Alta"))) | L6: GE | M6: =B6 | N6: =E6
A7: GC · comparación | B7: =COUNTIFS('2_Participantes'!$B$6:$B$305,"GC",'2_Participantes'!$C$6:$C$305,"Sí") | C7: =COUNTIFS('2_Participantes'!$B$6:$B$305,"GC",'2_Participantes'!$F$6:$F$305,"Retirado") | D7: =COUNTIFS('2_Participantes'!$B$6:$B$305,"GC",'2_Participantes'!$F$6:$F$305,"Excluido") | E7: =COUNTIFS('2_Participantes'!$B$6:$B$305,"GC",'2_Participantes'!$K$6:$K$305,"Sí") | F7: =SUMIFS('2_Participantes'!$M$6:$M$305,'2_Participantes'!$B$6:$B$305,"GC") | G7: =IF(B7=0,"",C7/B7) | H7: =IF(G7="","",IF(G7<0.05,"Baja",IF(G7<=0.2,"Moderada","Alta"))) | I7: =IF(B7=0,"",(B7-F7)/B7) | J7: =IF(I7="","",IF(I7<0.05,"Baja",IF(I7<=0.2,"Moderada","Alta"))) | L7: GC | M7: =B7 | N7: =E7
A8: G · grupo único | B8: =COUNTIFS('2_Participantes'!$B$6:$B$305,"G",'2_Participantes'!$C$6:$C$305,"Sí") | C8: =COUNTIFS('2_Participantes'!$B$6:$B$305,"G",'2_Participantes'!$F$6:$F$305,"Retirado") | D8: =COUNTIFS('2_Participantes'!$B$6:$B$305,"G",'2_Participantes'!$F$6:$F$305,"Excluido") | E8: =COUNTIFS('2_Participantes'!$B$6:$B$305,"G",'2_Participantes'!$K$6:$K$305,"Sí") | F8: =SUMIFS('2_Participantes'!$M$6:$M$305,'2_Participantes'!$B$6:$B$305,"G") | G8: =IF(B8=0,"",C8/B8) | H8: =IF(G8="","",IF(G8<0.05,"Baja",IF(G8<=0.2,"Moderada","Alta"))) | I8: =IF(B8=0,"",(B8-F8)/B8) | J8: =IF(I8="","",IF(I8<0.05,"Baja",IF(I8<=0.2,"Moderada","Alta")))
A10: Mortalidad diferencial GE − GC (no aplica: diseño de grupo único) | G10: =IF(OR(G6="",G7=""),"",ABS(G6-G7)) | H10: =IF(G10="","",IF(G10<=0.05,"Diferencia pequeña","Revisar la equivalencia de los grupos"))
A11: Referencia (Schulz y Grimes, 2002): < 5 % baja; 5 % a 20 % moderada (comparar la línea base de quienes se retiran con la de quienes permanecen); > 20 % alta. Ningún participante perdido se reemplaza.
A13: Motivos de retiro o exclusión
A14: Motivo | B14: GE | C14: GC | D14: G | E14: Total
A15: Renuncia | B15: =COUNTIFS('2_Participantes'!$B$6:$B$305,"GE",'2_Participantes'!$H$6:$H$305,"Renuncia") | C15: =COUNTIFS('2_Participantes'!$B$6:$B$305,"GC",'2_Participantes'!$H$6:$H$305,"Renuncia") | D15: =COUNTIFS('2_Participantes'!$B$6:$B$305,"G",'2_Participantes'!$H$6:$H$305,"Renuncia") | E15: =SUM(B15:D15)
A16: Licencia | B16: =COUNTIFS('2_Participantes'!$B$6:$B$305,"GE",'2_Participantes'!$H$6:$H$305,"Licencia") | C16: =COUNTIFS('2_Participantes'!$B$6:$B$305,"GC",'2_Participantes'!$H$6:$H$305,"Licencia") | D16: =COUNTIFS('2_Participantes'!$B$6:$B$305,"G",'2_Participantes'!$H$6:$H$305,"Licencia") | E16: =SUM(B16:D16)
A17: Rotación o cambio de sede | B17: =COUNTIFS('2_Participantes'!$B$6:$B$305,"GE",'2_Participantes'!$H$6:$H$305,"Rotación o cambio de sede") | C17: =COUNTIFS('2_Participantes'!$B$6:$B$305,"GC",'2_Participantes'!$H$6:$H$305,"Rotación o cambio de sede") | D17: =COUNTIFS('2_Participantes'!$B$6:$B$305,"G",'2_Participantes'!$H$6:$H$305,"Rotación o cambio de sede") | E17: =SUM(B17:D17)
A18: Retiro de consentimiento | B18: =COUNTIFS('2_Participantes'!$B$6:$B$305,"GE",'2_Participantes'!$H$6:$H$305,"Retiro de consentimiento") | C18: =COUNTIFS('2_Participantes'!$B$6:$B$305,"GC",'2_Participantes'!$H$6:$H$305,"Retiro de consentimiento") | D18: =COUNTIFS('2_Participantes'!$B$6:$B$305,"G",'2_Participantes'!$H$6:$H$305,"Retiro de consentimiento") | E18: =SUM(B18:D18)
A19: Inasistencia fuera de la ventana | B19: =COUNTIFS('2_Participantes'!$B$6:$B$305,"GE",'2_Participantes'!$H$6:$H$305,"Inasistencia fuera de la ventana") | C19: =COUNTIFS('2_Participantes'!$B$6:$B$305,"GC",'2_Participantes'!$H$6:$H$305,"Inasistencia fuera de la ventana") | D19: =COUNTIFS('2_Participantes'!$B$6:$B$305,"G",'2_Participantes'!$H$6:$H$305,"Inasistencia fuera de la ventana") | E19: =SUM(B19:D19)
A20: Registro inutilizable | B20: =COUNTIFS('2_Participantes'!$B$6:$B$305,"GE",'2_Participantes'!$H$6:$H$305,"Registro inutilizable") | C20: =COUNTIFS('2_Participantes'!$B$6:$B$305,"GC",'2_Participantes'!$H$6:$H$305,"Registro inutilizable") | D20: =COUNTIFS('2_Participantes'!$B$6:$B$305,"G",'2_Participantes'!$H$6:$H$305,"Registro inutilizable") | E20: =SUM(B20:D20)
A21: Otro | B21: =COUNTIFS('2_Participantes'!$B$6:$B$305,"GE",'2_Participantes'!$H$6:$H$305,"Otro") | C21: =COUNTIFS('2_Participantes'!$B$6:$B$305,"GC",'2_Participantes'!$H$6:$H$305,"Otro") | D21: =COUNTIFS('2_Participantes'!$B$6:$B$305,"G",'2_Participantes'!$H$6:$H$305,"Otro") | E21: =SUM(B21:D21)
A22: Total | B22: =SUM(B15:B21) | C22: =SUM(C15:C21) | D22: =SUM(D15:D21) | E22: =SUM(E15:E21)
A24: Flujo de participantes (texto para el informe y el diagrama)
A25: Evaluados en el pretest (O₁) | D25: ="G (grupo único): n = "&B8
A26: Retirados durante la intervención | D26: ="G: "&C8
A27: Excluidos (p. ej., retiro del consentimiento) | D27: ="G: "&D8
A28: Evaluados en el postest (O₂) | D28: ="G: n = "&E8
A29: Pares pretest–postest analizados | D29: ="G: n = "&F8&" ("&TEXT(IF(B8=0,0,F8/B8),"0.0%")&")"

Sheet 4_Equivalencia
A1: Paso 3 · Lista de cotejo de equivalencia de condiciones pretest–postest
A2: Coteje cada condición con el acta de aplicación del pretest antes de medir. Cada «No» exige una medida de control y una incidencia registrada.
A4: N.º | B4: Condición | C4: Pretest (según acta) | D4: Postest (previsto o ejecutado) | E4: ¿Equivale? | F4: Medida de control y evidencia
A5: 1 | B5: Instrumento y versión | C5: Cuestionario SUS (10 ítems), cuestionario de satisfacción (8 ítems) y ficha de tiempos y clics, versión validada | D5: Los mismos instrumentos y la misma versión | E5: Sí | F5: Mismo módulo del experimento; versión de los cuestionarios sin cambios.
A6: 2 | B6: Forma de aplicación (impreso o digital) | C6: Digital, en el módulo del experimento | D6: Digital, en el módulo del experimento | E6: Sí | F6: Misma interfaz de cuestionarios.
A7: 3 | B7: Guion de instrucciones (textual) | C7: Guion de la Sesión 02, hoja 1 | D7: El mismo guion, leído textualmente | E7: Sí | F7: Guion impreso y en PDF.
A8: 4 | B8: Aplicador u observador | C8: M. Trujillo y A. Godoy | D8: M. Trujillo y A. Godoy | E8: Sí | F8: Mismo aplicador por participante en lo posible.
A9: 5 | B9: Lugar, equipos y conectividad | C9: Dispositivo propio y conexión habitual; búsqueda en el portal actual | D9: Mismo tipo de dispositivo y conexión habitual; búsqueda en la aplicación | E9: Sí | F9: El cambio de plataforma es la intervención (X); el dispositivo se mantiene.
A10: 6 | B10: Días de la semana y franja horaria | C10: Lunes a sábado; 10:00–13:00 o 16:00–19:00 | D10: Lunes a sábado; misma franja y mismo día de la semana de su pretest | E10: Sí | F10: Postest programado 14 días después de cada pretest.
A11: 7 | B11: Duración y número de observaciones | C11: 2 tareas de búsqueda (máx. 300 s c/u) + SUS + satisfacción | D11: 2 tareas de búsqueda (máx. 300 s c/u) + SUS + satisfacción | E11: Sí | F11: Noticias equivalentes en dificultad (tareas 3 y 4).
A12: 8 | B12: Criterios de inicio y fin de cada medición | C12: Inicio: clic en «Comenzar tarea»; fin: apertura de la noticia correcta o 300 s | D12: Los mismos criterios | E12: Sí | F12: Mismo cronómetro del módulo.
A13: 9 | B13: Unidad de medida y escala | C13: Segundos, clics, puntos SUS (0–100), satisfacción (8–40) | D13: Las mismas unidades | E13: Sí | F13: Diccionario de variables (Sesión 03).
A14: 10 | B14: Codificación de participantes | C14: 108 códigos GU-TDH de la base del pretest (sesión 3). Sin GU-TDH-001. | D14: Los mismos códigos | E14: Sí | F14: Verificación del código antes de habilitar las tareas.
A15: 11 | B15: Secuencia de ítems o de tareas | C15: Tarea 1 → tarea 2 → SUS → satisfacción | D15: Tarea 3 → tarea 4 → SUS → satisfacción | E15: Sí | F15: Mismo orden de ítems.
A16: 12 | B16: Ventana de aplicación (hasta 5 días hábiles tras el cierre) | C16: 12–17/10/2026, antes de la intervención | D16: 26–31/10/2026, de 1 a 5 días hábiles tras el cierre (02/11) | E16: Sí | F16: Ventana de 5 días hábiles respetada.
B18: Condiciones equivalentes | C18: =COUNTIF(E5:E16,"Sí")&" de 12"
B19: Resultado | C19: =IF(COUNTIF(E5:E16,"Sí")=12,"Equivalencia total: aplicar el postest",IF(COUNTIF(E5:E16,"Sí")>=10,"Equivalente con observaciones: registrar cada No como incidencia con su medida de control","Revisar con el asesor antes de medir"))
B20: Las condiciones no equivalentes se reportan en el informe de postest como limitación, con la medida de control aplicada.

Sheet 5_Incidencias
A1: Paso 5 · Registro de incidencias del cierre y del postest
A2: La numeración continúa la del registro de monitoreo (semana 6). Tipos: técnica, metodológica, ética, logística y pérdida muestral.
A3: Total | B3: =COUNTA(B6:B205) | F3: Por tipo: | G3: ="Técnica: "&COUNTIF(F6:F205,"Técnica") | H3: ="Metodológica: "&COUNTIF(F6:F205,"Metodológica") | I3: ="Ética: "&COUNTIF(F6:F205,"Ética") | J3: ="Logística: "&COUNTIF(F6:F205,"Logística") | K3: ="Pérdida muestral: "&COUNTIF(F6:F205,"Pérdida muestral") | L3: En curso | M3: =COUNTIF(L6:L205,"En curso")
A5: N.º | B5: Fecha | C5: Hora | D5: Fase | E5: Código | F5: Tipo | G5: Descripción objetiva | H5: Efecto en la medición o en la muestra | I5: Acción tomada | J5: Responsable | K5: Fecha de la acción | L5: Estado | M5: Evidencia
A6: =IF(B6="","",ROW()-5) | B6: 46316 | C6: 20:15 | D6: Cierre | E6: G (grupo) | F6: Técnica | G6: Latencia alta del asistente (respuestas de más de 10 s) durante unos 25 minutos por saturación de la API del LLM. | H6: Posible menor uso ese día; no afecta la medición. | I6: Se activó la clave de API de respaldo y la caché semántica (matriz de riesgos, riesgo 16). | J6: Tesista (desarrollador) | K6: 46316 | L6: Resuelta | M6: Registro del servidor y bitácora de soporte
A7: =IF(B7="","",ROW()-5) | B7: 46318 | C7: 11:40 | D7: Cierre | E7: GU-TDH-017 | F7: Técnica | G7: El lector reportó que la PWA no se instalaba en su celular (iOS). | H7: Ninguno: siguió usando la aplicación desde el navegador. | I7: Se envió por WhatsApp la guía para agregar a la pantalla de inicio. | J7: Tesista | K7: 46318 | L7: Resuelta | M7: Captura del chat de soporte
A8: =IF(B8="","",ROW()-5) | B8: 46327 | D8: Postest | E8: GU-TDH-006 | F8: Pérdida muestral | G8: No rindió el postest dentro de la ventana; usó la aplicación 0 día(s) durante la intervención. | H8: No hay par pretest–postest; se reduce el n analizado. | I8: Tres recordatorios y reprogramación de 72 h; se registró el motivo y no se reemplazó. | J8: Tesista | K8: 46327 | L8: Cerrada con limitación | M8: Libro de códigos y mensajes de WhatsApp
A9: =IF(B9="","",ROW()-5) | B9: 46327 | D9: Postest | E9: GU-TDH-053 | F9: Pérdida muestral | G9: No rindió el postest dentro de la ventana; usó la aplicación 1 día(s) durante la intervención. | H9: No hay par pretest–postest; se reduce el n analizado. | I9: Tres recordatorios y reprogramación de 72 h; se registró el motivo y no se reemplazó. | J9: Tesista | K9: 46327 | L9: Cerrada con limitación | M9: Libro de códigos y mensajes de WhatsApp
A10: =IF(B10="","",ROW()-5) | B10: 46327 | D10: Postest | E10: GU-TDH-069 | F10: Pérdida muestral | G10: No rindió el postest dentro de la ventana; usó la aplicación 1 día(s) durante la intervención. | H10: No hay par pretest–postest; se reduce el n analizado. | I10: Tres recordatorios y reprogramación de 72 h; se registró el motivo y no se reemplazó. | J10: Tesista | K10: 46327 | L10: Cerrada con limitación | M10: Libro de códigos y mensajes de WhatsApp
A11: =IF(B11="","",ROW()-5) | B11: 46327 | D11: Postest | E11: GU-TDH-084 | F11: Pérdida muestral | G11: No rindió el postest dentro de la ventana; usó la aplicación 2 día(s) durante la intervención. | H11: No hay par pretest–postest; se reduce el n analizado. | I11: Tres recordatorios y reprogramación de 72 h; se registró el motivo y no se reemplazó. | J11: Tesista | K11: 46327 | L11: Cerrada con limitación | M11: Libro de códigos y mensajes de WhatsApp
A12: =IF(B12="","",ROW()-5) | B12: 46327 | D12: Postest | E12: GU-TDH-109 | F12: Pérdida muestral | G12: No rindió el postest dentro de la ventana; usó la aplicación 1 día(s) durante la intervención. | H12: No hay par pretest–postest; se reduce el n analizado. | I12: Tres recordatorios y reprogramación de 72 h; se registró el motivo y no se reemplazó. | J12: Tesista | K12: 46327 | L12: Cerrada con limitación | M12: Libro de códigos y mensajes de WhatsApp
A13: =IF(B13="","",ROW()-5) | B13: 46321 | C13: 10:25 | D13: Postest | E13: GU-TDH-004 | F13: Técnica | G13: Corte de internet del participante durante la tarea 3. | H13: Se repitió la tarea completa al reconectarse. | I13: Se conservó solo el segundo intento, según el protocolo del pretest. | J13: Aplicador de apoyo | K13: 46321 | L13: Resuelta | M13: Registro del módulo del experimento
A14: =IF(B14="","",ROW()-5) | B14: 46323 | C14: 17:05 | D14: Postest | E14: GU-TDH-047 | F14: Metodológica | G14: No localizó la noticia de la tarea 4 en el tiempo límite. | H14: Se registra 300 s y «no completada». | I14: Se aplicó el criterio declarado (300 s = tope, dato válido). | J14: Tesista | K14: 46323 | L14: Resuelta | M14: Registro del módulo del experimento
A15: =IF(B15="","",ROW()-5) | B15: 46324 | C15: 11:15 | D15: Postest | E15: GU-TDH-050 | F15: Logística | G15: Pidió cambiar su postest de la franja de mañana a la de tarde. | H15: Cambio de franja respecto a su pretest. | I15: Se mantuvo la franja de mañana con otro día de la ventana (mismo día de la semana no posible). | J15: Aplicador de apoyo | K15: 46325 | L15: Cerrada con limitación | M15: Correo de confirmación
A16: =IF(B16="","",ROW()-5) | B16: 46325 | C16: 16:30 | D16: Postest | E16: G (grupo) | F16: Ética | G16: Un participante preguntó si su opinión sería vista por el diario. | H16: Ninguno. | I16: Se repitió la cláusula de confidencialidad del consentimiento: solo se reporta con código. | J16: Tesista | K16: 46325 | L16: Resuelta | M16: Registro de soporte
A17: =IF(B17="","",ROW()-5)
A18: =IF(B18="","",ROW()-5)
A19: =IF(B19="","",ROW()-5)
A20: =IF(B20="","",ROW()-5)
A21: =IF(B21="","",ROW()-5)
A22: =IF(B22="","",ROW()-5)
A23: =IF(B23="","",ROW()-5)
A24: =IF(B24="","",ROW()-5)
A25: =IF(B25="","",ROW()-5)
A26: =IF(B26="","",ROW()-5)
A27: =IF(B27="","",ROW()-5)
A28: =IF(B28="","",ROW()-5)
... A205: =IF(B205="","",ROW()-5)

Sheet 6_Base_Postest
A1: Paso 6 · Base consolidada pretest–postest y verificación de correspondencia
A2: Una fila por código. GRUPO, ADH, ESTADO y FECHA_POST se toman automáticamente de 2_Participantes; VD_PRE proviene de la base del pretest (semana 3) y VD_POST del postest. VD_POST es SUS simulado, no medición de campo.
A5: CODIGO | B5: GRUPO | C5: VD_PRE | D5: VD_POST | E5: DIF (POST − PRE) | F5: ADH (%) | G5: ESTADO | H5: FECHA_POST | I5: PAR_COMPLETO | J5: CONTROL DE CALIDAD | L5: Verificación de la base
A6: GU-TDH-002 | B6: {=IF(A6="","",IFERROR(IF(INDEX('2_Participantes'!$B$6:$B$305,MATCH(A6,'2_Participantes'!$A$6:$A$305,0))="","",INDEX('2_Participantes'!$B$6:$B$305,MATCH(A6,'2_Participantes'!$A$6:$A$305,0))),"No registrado"))} | C6: 75 | D6: 90 | E6: =IF(AND(ISNUMBER(C6),ISNUMBER(D6)),D6-C6,"") | F6: {=IF(A6="","",IFERROR(IF(INDEX('2_Participantes'!$E$6:$E$305,MATCH(A6,'2_Participantes'!$A$6:$A$305,0))="","",INDEX('2_Participantes'!$E$6:$E$305,MATCH(A6,'2_Participantes'!$A$6:$A$305,0))),""))} | G6: {=IF(A6="","",IFERROR(IF(INDEX('2_Participantes'!$F$6:$F$305,MATCH(A6,'2_Participantes'!$A$6:$A$305,0))="","",INDEX('2_Participantes'!$F$6:$F$305,MATCH(A6,'2_Participantes'!$A$6:$A$305,0))),"No registrado"))} | H6: {=IF(A6="","",IFERROR(IF(INDEX('2_Participantes'!$L$6:$L$305,MATCH(A6,'2_Participantes'!$A$6:$A$305,0))="","",INDEX('2_Participantes'!$L$6:$L$305,MATCH(A6,'2_Participantes'!$A$6:$A$305,0))),""))} | I6: =IF(A6="","",IF(AND(ISNUMBER(C6),ISNUMBER(D6),G6<>"Excluido"),1,0)) | J6: =IF(A6="","",IF(G6="No registrado","Código ausente en 2_Participantes",IF(AND(ISNUMBER(D6),NOT(ISNUMBER(C6))),"Postest sin pretest (huérfano)",IF(OR(AND(ISNUMBER(C6),OR(C6<Inicio!$C$18,C6>Inicio!$C$19)),AND(ISNUMBER(D6),OR(D6<Inicio!$C$18,D6>Inicio!$C$19))),"Fuera de rango",IF(COUNTIF($A$6:$A$305,A6)>1,"Código duplicado","OK"))))) | L6: Registros (códigos) | M6: =COUNTA(A6:A305)
A7: GU-TDH-003 | B7: {=IF(A7="","",IFERROR(IF(INDEX('2_Participantes'!$B$6:$B$305,MATCH(A7,'2_Participantes'!$A$6:$A$305,0))="","",INDEX('2_Participantes'!$B$6:$B$305,MATCH(A7,'2_Participantes'!$A$6:$A$305,0))),"No registrado"))} | C7: 55 | D7: 75 | E7: =IF(AND(ISNUMBER(C7),ISNUMBER(D7)),D7-C7,"") | F7: {=IF(A7="","",IFERROR(IF(INDEX('2_Participantes'!$E$6:$E$305,MATCH(A7,'2_Participantes'!$A$6:$A$305,0))="","",INDEX('2_Participantes'!$E$6:$E$305,MATCH(A7,'2_Participantes'!$A$6:$A$305,0))),""))} | G7: {=IF(A7="","",IFERROR(IF(INDEX('2_Participantes'!$F$6:$F$305,MATCH(A7,'2_Participantes'!$A$6:$A$305,0))="","",INDEX('2_Participantes'!$F$6:$F$305,MATCH(A7,'2_Participantes'!$A$6:$A$305,0))),"No registrado"))} | H7: {=IF(A7="","",IFERROR(IF(INDEX('2_Participantes'!$L$6:$L$305,MATCH(A7,'2_Participantes'!$A$6:$A$305,0))="","",INDEX('2_Participantes'!$L$6:$L$305,MATCH(A7,'2_Participantes'!$A$6:$A$305,0))),""))} | I7: =IF(A7="","",IF(AND(ISNUMBER(C7),ISNUMBER(D7),G7<>"Excluido"),1,0)) | J7: =IF(A7="","",IF(G7="No registrado","Código ausente en 2_Participantes",IF(AND(ISNUMBER(D7),NOT(ISNUMBER(C7))),"Postest sin pretest (huérfano)",IF(OR(AND(ISNUMBER(C7),OR(C7<Inicio!$C$18,C7>Inicio!$C$19)),AND(ISNUMBER(D7),OR(D7<Inicio!$C$18,D7>Inicio!$C$19))),"Fuera de rango",IF(COUNTIF($A$6:$A$305,A7)>1,"Código duplicado","OK"))))) | L7: Con VD_PRE | M7: =COUNT(C6:C305)
A8: GU-TDH-004 | B8: {=IF(A8="","",IFERROR(IF(INDEX('2_Participantes'!$B$6:$B$305,MATCH(A8,'2_Participantes'!$A$6:$A$305,0))="","",INDEX('2_Participantes'!$B$6:$B$305,MATCH(A8,'2_Participantes'!$A$6:$A$305,0))),"No registrado"))} | C8: 42.5 | D8: 67.5 | E8: =IF(AND(ISNUMBER(C8),ISNUMBER(D8)),D8-C8,"") | F8: {=IF(A8="","",IFERROR(IF(INDEX('2_Participantes'!$E$6:$E$305,MATCH(A8,'2_Participantes'!$A$6:$A$305,0))="","",INDEX('2_Participantes'!$E$6:$E$305,MATCH(A8,'2_Participantes'!$A$6:$A$305,0))),""))} | G8: {=IF(A8="","",IFERROR(IF(INDEX('2_Participantes'!$F$6:$F$305,MATCH(A8,'2_Participantes'!$A$6:$A$305,0))="","",INDEX('2_Participantes'!$F$6:$F$305,MATCH(A8,'2_Participantes'!$A$6:$A$305,0))),"No registrado"))} | H8: {=IF(A8="","",IFERROR(IF(INDEX('2_Participantes'!$L$6:$L$305,MATCH(A8,'2_Participantes'!$A$6:$A$305,0))="","",INDEX('2_Participantes'!$L$6:$L$305,MATCH(A8,'2_Participantes'!$A$6:$A$305,0))),""))} | I8: =IF(A8="","",IF(AND(ISNUMBER(C8),ISNUMBER(D8),G8<>"Excluido"),1,0)) | J8: =IF(A8="","",IF(G8="No registrado","Código ausente en 2_Participantes",IF(AND(ISNUMBER(D8),NOT(ISNUMBER(C8))),"Postest sin pretest (huérfano)",IF(OR(AND(ISNUMBER(C8),OR(C8<Inicio!$C$18,C8>Inicio!$C$19)),AND(ISNUMBER(D8),OR(D8<Inicio!$C$18,D8>Inicio!$C$19))),"Fuera de rango",IF(COUNTIF($A$6:$A$305,A8)>1,"Código duplicado","OK"))))) | L8: Con VD_POST | M8: =COUNT(D6:D305)
A9: GU-TDH-006 | B9: {=IF(A9="","",IFERROR(IF(INDEX('2_Participantes'!$B$6:$B$305,MATCH(A9,'2_Participantes'!$A$6:$A$305,0))="","",INDEX('2_Participantes'!$B$6:$B$305,MATCH(A9,'2_Participantes'!$A$6:$A$305,0))),"No registrado"))} | C9: 75 | D9: 80 | E9: =IF(AND(ISNUMBER(C9),ISNUMBER(D9)),D9-C9,"") | F9: {=IF(A9="","",IFERROR(IF(INDEX('2_Participantes'!$E$6:$E$305,MATCH(A9,'2_Participantes'!$A$6:$A$305,0))="","",INDEX('2_Participantes'!$E$6:$E$305,MATCH(A9,'2_Participantes'!$A$6:$A$305,0))),""))} | G9: {=IF(A9="","",IFERROR(IF(INDEX('2_Participantes'!$F$6:$F$305,MATCH(A9,'2_Participantes'!$A$6:$A$305,0))="","",INDEX('2_Participantes'!$F$6:$F$305,MATCH(A9,'2_Participantes'!$A$6:$A$305,0))),"No registrado"))} | H9: {=IF(A9="","",IFERROR(IF(INDEX('2_Participantes'!$L$6:$L$305,MATCH(A9,'2_Participantes'!$A$6:$A$305,0))="","",INDEX('2_Participantes'!$L$6:$L$305,MATCH(A9,'2_Participantes'!$A$6:$A$305,0))),""))} | I9: =IF(A9="","",IF(AND(ISNUMBER(C9),ISNUMBER(D9),G9<>"Excluido"),1,0)) | J9: =IF(A9="","",IF(G9="No registrado","Código ausente en 2_Participantes",IF(AND(ISNUMBER(D9),NOT(ISNUMBER(C9))),"Postest sin pretest (huérfano)",IF(OR(AND(ISNUMBER(C9),OR(C9<Inicio!$C$18,C9>Inicio!$C$19)),AND(ISNUMBER(D9),OR(D9<Inicio!$C$18,D9>Inicio!$C$19))),"Fuera de rango",IF(COUNTIF($A$6:$A$305,A9)>1,"Código duplicado","OK"))))) | L9: Pares completos analizables | M9: =SUM(I6:I305)
A10: GU-TDH-007 | B10: {=IF(A10="","",IFERROR(IF(INDEX('2_Participantes'!$B$6:$B$305,MATCH(A10,'2_Participantes'!$A$6:$A$305,0))="","",INDEX('2_Participantes'!$B$6:$B$305,MATCH(A10,'2_Participantes'!$A$6:$A$305,0))),"No registrado"))} | C10: 55 | D10: 85 | E10: =IF(AND(ISNUMBER(C10),ISNUMBER(D10)),D10-C10,"") | F10: {=IF(A10="","",IFERROR(IF(INDEX('2_Participantes'!$E$6:$E$305,MATCH(A10,'2_Participantes'!$A$6:$A$305,0))="","",INDEX('2_Participantes'!$E$6:$E$305,MATCH(A10,'2_Participantes'!$A$6:$A$305,0))),""))} | G10: {=IF(A10="","",IFERROR(IF(INDEX('2_Participantes'!$F$6:$F$305,MATCH(A10,'2_Participantes'!$A$6:$A$305,0))="","",INDEX('2_Participantes'!$F$6:$F$305,MATCH(A10,'2_Participantes'!$A$6:$A$305,0))),"No registrado"))} | H10: {=IF(A10="","",IFERROR(IF(INDEX('2_Participantes'!$L$6:$L$305,MATCH(A10,'2_Participantes'!$A$6:$A$305,0))="","",INDEX('2_Participantes'!$L$6:$L$305,MATCH(A10,'2_Participantes'!$A$6:$A$305,0))),""))} | I10: =IF(A10="","",IF(AND(ISNUMBER(C10),ISNUMBER(D10),G10<>"Excluido"),1,0)) | J10: =IF(A10="","",IF(G10="No registrado","Código ausente en 2_Participantes",IF(AND(ISNUMBER(D10),NOT(ISNUMBER(C10))),"Postest sin pretest (huérfano)",IF(OR(AND(ISNUMBER(C10),OR(C10<Inicio!$C$18,C10>Inicio!$C$19)),AND(ISNUMBER(D10),OR(D10<Inicio!$C$18,D10>Inicio!$C$19))),"Fuera de rango",IF(COUNTIF($A$6:$A$305,A10)>1,"Código duplicado","OK"))))) | L10: Códigos duplicados | M10: =COUNTIF(J6:J305,"Código duplicado")
A11: GU-TDH-008 | B11: {=IF(A11="","",IFERROR(IF(INDEX('2_Participantes'!$B$6:$B$305,MATCH(A11,'2_Participantes'!$A$6:$A$305,0))="","",INDEX('2_Participantes'!$B$6:$B$305,MATCH(A11,'2_Participantes'!$A$6:$A$305,0))),"No registrado"))} | C11: 40 | D11: 50 | E11: =IF(AND(ISNUMBER(C11),ISNUMBER(D11)),D11-C11,"") | F11: {=IF(A11="","",IFERROR(IF(INDEX('2_Participantes'!$E$6:$E$305,MATCH(A11,'2_Participantes'!$A$6:$A$305,0))="","",INDEX('2_Participantes'!$E$6:$E$305,MATCH(A11,'2_Participantes'!$A$6:$A$305,0))),""))} | G11: {=IF(A11="","",IFERROR(IF(INDEX('2_Participantes'!$F$6:$F$305,MATCH(A11,'2_Participantes'!$A$6:$A$305,0))="","",INDEX('2_Participantes'!$F$6:$F$305,MATCH(A11,'2_Participantes'!$A$6:$A$305,0))),"No registrado"))} | H11: {=IF(A11="","",IFERROR(IF(INDEX('2_Participantes'!$L$6:$L$305,MATCH(A11,'2_Participantes'!$A$6:$A$305,0))="","",INDEX('2_Participantes'!$L$6:$L$305,MATCH(A11,'2_Participantes'!$A$6:$A$305,0))),""))} | I11: =IF(A11="","",IF(AND(ISNUMBER(C11),ISNUMBER(D11),G11<>"Excluido"),1,0)) | J11: =IF(A11="","",IF(G11="No registrado","Código ausente en 2_Participantes",IF(AND(ISNUMBER(D11),NOT(ISNUMBER(C11))),"Postest sin pretest (huérfano)",IF(OR(AND(ISNUMBER(C11),OR(C11<Inicio!$C$18,C11>Inicio!$C$19)),AND(ISNUMBER(D11),OR(D11<Inicio!$C$18,D11>Inicio!$C$19))),"Fuera de rango",IF(COUNTIF($A$6:$A$305,A11)>1,"Código duplicado","OK"))))) | L11: Postest sin pretest (huérfanos) | M11: =COUNTIF(J6:J305,"Postest sin pretest (huérfano)")
A12: GU-TDH-009 | B12: {=IF(A12="","",IFERROR(IF(INDEX('2_Participantes'!$B$6:$B$305,MATCH(A12,'2_Participantes'!$A$6:$A$305,0))="","",INDEX('2_Participantes'!$B$6:$B$305,MATCH(A12,'2_Participantes'!$A$6:$A$305,0))),"No registrado"))} | C12: 50 | D12: 65 | E12: =IF(AND(ISNUMBER(C12),ISNUMBER(D12)),D12-C12,"") | F12: {=IF(A12="","",IFERROR(IF(INDEX('2_Participantes'!$E$6:$E$305,MATCH(A12,'2_Participantes'!$A$6:$A$305,0))="","",INDEX('2_Participantes'!$E$6:$E$305,MATCH(A12,'2_Participantes'!$A$6:$A$305,0))),""))} | G12: {=IF(A12="","",IFERROR(IF(INDEX('2_Participantes'!$F$6:$F$305,MATCH(A12,'2_Participantes'!$A$6:$A$305,0))="","",INDEX('2_Participantes'!$F$6:$F$305,MATCH(A12,'2_Participantes'!$A$6:$A$305,0))),"No registrado"))} | H12: {=IF(A12="","",IFERROR(IF(INDEX('2_Participantes'!$L$6:$L$305,MATCH(A12,'2_Participantes'!$A$6:$A$305,0))="","",INDEX('2_Participantes'!$L$6:$L$305,MATCH(A12,'2_Participantes'!$A$6:$A$305,0))),""))} | I12: =IF(A12="","",IF(AND(ISNUMBER(C12),ISNUMBER(D12),G12<>"Excluido"),1,0)) | J12: =IF(A12="","",IF(G12="No registrado","Código ausente en 2_Participantes",IF(AND(ISNUMBER(D12),NOT(ISNUMBER(C12))),"Postest sin pretest (huérfano)",IF(OR(AND(ISNUMBER(C12),OR(C12<Inicio!$C$18,C12>Inicio!$C$19)),AND(ISNUMBER(D12),OR(D12<Inicio!$C$18,D12>Inicio!$C$19))),"Fuera de rango",IF(COUNTIF($A$6:$A$305,A12)>1,"Código duplicado","OK"))))) | L12: Valores fuera de rango | M12: =COUNTIF(J6:J305,"Fuera de rango")
A13: GU-TDH-010 | B13: {=IF(A13="","",IFERROR(IF(INDEX('2_Participantes'!$B$6:$B$305,MATCH(A13,'2_Participantes'!$A$6:$A$305,0))="","",INDEX('2_Participantes'!$B$6:$B$305,MATCH(A13,'2_Participantes'!$A$6:$A$305,0))),"No registrado"))} | C13: 80 | D13: 90 | E13: =IF(AND(ISNUMBER(C13),ISNUMBER(D13)),D13-C13,"") | F13: {=IF(A13="","",IFERROR(IF(INDEX('2_Participantes'!$E$6:$E$305,MATCH(A13,'2_Participantes'!$A$6:$A$305,0))="","",INDEX('2_Participantes'!$E$6:$E$305,MATCH(A13,'2_Participantes'!$A$6:$A$305,0))),""))} | G13: {=IF(A13="","",IFERROR(IF(INDEX('2_Participantes'!$F$6:$F$305,MATCH(A13,'2_Participantes'!$A$6:$A$305,0))="","",INDEX('2_Participantes'!$F$6:$F$305,MATCH(A13,'2_Participantes'!$A$6:$A$305,0))),"No registrado"))} | H13: {=IF(A13="","",IFERROR(IF(INDEX('2_Participantes'!$L$6:$L$305,MATCH(A13,'2_Participantes'!$A$6:$A$305,0))="","",INDEX('2_Participantes'!$L$6:$L$305,MATCH(A13,'2_Participantes'!$A$6:$A$305,0))),""))} | I13: =IF(A13="","",IF(AND(ISNUMBER(C13),ISNUMBER(D13),G13<>"Excluido"),1,0)) | J13: =IF(A13="","",IF(G13="No registrado","Código ausente en 2_Participantes",IF(AND(ISNUMBER(D13),NOT(ISNUMBER(C13))),"Postest sin pretest (huérfano)",IF(OR(AND(ISNUMBER(C13),OR(C13<Inicio!$C$18,C13>Inicio!$C$19)),AND(ISNUMBER(D13),OR(D13<Inicio!$C$18,D13>Inicio!$C$19))),"Fuera de rango",IF(COUNTIF($A$6:$A$305,A13)>1,"Código duplicado","OK"))))) | L13: Códigos ausentes en 2_Participantes | M13: =COUNTIF(J6:J305,"Código ausente en 2_Participantes")
A14: GU-TDH-011 | B14: {=IF(A14="","",IFERROR(IF(INDEX('2_Participantes'!$B$6:$B$305,MATCH(A14,'2_Participantes'!$A$6:$A$305,0))="","",INDEX('2_Participantes'!$B$6:$B$305,MATCH(A14,'2_Participantes'!$A$6:$A$305,0))),"No registrado"))} | C14: 30 | D14: 67.5 | E14: =IF(AND(ISNUMBER(C14),ISNUMBER(D14)),D14-C14,"") | F14: {=IF(A14="","",IFERROR(IF(INDEX('2_Participantes'!$E$6:$E$305,MATCH(A14,'2_Participantes'!$A$6:$A$305,0))="","",INDEX('2_Participantes'!$E$6:$E$305,MATCH(A14,'2_Participantes'!$A$6:$A$305,0))),""))} | G14: {=IF(A14="","",IFERROR(IF(INDEX('2_Participantes'!$F$6:$F$305,MATCH(A14,'2_Participantes'!$A$6:$A$305,0))="","",INDEX('2_Participantes'!$F$6:$F$305,MATCH(A14,'2_Participantes'!$A$6:$A$305,0))),"No registrado"))} | H14: {=IF(A14="","",IFERROR(IF(INDEX('2_Participantes'!$L$6:$L$305,MATCH(A14,'2_Participantes'!$A$6:$A$305,0))="","",INDEX('2_Participantes'!$L$6:$L$305,MATCH(A14,'2_Participantes'!$A$6:$A$305,0))),""))} | I14: =IF(A14="","",IF(AND(ISNUMBER(C14),ISNUMBER(D14),G14<>"Excluido"),1,0)) | J14: =IF(A14="","",IF(G14="No registrado","Código ausente en 2_Participantes",IF(AND(ISNUMBER(D14),NOT(ISNUMBER(C14))),"Postest sin pretest (huérfano)",IF(OR(AND(ISNUMBER(C14),OR(C14<Inicio!$C$18,C14>Inicio!$C$19)),AND(ISNUMBER(D14),OR(D14<Inicio!$C$18,D14>Inicio!$C$19))),"Fuera de rango",IF(COUNTIF($A$6:$A$305,A14)>1,"Código duplicado","OK"))))) | L14: Resultado | M14: =IF(SUM(M10:M13)=0,"Base consolidada sin inconsistencias","Corregir las filas marcadas en CONTROL DE CALIDAD")
A15: GU-TDH-012 | B15: {=IF(A15="","",IFERROR(IF(INDEX('2_Participantes'!$B$6:$B$305,MATCH(A15,'2_Participantes'!$A$6:$A$305,0))="","",INDEX('2_Participantes'!$B$6:$B$305,MATCH(A15,'2_Participantes'!$A$6:$A$305,0))),"No registrado"))} | C15: 65 | D15: 80 | E15: =IF(AND(ISNUMBER(C15),ISNUMBER(D15)),D15-C15,"") | F15: {=IF(A15="","",IFERROR(IF(INDEX('2_Participantes'!$E$6:$E$305,MATCH(A15,'2_Participantes'!$A$6:$A$305,0))="","",INDEX('2_Participantes'!$E$6:$E$305,MATCH(A15,'2_Participantes'!$A$6:$A$305,0))),""))} | G15: {=IF(A15="","",IFERROR(IF(INDEX('2_Participantes'!$F$6:$F$305,MATCH(A15,'2_Participantes'!$A$6:$A$305,0))="","",INDEX('2_Participantes'!$F$6:$F$305,MATCH(A15,'2_Participantes'!$A$6:$A$305,0))),"No registrado"))} | H15: {=IF(A15="","",IFERROR(IF(INDEX('2_Participantes'!$L$6:$L$305,MATCH(A15,'2_Participantes'!$A$6:$A$305,0))="","",INDEX('2_Participantes'!$L$6:$L$305,MATCH(A15,'2_Participantes'!$A$6:$A$305,0))),""))} | I15: =IF(A15="","",IF(AND(ISNUMBER(C15),ISNUMBER(D15),G15<>"Excluido"),1,0)) | J15: =IF(A15="","",IF(G15="No registrado","Código ausente en 2_Participantes",IF(AND(ISNUMBER(D15),NOT(ISNUMBER(C15))),"Postest sin pretest (huérfano)",IF(OR(AND(ISNUMBER(C15),OR(C15<Inicio!$C$18,C15>Inicio!$C$19)),AND(ISNUMBER(D15),OR(D15<Inicio!$C$18,D15>Inicio!$C$19))),"Fuera de rango",IF(COUNTIF($A$6:$A$305,A15)>1,"Código duplicado","OK")))))
A16: GU-TDH-014 | B16: {=IF(A16="","",IFERROR(IF(INDEX('2_Participantes'!$B$6:$B$305,MATCH(A16,'2_Participantes'!$A$6:$A$305,0))="","",INDEX('2_Participantes'!$B$6:$B$305,MATCH(A16,'2_Participantes'!$A$6:$A$305,0))),"No registrado"))} | C16: 55 | D16: 65 | E16: =IF(AND(ISNUMBER(C16),ISNUMBER(D16)),D16-C16,"") | F16: {=IF(A16="","",IFERROR(IF(INDEX('2_Participantes'!$E$6:$E$305,MATCH(A16,'2_Participantes'!$A$6:$A$305,0))="","",INDEX('2_Participantes'!$E$6:$E$305,MATCH(A16,'2_Participantes'!$A$6:$A$305,0))),""))} | G16: {=IF(A16="","",IFERROR(IF(INDEX('2_Participantes'!$F$6:$F$305,MATCH(A16,'2_Participantes'!$A$6:$A$305,0))="","",INDEX('2_Participantes'!$F$6:$F$305,MATCH(A16,'2_Participantes'!$A$6:$A$305,0))),"No registrado"))} | H16: {=IF(A16="","",IFERROR(IF(INDEX('2_Participantes'!$L$6:$L$305,MATCH(A16,'2_Participantes'!$A$6:$A$305,0))="","",INDEX('2_Participantes'!$L$6:$L$305,MATCH(A16,'2_Participantes'!$A$6:$A$305,0))),""))} | I16: =IF(A16="","",IF(AND(ISNUMBER(C16),ISNUMBER(D16),G16<>"Excluido"),1,0)) | J16: =IF(A16="","",IF(G16="No registrado","Código ausente en 2_Participantes",IF(AND(ISNUMBER(D16),NOT(ISNUMBER(C16))),"Postest sin pretest (huérfano)",IF(OR(AND(ISNUMBER(C16),OR(C16<Inicio!$C$18,C16>Inicio!$C$19)),AND(ISNUMBER(D16),OR(D16<Inicio!$C$18,D16>Inicio!$C$19))),"Fuera de rango",IF(COUNTIF($A$6:$A$305,A16)>1,"Código duplicado","OK")))))
A17: GU-TDH-015 | B17: {=IF(A17="","",IFERROR(IF(INDEX('2_Participantes'!$B$6:$B$305,MATCH(A17,'2_Participantes'!$A$6:$A$305,0))="","",INDEX('2_Participantes'!$B$6:$B$305,MATCH(A17,'2_Participantes'!$A$6:$A$305,0))),"No registrado"))} | C17: 72.5 | E17: =IF(AND(ISNUMBER(C17),ISNUMBER(D17)),D17-C17,"") | F17: {=IF(A17="","",IFERROR(IF(INDEX('2_Participantes'!$E$6:$E$305,MATCH(A17,'2_Participantes'!$A$6:$A$305,0))="","",INDEX('2_Participantes'!$E$6:$E$305,MATCH(A17,'2_Participantes'!$A$6:$A$305,0))),""))} | G17: {=IF(A17="","",IFERROR(IF(INDEX('2_Participantes'!$F$6:$F$305,MATCH(A17,'2_Participantes'!$A$6:$A$305,0))="","",INDEX('2_Participantes'!$F$6:$F$305,MATCH(A17,'2_Participantes'!$A$6:$A$305,0))),"No registrado"))} | H17: {=IF(A17="","",IFERROR(IF(INDEX('2_Participantes'!$L$6:$L$305,MATCH(A17,'2_Participantes'!$A$6:$A$305,0))="","",INDEX('2_Participantes'!$L$6:$L$305,MATCH(A17,'2_Participantes'!$A$6:$A$305,0))),""))} | I17: =IF(A17="","",IF(AND(ISNUMBER(C17),ISNUMBER(D17),G17<>"Excluido"),1,0)) | J17: =IF(A17="","",IF(G17="No registrado","Código ausente en 2_Participantes",IF(AND(ISNUMBER(D17),NOT(ISNUMBER(C17))),"Postest sin pretest (huérfano)",IF(OR(AND(ISNUMBER(C17),OR(C17<Inicio!$C$18,C17>Inicio!$C$19)),AND(ISNUMBER(D17),OR(D17<Inicio!$C$18,D17>Inicio!$C$19))),"Fuera de rango",IF(COUNTIF($A$6:$A$305,A17)>1,"Código duplicado","OK"))))) | L17: Descriptivos de los pares analizados
A18: GU-TDH-016 | B18: {=IF(A18="","",IFERROR(IF(INDEX('2_Participantes'!$B$6:$B$305,MATCH(A18,'2_Participantes'!$A$6:$A$305,0))="","",INDEX('2_Participantes'!$B$6:$B$305,MATCH(A18,'2_Participantes'!$A$6:$A$305,0))),"No registrado"))} | C18: 42.5 | D18: 82.5 | E18: =IF(AND(ISNUMBER(C18),ISNUMBER(D18)),D18-C18,"") | F18: {=IF(A18="","",IFERROR(IF(INDEX('2_Participantes'!$E$6:$E$305,MATCH(A18,'2_Participantes'!$A$6:$A$305,0))="","",INDEX('2_Participantes'!$E$6:$E$305,MATCH(A18,'2_Participantes'!$A$6:$A$305,0))),""))} | G18: {=IF(A18="","",IFERROR(IF(INDEX('2_Participantes'!$F$6:$F$305,MATCH(A18,'2_Participantes'!$A$6:$A$305,0))="","",INDEX('2_Participantes'!$F$6:$F$305,MATCH(A18,'2_Participantes'!$A$6:$A$305,0))),"No registrado"))} | H18: {=IF(A18="","",IFERROR(IF(INDEX('2_Participantes'!$L$6:$L$305,MATCH(A18,'2_Participantes'!$A$6:$A$305,0))="","",INDEX('2_Participantes'!$L$6:$L$305,MATCH(A18,'2_Participantes'!$A$6:$A$305,0))),""))} | I18: =IF(A18="","",IF(AND(ISNUMBER(C18),ISNUMBER(D18),G18<>"Excluido"),1,0)) | J18: =IF(A18="","",IF(G18="No registrado","Código ausente en 2_Participantes",IF(AND(ISNUMBER(D18),NOT(ISNUMBER(C18))),"Postest sin pretest (huérfano)",IF(OR(AND(ISNUMBER(C18),OR(C18<Inicio!$C$18,C18>Inicio!$C$19)),AND(ISNUMBER(D18),OR(D18<Inicio!$C$18,D18>Inicio!$C$19))),"Fuera de rango",IF(COUNTIF($A$6:$A$305,A18)>1,"Código duplicado","OK"))))) | L18: Grupo | M18: n pares | N18: Media VD_PRE | O18: Media VD_POST | P18: Diferencia de medias | Q18: DE VD_PRE | R18: DE VD_POST
A19: GU-TDH-017 | B19: {=IF(A19="","",IFERROR(IF(INDEX('2_Participantes'!$B$6:$B$305,MATCH(A19,'2_Participantes'!$A$6:$A$305,0))="","",INDEX('2_Participantes'!$B$6:$B$305,MATCH(A19,'2_Participantes'!$A$6:$A$305,0))),"No registrado"))} | C19: 62.5 | D19: 75 | E19: =IF(AND(ISNUMBER(C19),ISNUMBER(D19)),D19-C19,"") | F19: {=IF(A19="","",IFERROR(IF(INDEX('2_Participantes'!$E$6:$E$305,MATCH(A19,'2_Participantes'!$A$6:$A$305,0))="","",INDEX('2_Participantes'!$E$6:$E$305,MATCH(A19,'2_Participantes'!$A$6:$A$305,0))),""))} | G19: {=IF(A19="","",IFERROR(IF(INDEX('2_Participantes'!$F$6:$F$305,MATCH(A19,'2_Participantes'!$A$6:$A$305,0))="","",INDEX('2_Participantes'!$F$6:$F$305,MATCH(A19,'2_Participantes'!$A$6:$A$305,0))),"No registrado"))} | H19: {=IF(A19="","",IFERROR(IF(INDEX('2_Participantes'!$L$6:$L$305,MATCH(A19,'2_Participantes'!$A$6:$A$305,0))="","",INDEX('2_Participantes'!$L$6:$L$305,MATCH(A19,'2_Participantes'!$A$6:$A$305,0))),""))} | I19: =IF(A19="","",IF(AND(ISNUMBER(C19),ISNUMBER(D19),G19<>"Excluido"),1,0)) | J19: =IF(A19="","",IF(G19="No registrado","Código ausente en 2_Participantes",IF(AND(ISNUMBER(D19),NOT(ISNUMBER(C19))),"Postest sin pretest (huérfano)",IF(OR(AND(ISNUMBER(C19),OR(C19<Inicio!$C$18,C19>Inicio!$C$19)),AND(ISNUMBER(D19),OR(D19<Inicio!$C$18,D19>Inicio!$C$19))),"Fuera de rango",IF(COUNTIF($A$6:$A$305,A19)>1,"Código duplicado","OK"))))) | L19: GE | M19: =COUNTIFS(B6:B305,"GE",I6:I305,1) | N19: =IFERROR(AVERAGEIFS(C6:C305,B6:B305,"GE",I6:I305,1),"") | O19: =IFERROR(AVERAGEIFS(D6:D305,B6:B305,"GE",I6:I305,1),"") | P19: =IF(OR(N19="",O19=""),"",O19-N19) | Q19: =IF(M19<2,"",SQRT((SUMPRODUCT((B6:B305="GE")*(I6:I305=1)*(C6:C305)^2)-M19*N19^2)/(M19-1))) | R19: =IF(M19<2,"",SQRT((SUMPRODUCT((B6:B305="GE")*(I6:I305=1)*(D6:D305)^2)-M19*O19^2)/(M19-1)))
A20: GU-TDH-019 | B20: {=IF(A20="","",IFERROR(IF(INDEX('2_Participantes'!$B$6:$B$305,MATCH(A20,'2_Participantes'!$A$6:$A$305,0))="","",INDEX('2_Participantes'!$B$6:$B$305,MATCH(A20,'2_Participantes'!$A$6:$A$305,0))),"No registrado"))} | C20: 67.5 | D20: 85 | E20: =IF(AND(ISNUMBER(C20),ISNUMBER(D20)),D20-C20,"") | F20: {=IF(A20="","",IFERROR(IF(INDEX('2_Participantes'!$E$6:$E$305,MATCH(A20,'2_Participantes'!$A$6:$A$305,0))="","",INDEX('2_Participantes'!$E$6:$E$305,MATCH(A20,'2_Participantes'!$A$6:$A$305,0))),""))} | G20: {=IF(A20="","",IFERROR(IF(INDEX('2_Participantes'!$F$6:$F$305,MATCH(A20,'2_Participantes'!$A$6:$A$305,0))="","",INDEX('2_Participantes'!$F$6:$F$305,MATCH(A20,'2_Participantes'!$A$6:$A$305,0))),"No registrado"))} | H20: {=IF(A20="","",IFERROR(IF(INDEX('2_Participantes'!$L$6:$L$305,MATCH(A20,'2_Participantes'!$A$6:$A$305,0))="","",INDEX('2_Participantes'!$L$6:$L$305,MATCH(A20,'2_Participantes'!$A$6:$A$305,0))),""))} | I20: =IF(A20="","",IF(AND(ISNUMBER(C20),ISNUMBER(D20),G20<>"Excluido"),1,0)) | J20: =IF(A20="","",IF(G20="No registrado","Código ausente en 2_Participantes",IF(AND(ISNUMBER(D20),NOT(ISNUMBER(C20))),"Postest sin pretest (huérfano)",IF(OR(AND(ISNUMBER(C20),OR(C20<Inicio!$C$18,C20>Inicio!$C$19)),AND(ISNUMBER(D20),OR(D20<Inicio!$C$18,D20>Inicio!$C$19))),"Fuera de rango",IF(COUNTIF($A$6:$A$305,A20)>1,"Código duplicado","OK"))))) | L20: GC | M20: =COUNTIFS(B6:B305,"GC",I6:I305,1) | N20: =IFERROR(AVERAGEIFS(C6:C305,B6:B305,"GC",I6:I305,1),"") | O20: =IFERROR(AVERAGEIFS(D6:D305,B6:B305,"GC",I6:I305,1),"") | P20: =IF(OR(N20="",O20=""),"",O20-N20) | Q20: =IF(M20<2,"",SQRT((SUMPRODUCT((B6:B305="GC")*(I6:I305=1)*(C6:C305)^2)-M20*N20^2)/(M20-1))) | R20: =IF(M20<2,"",SQRT((SUMPRODUCT((B6:B305="GC")*(I6:I305=1)*(D6:D305)^2)-M20*O20^2)/(M20-1)))
A21: GU-TDH-020 | B21: {=IF(A21="","",IFERROR(IF(INDEX('2_Participantes'!$B$6:$B$305,MATCH(A21,'2_Participantes'!$A$6:$A$305,0))="","",INDEX('2_Participantes'!$B$6:$B$305,MATCH(A21,'2_Participantes'!$A$6:$A$305,0))),"No registrado"))} | C21: 57.5 | D21: 67.5 | E21: =IF(AND(ISNUMBER(C21),ISNUMBER(D21)),D21-C21,"") | F21: {=IF(A21="","",IFERROR(IF(INDEX('2_Participantes'!$E$6:$E$305,MATCH(A21,'2_Participantes'!$A$6:$A$305,0))="","",INDEX('2_Participantes'!$E$6:$E$305,MATCH(A21,'2_Participantes'!$A$6:$A$305,0))),""))} | G21: {=IF(A21="","",IFERROR(IF(INDEX('2_Participantes'!$F$6:$F$305,MATCH(A21,'2_Participantes'!$A$6:$A$305,0))="","",INDEX('2_Participantes'!$F$6:$F$305,MATCH(A21,'2_Participantes'!$A$6:$A$305,0))),"No registrado"))} | H21: {=IF(A21="","",IFERROR(IF(INDEX('2_Participantes'!$L$6:$L$305,MATCH(A21,'2_Participantes'!$A$6:$A$305,0))="","",INDEX('2_Participantes'!$L$6:$L$305,MATCH(A21,'2_Participantes'!$A$6:$A$305,0))),""))} | I21: =IF(A21="","",IF(AND(ISNUMBER(C21),ISNUMBER(D21),G21<>"Excluido"),1,0)) | J21: =IF(A21="","",IF(G21="No registrado","Código ausente en 2_Participantes",IF(AND(ISNUMBER(D21),NOT(ISNUMBER(C21))),"Postest sin pretest (huérfano)",IF(OR(AND(ISNUMBER(C21),OR(C21<Inicio!$C$18,C21>Inicio!$C$19)),AND(ISNUMBER(D21),OR(D21<Inicio!$C$18,D21>Inicio!$C$19))),"Fuera de rango",IF(COUNTIF($A$6:$A$305,A21)>1,"Código duplicado","OK"))))) | L21: G | M21: =COUNTIFS(B6:B305,"G",I6:I305,1) | N21: =IFERROR(AVERAGEIFS(C6:C305,B6:B305,"G",I6:I305,1),"") | O21: =IFERROR(AVERAGEIFS(D6:D305,B6:B305,"G",I6:I305,1),"") | P21: =IF(OR(N21="",O21=""),"",O21-N21) | Q21: =IF(M21<2,"",SQRT((SUMPRODUCT((B6:B305="G")*(I6:I305=1)*(C6:C305)^2)-M21*N21^2)/(M21-1))) | R21: =IF(M21<2,"",SQRT((SUMPRODUCT((B6:B305="G")*(I6:I305=1)*(D6:D305)^2)-M21*O21^2)/(M21-1)))
A22: GU-TDH-021 | B22: {=IF(A22="","",IFERROR(IF(INDEX('2_Participantes'!$B$6:$B$305,MATCH(A22,'2_Participantes'!$A$6:$A$305,0))="","",INDEX('2_Participantes'!$B$6:$B$305,MATCH(A22,'2_Participantes'!$A$6:$A$305,0))),"No registrado"))} | C22: 55 | D22: 80 | E22: =IF(AND(ISNUMBER(C22),ISNUMBER(D22)),D22-C22,"") | F22: {=IF(A22="","",IFERROR(IF(INDEX('2_Participantes'!$E$6:$E$305,MATCH(A22,'2_Participantes'!$A$6:$A$305,0))="","",INDEX('2_Participantes'!$E$6:$E$305,MATCH(A22,'2_Participantes'!$A$6:$A$305,0))),""))} | G22: {=IF(A22="","",IFERROR(IF(INDEX('2_Participantes'!$F$6:$F$305,MATCH(A22,'2_Participantes'!$A$6:$A$305,0))="","",INDEX('2_Participantes'!$F$6:$F$305,MATCH(A22,'2_Participantes'!$A$6:$A$305,0))),"No registrado"))} | H22: {=IF(A22="","",IFERROR(IF(INDEX('2_Participantes'!$L$6:$L$305,MATCH(A22,'2_Participantes'!$A$6:$A$305,0))="","",INDEX('2_Participantes'!$L$6:$L$305,MATCH(A22,'2_Participantes'!$A$6:$A$305,0))),""))} | I22: =IF(A22="","",IF(AND(ISNUMBER(C22),ISNUMBER(D22),G22<>"Excluido"),1,0)) | J22: =IF(A22="","",IF(G22="No registrado","Código ausente en 2_Participantes",IF(AND(ISNUMBER(D22),NOT(ISNUMBER(C22))),"Postest sin pretest (huérfano)",IF(OR(AND(ISNUMBER(C22),OR(C22<Inicio!$C$18,C22>Inicio!$C$19)),AND(ISNUMBER(D22),OR(D22<Inicio!$C$18,D22>Inicio!$C$19))),"Fuera de rango",IF(COUNTIF($A$6:$A$305,A22)>1,"Código duplicado","OK"))))) | L22: DE = desviación estándar muestral de los pares analizados. La comparación de la línea base de quienes se retiraron frente a quienes completaron (ESTADO = Activo) es el análisis del sesgo por atrición que pide la rúbrica.
A23: GU-TDH-022 | B23: {=IF(A23="","",IFERROR(IF(INDEX('2_Participantes'!$B$6:$B$305,MATCH(A23,'2_Participantes'!$A$6:$A$305,0))="","",INDEX('2_Participantes'!$B$6:$B$305,MATCH(A23,'2_Participantes'!$A$6:$A$305,0))),"No registrado"))} | C23: 52.5 | D23: 87.5 | E23: =IF(AND(ISNUMBER(C23),ISNUMBER(D23)),D23-C23,"") | F23: {=IF(A23="","",IFERROR(IF(INDEX('2_Participantes'!$E$6:$E$305,MATCH(A23,'2_Participantes'!$A$6:$A$305,0))="","",INDEX('2_Participantes'!$E$6:$E$305,MATCH(A23,'2_Participantes'!$A$6:$A$305,0))),""))} | G23: {=IF(A23="","",IFERROR(IF(INDEX('2_Participantes'!$F$6:$F$305,MATCH(A23,'2_Participantes'!$A$6:$A$305,0))="","",INDEX('2_Participantes'!$F$6:$F$305,MATCH(A23,'2_Participantes'!$A$6:$A$305,0))),"No registrado"))} | H23: {=IF(A23="","",IFERROR(IF(INDEX('2_Participantes'!$L$6:$L$305,MATCH(A23,'2_Participantes'!$A$6:$A$305,0))="","",INDEX('2_Participantes'!$L$6:$L$305,MATCH(A23,'2_Participantes'!$A$6:$A$305,0))),""))} | I23: =IF(A23="","",IF(AND(ISNUMBER(C23),ISNUMBER(D23),G23<>"Excluido"),1,0)) | J23: =IF(A23="","",IF(G23="No registrado","Código ausente en 2_Participantes",IF(AND(ISNUMBER(D23),NOT(ISNUMBER(C23))),"Postest sin pretest (huérfano)",IF(OR(AND(ISNUMBER(C23),OR(C23<Inicio!$C$18,C23>Inicio!$C$19)),AND(ISNUMBER(D23),OR(D23<Inicio!$C$18,D23>Inicio!$C$19))),"Fuera de rango",IF(COUNTIF($A$6:$A$305,A23)>1,"Código duplicado","OK")))))
