Workbook

Sheet 00_Guia
A1: UNIVERSIDAD DE HUÁNUCO · Programa Académico de Ingeniería de Sistemas e Informática · Seminario de Tesis III
A2: GUÍA DEL ESTUDIANTE · SESIÓN 4: DESPLIEGUE E INICIO DE LA SOLUCIÓN TECNOLÓGICA
A3: Unidad I · Semana 4 · Investigación aplicada, cuantitativa, nivel aplicativo, diseño preexperimental o cuasiexperimental
A6: 1. PROPÓSITO
A7: Esta guía te acompaña para iniciar formalmente la intervención (T₀): instalar o desplegar tu solución, configurar usuarios, roles y datos, verificar su operatividad, capacitar a los participantes, realizar pruebas iniciales, comunicar las condiciones de uso y registrar el inicio. Todo debe quedar evidenciado para la Tarea Académica 1.
A8: 2. INDICADOR DE LOGRO
A9: Inicia la intervención con una solución operativa, configurada y accesible, presentando evidencias de instalación, capacitación y cumplimiento del protocolo.
A10: 3. RUTA DE TRABAJO Y FORMATOS DE ESTE LIBRO
A11: N.° | B11: Formato (hoja) | C11: Qué debes hacer | D11: Evidencia / instrumento
A12: 1 | B12: 01_Lista_cotejo | C12: Autoevalúa las 10 condiciones del despliegue antes de T₀. Todas deben estar en «Sí». | D12: Lista de cotejo de despliegue
A13: 2 | B13: 02_Acta_instalacion | C13: Registra entorno, versión, componentes instalados y pruebas; imprime y firma con TI y el área usuaria. | D13: Acta de instalación
A14: 3 | B14: 03_Matriz_roles | C14: Crea una cuenta individual por participante usando su código (P01…), con el rol de mínimo privilegio. | D14: Matriz de usuarios y roles
A15: 4 | B15: 04_Verificacion_funcional | C15: Prueba cada requisito funcional; marca Conforme/No conforme. Los críticos deben estar al 100 %. | D15: Ficha de verificación funcional
A16: 5 | B16: 05_Pruebas_iniciales | C16: Documenta los casos de prueba (humo, funcionales, aceptación, carga básica) con su evidencia. | D16: Log de pruebas
A17: 6 | B17: 06_Registro_capacitacion | C17: Registra asistencia, duración y resultado del ejercicio práctico de cada participante del GE. | D17: Registro de capacitación
A18: 7 | B18: 07_Registro_incidencias | C18: Registra toda incidencia desde la instalación; clasifícala por prioridad y cierra con acción correctiva. | D18: Registro de incidencias
A19: 8 | B19: 08_Protocolo_condiciones | C19: Define la dosis de X (duración, frecuencia, intensidad) y marca las condiciones de uso comunicadas. | D19: Protocolo de intervención
A20: 9 | B20: 09_Acta_inicio_T0 | C20: Formaliza fecha y hora de inicio, participantes, condiciones y firmas. | D20: Acta de inicio
A21: 10 | B21: 10_Rubrica_informe | C21: Autoevalúa tu informe inicial antes de entregarlo (20 puntos). | D21: Rúbrica del informe inicial
A22: 11 | B22: 11_Resumen | C22: Revisa el tablero: indica si estás «LISTO PARA T₀». | D22: Semáforo de cumplimiento
A24: 4. INSTRUCCIONES DE LLENADO
A25: • Llena solo las celdas de color AMARILLO. Las celdas blancas contienen fórmulas o textos fijos: no las modifiques.
A26: • La fila en azul cursiva de cada tabla es un EJEMPLO: reemplázala con tus datos o bórrala.
A27: • Usa SIEMPRE el código del participante (P01, P02…), nunca su nombre, en tablas, capturas e informes (Ley N.° 29733).
A28: • La tabla de correspondencia código–identidad se guarda aparte, cifrada y solo con acceso del investigador.
A29: • Las actas (hojas 02 y 09) se imprimen, se firman y se escanean en PDF para el portafolio.
A30: • Nombra tus evidencias así: TA1_S4_[Apellido]_[N.°formato]_[descripcion].pdf (ej.: TA1_S4_Quispe_02_acta_instalacion.pdf).
A32: 5. CRONOGRAMA SUGERIDO HACIA T₀ (ajústalo a tu contexto)
B33: Día −7 | C33: Preparar el entorno y obtener autorizaciones (formato 01)
B34: Día −5 | C34: Instalar, configurar usuarios, roles y datos (formatos 02 y 03)
B35: Día −3 | C35: Verificación funcional y pruebas (formatos 04 y 05)
B36: Día −2 | C36: Capacitación de participantes (formato 06)
B37: Día −1 | C37: Prueba con usuarios y comunicación de condiciones (formato 08)
B38: Día 0 | C38: Acta de inicio T₀ (formato 09)
A40: 6. ESTRUCTURA DEL INFORME INICIAL (entregable para la Tarea Académica 1)
A41: 1. Datos generales y versión de la solución 2. Descripción de la solución 3. Entorno e instalación 4. Usuarios, roles y datos 5. Seguridad y protección de datos
A42: 6. Verificación funcional 7. Capacitación 8. Protocolo y condiciones de uso 9. Registro de inicio (T₀) 10. Incidencias iniciales y anexos (formatos de este libro)
A44: 7. ERRORES QUE EL JURADO OBSERVA
A45: Desplegar sin pruebas · cambiar funciones a mitad del experimento · cuentas compartidas · capacitación desigual · T₀ sin acta · evidencias con datos personales expuestos.

Sheet 01_Lista_cotejo
A1: UNIVERSIDAD DE HUÁNUCO · Programa Académico de Ingeniería de Sistemas e Informática · Seminario de Tesis III
A2: FORMATO 01 · LISTA DE COTEJO DE DESPLIEGUE
A3: Marca Sí o No en cada ítem y anota la evidencia que lo respalda
A6: Tesista: | B6: Trujillo Avila, Marcel Alexander Javier; Godoy Condezo, Alejandro Jeanpier
A7: Título de la tesis: | B7: Influencia de una aplicación multiplataforma de búsqueda semántica conversacional en la experiencia de lectores de Tu Diario Huánuco, 2026
A8: Institución / contexto: | B8: Tu Diario Huánuco (medio de comunicación digital), Huánuco
A9: Diseño: | B9: Preexperimental: G O1 X O2 (grupo único, pretest y postest)
A11: N.° | B11: Ítem de verificación | C11: ¿Cumple? (Sí/No) | D11: Evidencia que lo respalda | E11: Observaciones
A12: 1 | B12: El entorno fue verificado en el lugar real de uso | C12: Sí | D12: HTTPS en chat.tudiariohuanuco.pe el 18/10/2026. | E12: VPS KVM 1 + Dokploy
A13: 2 | B13: La versión está etiquetada (p. ej. v1.0.0) y congelada | C13: Sí | D13: Tag v1.0.0-frozen-2026-10-18. Sin deploys hasta el postest. | E13: Congelado
A14: 3 | B14: Cada participante tiene una cuenta individual con su código | C14: Sí | D14: 108 cuentas, los mismos códigos GU-TDH del pretest. | E14: Grupo único. En esta plantilla el grupo se registra como GE; no hay GC.
A15: 4 | B15: Los roles aplican el principio de mínimo privilegio | C15: Sí | D15: Rol lector: chat, búsqueda y módulo experimento. | E15: Mínimo privilegio
A16: 5 | B16: Los datos de prueba fueron eliminados antes de T₀ | C16: Sí | D16: Datos de prueba eliminados el 18/10/2026. | E16: purge_demo.sql
A17: 6 | B17: El 100 % de requisitos críticos está «Conforme» | C17: Sí | D17: Requisitos críticos en Conforme (hoja 04).
A18: 7 | B18: El respaldo y la restauración fueron probados | C18: Sí | D18: Backup Supabase y copia cifrada. Restore de prueba OK.
A19: 8 | B19: El 100 % del grupo experimental fue capacitado | C19: Sí | D19: Guía rápida y registro de capacitación.
A20: 9 | B20: Las condiciones de uso fueron comunicadas por escrito | C20: Sí | D20: Condiciones por WhatsApp y banner (hoja 08). | E20: 8/8
A21: 10 | B21: El acta de inicio (T₀) está firmada | C21: Sí | D21: Acta T0 del 19/10/2026 (hoja 09).
B23: Ítems cumplidos | C23: =COUNTIF(C12:C21,"Sí")
B24: Porcentaje de cumplimiento | C24: =C23/10
B25: Dictamen | C25: =IF(C23=10,"LISTO PARA T₀","NO INICIAR: subsanar")
A27: Leyenda: celdas amarillas = llenar. Fila azul en cursiva = ejemplo. El dictamen se calcula solo: se requiere 10/10 para iniciar la intervención.

Sheet 02_Acta_instalacion
A1: UNIVERSIDAD DE HUÁNUCO · Programa Académico de Ingeniería de Sistemas e Informática · Seminario de Tesis III
A2: FORMATO 02 · ACTA DE INSTALACIÓN DE LA SOLUCIÓN TECNOLÓGICA
A3: Documento que certifica la instalación conforme. Imprimir, firmar y escanear.
A6: Nombre de la solución: | B6: Aplicación multiplataforma de búsqueda semántica conversacional (PWA + RAG)
A7: Versión desplegada (etiqueta): | B7: v1.0.0-frozen-2026-10-18
A8: Modalidad de despliegue: | B8: Nube / VPS (Dokploy) + PWA en el dispositivo del participante
A9: URL / servidor / dispositivo: | B9: https://chat.tudiariohuanuco.pe | https://api.tudiariohuanuco.pe | Hostinger VPS KVM 1 + Dokploy (IP real pendiente)
A10: Lugar de instalación: | B10: Servidor en la nube; uso desde el dispositivo del participante
A11: Fecha y hora de instalación: | B11: 46313.771
A12: Responsable técnico (tesista): | B12: Trujillo Avila, Marcel Alexander Javier; Godoy Condezo, Alejandro Jeanpier
A13: Responsable de TI de la institución: | B13: [PENDIENTE] Responsable de TI del diario
A14: Responsable del área usuaria: | B14: [PENDIENTE] Gerencia de Tu Diario Huánuco
A16: COMPONENTES INSTALADOS
A17: Componente | B17: Versión | C17: Ubicación | D17: Estado | E17: Verificado por | F17: Observación
A18: Interfaz web y PWA (Next.js) | B18: v1.0.0-frozen-2026-10-18 | C18: chat.tudiariohuanuco.pe | D18: Operativo | E18: M. Trujillo | F18: Install prompt verificado
A19: API principal (FastAPI) | B19: v1.0.0-frozen-2026-10-18 | C19: api.tudiariohuanuco.pe | D19: Operativo | E19: M. Trujillo | F19: Gemini + WordPress REST
A20: Telemetría (FastAPI) | B20: v1.0.0-frozen-2026-10-18 | C20: VPS | D20: Operativo | E20: A. Godoy | F20: Tiempos y clics
A21: Módulo del experimento | B21: v1.0.0-frozen-2026-10-18 | C21: VPS | D21: Operativo | E21: A. Godoy | F21: Tareas O1/O2
A22: PostgreSQL + pgvector | B22: Supabase free | C22: Supabase | D22: Operativo | E22: M. Trujillo | F22: Embeddings
A23: Redis | B23: 7.x | C23: VPS | D23: Operativo | E23: M. Trujillo | F23: Caché
A25: PRUEBAS REALIZADAS EN LA INSTALACIÓN
A26: Prueba de humo (el sistema inicia y responde) | D26: Sí | E26: Healthcheck 200
A27: Acceso por HTTPS / red interna | D27: Sí | E27: HTTPS Let's Encrypt
A28: Inicio de sesión por rol | D28: Sí | E28: Login con código
A29: Respaldo y restauración | D29: Sí | E29: Restore de prueba
A31: CONFORMIDAD: | B31: Las partes declaran que la solución fue instalada y se encuentra operativa para iniciar la intervención.
A35: ______________________ | C35: ______________________ | E35: ______________________
A36: Tesista | C36: Responsable de TI | E36: Responsable del área usuaria
A37: Nombre / DNI / Firma | C37: Nombre / DNI / Firma | E37: Nombre / DNI / Firma

Sheet 03_Matriz_roles
A1: UNIVERSIDAD DE HUÁNUCO · Programa Académico de Ingeniería de Sistemas e Informática · Seminario de Tesis III
A2: FORMATO 03 · MATRIZ DE USUARIOS Y ROLES
A3: Una cuenta individual por participante, identificada solo por código
A6: Tesista: | B6: Trujillo Avila, Marcel Alexander Javier; Godoy Condezo, Alejandro Jeanpier
A7: Título de la tesis: | B7: Influencia de una aplicación multiplataforma de búsqueda semántica conversacional en la experiencia de lectores de Tu Diario Huánuco, 2026
A8: Institución / contexto: | B8: Tu Diario Huánuco (medio de comunicación digital), Huánuco
A9: Diseño: | B9: Preexperimental: G O1 X O2 (grupo único, pretest y postest)
A11: Código participante | B11: Grupo | C11: Usuario del sistema | D11: Rol | E11: Permisos principales | F11: Fecha de creación | G11: Cambio de contraseña en 1.er ingreso | H11: Estado
A12: GU-TDH-002 | B12: GE | C12: gu_tdh_002 | D12: Lector participante | E12: Chat RAG y módulo experimento; sin admin | F12: 46313 | G12: Sí | H12: Activa
A13: GU-TDH-003 | B13: GE | C13: gu_tdh_003 | D13: Lector participante | E13: Chat RAG y módulo experimento; sin admin | F13: 46313 | G13: Sí | H13: Activa
A14: GU-TDH-004 | B14: GE | C14: gu_tdh_004 | D14: Lector participante | E14: Chat RAG y módulo experimento; sin admin | F14: 46313 | G14: Sí | H14: Activa
A15: GU-TDH-006 | B15: GE | C15: gu_tdh_006 | D15: Lector participante | E15: Chat RAG y módulo experimento; sin admin | F15: 46313 | G15: Sí | H15: Activa
A16: GU-TDH-007 | B16: GE | C16: gu_tdh_007 | D16: Lector participante | E16: Chat RAG y módulo experimento; sin admin | F16: 46313 | G16: Sí | H16: Activa
A17: GU-TDH-008 | B17: GE | C17: gu_tdh_008 | D17: Lector participante | E17: Chat RAG y módulo experimento; sin admin | F17: 46313 | G17: Sí | H17: Activa
A18: GU-TDH-009 | B18: GE | C18: gu_tdh_009 | D18: Lector participante | E18: Chat RAG y módulo experimento; sin admin | F18: 46313 | G18: Sí | H18: Activa
A19: GU-TDH-010 | B19: GE | C19: gu_tdh_010 | D19: Lector participante | E19: Chat RAG y módulo experimento; sin admin | F19: 46313 | G19: Sí | H19: Activa
A20: GU-TDH-011 | B20: GE | C20: gu_tdh_011 | D20: Lector participante | E20: Chat RAG y módulo experimento; sin admin | F20: 46313 | G20: Sí | H20: Activa
A21: GU-TDH-012 | B21: GE | C21: gu_tdh_012 | D21: Lector participante | E21: Chat RAG y módulo experimento; sin admin | F21: 46313 | G21: Sí | H21: Activa
A22: GU-TDH-014 | B22: GE | C22: gu_tdh_014 | D22: Lector participante | E22: Chat RAG y módulo experimento; sin admin | F22: 46313 | G22: Sí | H22: Activa
A23: GU-TDH-015 | B23: GE | C23: gu_tdh_015 | D23: Lector participante | E23: Chat RAG y módulo experimento; sin admin | F23: 46313 | G23: Sí | H23: Activa
... A119: GU-TDH-125 | B119: GE | C119: gu_tdh_125 | D119: Lector participante | E119: Chat RAG y módulo experimento; sin admin | F119: 46313 | G119: Sí | H119: Activa
A121: Cuentas activas del GE | C121: =COUNTIFS(B12:B119,"GE",H12:H119,"Activa")
A122: Principio de mínimo privilegio: cada rol accede solo a lo necesario. Nunca registres nombres reales en esta hoja. El GC no recibe cuenta en la solución (diseño cuasiexperimental).

Sheet 04_Verificacion_funcional
A1: UNIVERSIDAD DE HUÁNUCO · Programa Académico de Ingeniería de Sistemas e Informática · Seminario de Tesis III
A2: FORMATO 04 · FICHA DE VERIFICACIÓN FUNCIONAL
A3: Criterio de inicio: 100 % de requisitos críticos en estado «Conforme»
A6: Tesista: | B6: Trujillo Avila, Marcel Alexander Javier; Godoy Condezo, Alejandro Jeanpier
A7: Título de la tesis: | B7: Influencia de una aplicación multiplataforma de búsqueda semántica conversacional en la experiencia de lectores de Tu Diario Huánuco, 2026
A8: Institución / contexto: | B8: Tu Diario Huánuco (medio de comunicación digital), Huánuco
A9: Diseño: | B9: Preexperimental: G O1 X O2 (grupo único, pretest y postest)
A11: Código RF | B11: Funcionalidad | C11: ¿Crítico? | D11: Resultado esperado | E11: Resultado obtenido | F11: Estado | G11: Evidencia (captura) | H11: Fecha
A12: RF-01 | B12: PWA por HTTPS | C12: Sí | D12: Operativo | E12: Operativo | F12: Conforme | G12: cap_RF-01.png | H12: 46313
A13: RF-02 | B13: Login con código | C13: Sí | D13: Operativo | E13: Operativo | F13: Conforme | G13: cap_RF-02.png | H13: 46313
A14: RF-03 | B14: Consulta RAG con citas | C14: Sí | D14: Operativo | E14: Operativo | F14: Conforme | G14: cap_RF-03.png | H14: 46313
A15: RF-04 | B15: Recuperación semántica | C15: Sí | D15: Operativo | E15: Operativo | F15: Conforme | G15: cap_RF-04.png | H15: 46313
A16: RF-05 | B16: Enlaces al artículo fuente | C16: Sí | D16: Operativo | E16: Operativo | F16: Conforme | G16: cap_RF-05.png | H16: 46313
A17: RF-06 | B17: Telemetría de tiempo y clics | C17: Sí | D17: Operativo | E17: Operativo | F17: Conforme | G17: cap_RF-06.png | H17: 46313
A18: RF-07 | B18: Módulo de experimento | C18: Sí | D18: Operativo | E18: Operativo | F18: Conforme | G18: cap_RF-07.png | H18: 46313
A19: RF-08 | B19: Ingesta WordPress REST | C19: No | D19: Operativo | E19: Operativo | F19: Conforme | G19: cap_RF-08.png | H19: 46313
A20: RF-09 | B20: Healthcheck | C20: Sí | D20: Operativo | E20: Operativo | F20: Conforme | G20: cap_RF-09.png | H20: 46313
A21: RF-10 | B21: Caché Redis | C21: No | D21: Operativo | E21: Operativo | F21: Conforme | G21: cap_RF-10.png | H21: 46313
A22: RF-11 | B22: Exportación de logs | C22: Sí | D22: Operativo | E22: Operativo | F22: Conforme | G22: cap_RF-11.png | H22: 46313
A23: RF-12 | B23: Versión congelada | C23: Sí | D23: Operativo | E23: Operativo | F23: Conforme | G23: cap_RF-12.png | H23: 46313
A33: Requisitos críticos registrados | C33: =COUNTIF(C12:C31,"Sí")
A34: Críticos conformes | C34: =COUNTIFS(C12:C31,"Sí",F12:F31,"Conforme")
A35: % críticos conformes | C35: =IF(C33=0,0,C34/C33)
A36: Dictamen | C36: =IF(AND(C33>0,C35=1),"LISTO PARA T₀","NO INICIAR: corregir")
A38: Un requisito crítico «No conforme» posterga T₀. Registra la corrección en el formato 07 y vuelve a verificar.

Sheet 05_Pruebas_iniciales
A1: UNIVERSIDAD DE HUÁNUCO · Programa Académico de Ingeniería de Sistemas e Informática · Seminario de Tesis III
A2: FORMATO 05 · REGISTRO DE PRUEBAS INICIALES
A3: Humo · funcionales · aceptación (UAT) · carga básica
A6: Tesista: | B6: Trujillo Avila, Marcel Alexander Javier; Godoy Condezo, Alejandro Jeanpier
A7: Título de la tesis: | B7: Influencia de una aplicación multiplataforma de búsqueda semántica conversacional en la experiencia de lectores de Tu Diario Huánuco, 2026
A8: Institución / contexto: | B8: Tu Diario Huánuco (medio de comunicación digital), Huánuco
A9: Diseño: | B9: Preexperimental: G O1 X O2 (grupo único, pretest y postest)
A11: ID caso | B11: Tipo de prueba | C11: RF asociado | D11: Pasos | E11: Resultado esperado | F11: Resultado obtenido | G11: Resultado | H11: Responsable | I11: Fecha
A12: TC-01 | B12: Humo | C12: RF-01 | D12: TC-01 Humo | E12: Según protocolo | F12: Según protocolo | G12: Aprobado | H12: M. Trujillo | I12: 46313
A13: TC-02 | B13: Login | C13: RF-02 | D13: TC-02 Login | E13: Según protocolo | F13: Según protocolo | G13: Aprobado | H13: M. Trujillo | I13: 46313
A14: TC-03 | B14: RAG | C14: RF-03 | D14: TC-03 RAG | E14: Según protocolo | F14: Según protocolo | G14: Aprobado | H14: M. Trujillo | I14: 46313
A15: TC-04 | B15: Semántica | C15: RF-04 | D15: TC-04 Semántica | E15: Según protocolo | F15: Según protocolo | G15: Aprobado | H15: M. Trujillo | I15: 46313
A16: TC-05 | B16: Telemetría | C16: RF-05 | D16: TC-05 Telemetría | E16: Según protocolo | F16: Según protocolo | G16: Aprobado | H16: M. Trujillo | I16: 46313
A17: TC-06 | B17: UAT | C17: RF-06 | D17: TC-06 UAT | E17: Según protocolo | F17: Según protocolo | G17: Aprobado | H17: M. Trujillo | I17: 46313
A18: TC-07 | B18: Carga | C18: RF-07 | D18: TC-07 Carga 20 usuarios | E18: Según protocolo | F18: Según protocolo | G18: Aprobado | H18: M. Trujillo | I18: 46313
A19: TC-08 | B19: Enlace | C19: RF-08 | D19: TC-08 Enlace a la noticia | E19: Según protocolo | F19: Según protocolo | G19: Aprobado | H19: M. Trujillo | I19: 46313
A20: TC-09 | B20: Caché | C20: RF-09 | D20: TC-09 Caché | E20: Según protocolo | F20: Según protocolo | G20: Aprobado | H20: M. Trujillo | I20: 46313
A21: TC-10 | B21: Exportación | C21: RF-10 | D21: TC-10 Exportación | E21: Según protocolo | F21: Según protocolo | G21: Aprobado | H21: M. Trujillo | I21: 46313
A38: Aprobados | C38: =COUNTIF(G12:G36,"Aprobado")
A39: Fallidos | C39: =COUNTIF(G12:G36,"Fallido")

Sheet 06_Registro_capacitacion
A1: UNIVERSIDAD DE HUÁNUCO · Programa Académico de Ingeniería de Sistemas e Informática · Seminario de Tesis III
A2: FORMATO 06 · REGISTRO DE CAPACITACIÓN
A3: Capacitación estandarizada: mismo contenido, duración e instructor para todo el GE
A6: Tesista: | B6: Trujillo Avila, Marcel Alexander Javier; Godoy Condezo, Alejandro Jeanpier
A7: Título de la tesis: | B7: Influencia de una aplicación multiplataforma de búsqueda semántica conversacional en la experiencia de lectores de Tu Diario Huánuco, 2026
A8: Institución / contexto: | B8: Tu Diario Huánuco (medio de comunicación digital), Huánuco
A9: Diseño: | B9: Preexperimental: G O1 X O2 (grupo único, pretest y postest)
A11: Puntaje mínimo aprobatorio del ejercicio (0-20): | E11: 14 | F11: ← valor sugerido por el docente; ajústalo a tu protocolo
A13: Código | B13: Grupo | C13: Fecha | D13: Hora inicio | E13: Hora fin | F13: Duración (min) | G13: Módulos recibidos | H13: Puntaje ejercicio (0-20) | I13: Resultado | J13: Firma / conformidad
A14: GU-TDH-002 | B14: GE | C14: 46312 | D14: 46312.417 | E14: 46312.434 | F14: =IF(OR(D14="",E14=""),"",ROUND((E14-D14)*1440,0)) | G14: Login, chat RAG, instalar PWA, módulo experimento | H14: 19 | I14: =IF(H14="","",IF(H14>=$E$11,"Aprobado","Recupera")) | J14: Conforme (digital)
A15: GU-TDH-003 | B15: GE | C15: 46312 | D15: 46312.669 | E15: 46312.686 | F15: =IF(OR(D15="",E15=""),"",ROUND((E15-D15)*1440,0)) | G15: Login, chat RAG, instalar PWA, módulo experimento | H15: 16 | I15: =IF(H15="","",IF(H15>=$E$11,"Aprobado","Recupera")) | J15: Conforme (digital)
A16: GU-TDH-004 | B16: GE | C16: 46312 | D16: 46312.421 | E16: 46312.438 | F16: =IF(OR(D16="",E16=""),"",ROUND((E16-D16)*1440,0)) | G16: Login, chat RAG, instalar PWA, módulo experimento | H16: 20 | I16: =IF(H16="","",IF(H16>=$E$11,"Aprobado","Recupera")) | J16: Conforme (digital)
A17: GU-TDH-006 | B17: GE | C17: 46312 | D17: 46312.673 | E17: 46312.69 | F17: =IF(OR(D17="",E17=""),"",ROUND((E17-D17)*1440,0)) | G17: Login, chat RAG, instalar PWA, módulo experimento | H17: 15 | I17: =IF(H17="","",IF(H17>=$E$11,"Aprobado","Recupera")) | J17: Conforme (digital)
A18: GU-TDH-007 | B18: GE | C18: 46312 | D18: 46312.425 | E18: 46312.442 | F18: =IF(OR(D18="",E18=""),"",ROUND((E18-D18)*1440,0)) | G18: Login, chat RAG, instalar PWA, módulo experimento | H18: 17 | I18: =IF(H18="","",IF(H18>=$E$11,"Aprobado","Recupera")) | J18: Conforme (digital)
A19: GU-TDH-008 | B19: GE | C19: 46312 | D19: 46312.677 | E19: 46312.694 | F19: =IF(OR(D19="",E19=""),"",ROUND((E19-D19)*1440,0)) | G19: Login, chat RAG, instalar PWA, módulo experimento | H19: 20 | I19: =IF(H19="","",IF(H19>=$E$11,"Aprobado","Recupera")) | J19: Conforme (digital)
A20: GU-TDH-009 | B20: GE | C20: 46312 | D20: 46312.429 | E20: 46312.447 | F20: =IF(OR(D20="",E20=""),"",ROUND((E20-D20)*1440,0)) | G20: Login, chat RAG, instalar PWA, módulo experimento | H20: 15 | I20: =IF(H20="","",IF(H20>=$E$11,"Aprobado","Recupera")) | J20: Conforme (digital)
A21: GU-TDH-010 | B21: GE | C21: 46312 | D21: 46312.681 | E21: 46312.699 | F21: =IF(OR(D21="",E21=""),"",ROUND((E21-D21)*1440,0)) | G21: Login, chat RAG, instalar PWA, módulo experimento | H21: 16 | I21: =IF(H21="","",IF(H21>=$E$11,"Aprobado","Recupera")) | J21: Conforme (digital)
A22: GU-TDH-011 | B22: GE | C22: 46312 | D22: 46312.433 | E22: 46312.451 | F22: =IF(OR(D22="",E22=""),"",ROUND((E22-D22)*1440,0)) | G22: Login, chat RAG, instalar PWA, módulo experimento | H22: 19 | I22: =IF(H22="","",IF(H22>=$E$11,"Aprobado","Recupera")) | J22: Conforme (digital)
A23: GU-TDH-012 | B23: GE | C23: 46312 | D23: 46312.685 | E23: 46312.703 | F23: =IF(OR(D23="",E23=""),"",ROUND((E23-D23)*1440,0)) | G23: Login, chat RAG, instalar PWA, módulo experimento | H23: 15 | I23: =IF(H23="","",IF(H23>=$E$11,"Aprobado","Recupera")) | J23: Conforme (digital)
A24: GU-TDH-014 | B24: GE | C24: 46312 | D24: 46312.438 | E24: 46312.455 | F24: =IF(OR(D24="",E24=""),"",ROUND((E24-D24)*1440,0)) | G24: Login, chat RAG, instalar PWA, módulo experimento | H24: 20 | I24: =IF(H24="","",IF(H24>=$E$11,"Aprobado","Recupera")) | J24: Conforme (digital)
A25: GU-TDH-015 | B25: GE | C25: 46312 | D25: 46312.69 | E25: 46312.707 | F25: =IF(OR(D25="",E25=""),"",ROUND((E25-D25)*1440,0)) | G25: Login, chat RAG, instalar PWA, módulo experimento | H25: 20 | I25: =IF(H25="","",IF(H25>=$E$11,"Aprobado","Recupera")) | J25: Conforme (digital)
... A44: GU-TDH-036 | B44: GE | C44: 46312 | D44: 46312.45 | E44: 46312.467 | F44: =IF(OR(D44="",E44=""),"",ROUND((E44-D44)*1440,0)) | G44: Login, chat RAG, instalar PWA, módulo experimento | H44: 16 | I44: =IF(H44="","",IF(H44>=$E$11,"Aprobado","Recupera")) | J44: Conforme (digital)
A45: GU-TDH-038 | B45: GE | C45: 46312 | D45: 46312.537 | E45: 46312.555 | F45: =IF(OR(D45="",E123=""),"",ROUND((E123-D45)*1440,0)) | G45: Login, chat RAG, instalar PWA, módulo experimento | H45: 18 | I45: =IF(H45="","",IF(H45>=$E$11,"Aprobado","Recupera")) | J45: Conforme (digital)
A46: GU-TDH-039 | B46: GE | C46: 46312 | D46: 46312.581 | E46: 46312.599 | F46: =IF(OR(D46="",E124=""),"",ROUND((E124-D46)*1440,0)) | G46: Login, chat RAG, instalar PWA, módulo experimento | H46: 19 | I46: =IF(H46="","",IF(H46>=$E$11,"Aprobado","Recupera")) | J46: Conforme (digital)
A47: GU-TDH-040 | B47: GE | C47: 46312 | D47: 46312.583 | E47: 46312.601 | F47: =IF(OR(D47="",E47=""),"",ROUND((E47-D47)*1440,0)) | G47: Login, chat RAG, instalar PWA, módulo experimento | H47: 15 | I47: =IF(H47="","",IF(H47>=$E$11,"Aprobado","Recupera")) | J47: Conforme (digital)
A48: GU-TDH-041 | B48: GE | C48: 46312 | D48: 46312.627 | E48: 46312.644 | F48: =IF(OR(D48="",E48=""),"",ROUND((E48-D48)*1440,0)) | G48: Login, chat RAG, instalar PWA, módulo experimento | H48: 16 | I48: =IF(H48="","",IF(H48>=$E$11,"Aprobado","Recupera")) | J48: Conforme (digital)
A49: GU-TDH-042 | B49: GE | C49: 46312 | D49: 46312.421 | E49: 46312.438 | F49: =IF(OR(D49="",E49=""),"",ROUND((E49-D49)*1440,0)) | G49: Login, chat RAG, instalar PWA, módulo experimento | H49: 17 | I49: =IF(H49="","",IF(H49>=$E$11,"Aprobado","Recupera")) | J49: Conforme (digital)
A50: GU-TDH-043 | B50: GE | C50: 46312 | D50: 46312.465 | E50: 46312.482 | F50: =IF(OR(D50="",E50=""),"",ROUND((E50-D50)*1440,0)) | G50: Login, chat RAG, instalar PWA, módulo experimento | H50: 18 | I50: =IF(H50="","",IF(H50>=$E$11,"Aprobado","Recupera")) | J50: Conforme (digital)
A51: GU-TDH-045 | B51: GE | C51: 46312 | D51: 46312.552 | E51: 46312.569 | F51: =IF(OR(D51="",E51=""),"",ROUND((E51-D51)*1440,0)) | G51: Login, chat RAG, instalar PWA, módulo experimento | H51: 15 | I51: =IF(H51="","",IF(H51>=$E$11,"Aprobado","Recupera")) | J51: Conforme (digital)
A52: GU-TDH-047 | B52: GE | C52: 46312 | D52: 46312.64 | E52: 46312.657 | F52: =IF(OR(D52="",E52=""),"",ROUND((E52-D52)*1440,0)) | G52: Login, chat RAG, instalar PWA, módulo experimento | H52: 17 | I52: =IF(H52="","",IF(H52>=$E$11,"Aprobado","Recupera")) | J52: Conforme (digital)
A53: GU-TDH-048 | B53: GE | C53: 46312 | D53: 46312.433 | E53: 46312.451 | F53: =IF(OR(D53="",E53=""),"",ROUND((E53-D53)*1440,0)) | G53: Login, chat RAG, instalar PWA, módulo experimento | H53: 18 | I53: =IF(H53="","",IF(H53>=$E$11,"Aprobado","Recupera")) | J53: Conforme (digital)
A54: GU-TDH-049 | B54: GE | C54: 46312 | D54: 46312.477 | E54: 46312.494 | F54: =IF(OR(D54="",E54=""),"",ROUND((E54-D54)*1440,0)) | G54: Login, chat RAG, instalar PWA, módulo experimento | H54: 19 | I54: =IF(H54="","",IF(H54>=$E$11,"Aprobado","Recupera")) | J54: Conforme (digital)
A55: GU-TDH-050 | B55: GE | C55: 46312 | D55: 46312.521 | E55: 46312.538 | F55: =IF(OR(D55="",E55=""),"",ROUND((E55-D55)*1440,0)) | G55: Login, chat RAG, instalar PWA, módulo experimento | H55: 15 | I55: =IF(H55="","",IF(H55>=$E$11,"Aprobado","Recupera")) | J55: Conforme (digital)
A56: GU-TDH-051 | B56: GE | C56: 46312 | D56: 46312.565 | E56: 46312.582 | F56: =IF(OR(D56="",E56=""),"",ROUND((E56-D56)*1440,0)) | G56: Login, chat RAG, instalar PWA, módulo experimento | H56: 16 | I56: =IF(H56="","",IF(H56>=$E$11,"Aprobado","Recupera")) | J56: Conforme (digital)
A57: GU-TDH-052 | B57: GE | C57: 46312 | D57: 46312.608 | E57: 46312.626 | F57: =IF(OR(D57="",E57=""),"",ROUND((E57-D57)*1440,0)) | G57: Login, chat RAG, instalar PWA, módulo experimento | H57: 17 | I57: =IF(H57="","",IF(H57>=$E$11,"Aprobado","Recupera")) | J57: Conforme (digital)
A58: GU-TDH-053 | B58: GE | C58: 46312 | D58: 46312.652 | E58: 46312.669 | F58: =IF(OR(D58="",E58=""),"",ROUND((E58-D58)*1440,0)) | G58: Login, chat RAG, instalar PWA, módulo experimento | H58: 18 | I58: =IF(H58="","",IF(H58>=$E$11,"Aprobado","Recupera")) | J58: Conforme (digital)
... A121: GU-TDH-125 | B121: GE | C121: 46312 | D121: 46312.635 | E121: 46312.653 | F121: =IF(OR(D121="",E121=""),"",ROUND((E121-D121)*1440,0)) | G121: Login, chat RAG, instalar PWA, módulo experimento | H121: 15 | I121: =IF(H121="","",IF(H121>=$E$11,"Aprobado","Recupera")) | J121: Conforme (digital)
A123: Participantes del GE previstos: | E123: 108
A124: Capacitados (con registro): | E124: =COUNTIFS(B14:B121,"GE",F14:F121,">0")
A125: % del GE capacitado: | E125: =IF(N(E123)=0,0,E124/E123)
...

Sheet 07_Registro_incidencias
A1: UNIVERSIDAD DE HUÁNUCO · Programa Académico de Ingeniería de Sistemas e Informática · Seminario de Tesis III
A2: FORMATO 07 · REGISTRO DE INCIDENCIAS Y SOPORTE INICIAL
A3: Crítica < 2 h · Alta < 8 h · Media < 24 h · Baja < 72 h (tiempos de respuesta sugeridos)
A6: Tesista: | B6: Trujillo Avila, Marcel Alexander Javier; Godoy Condezo, Alejandro Jeanpier
A7: Título de la tesis: | B7: Influencia de una aplicación multiplataforma de búsqueda semántica conversacional en la experiencia de lectores de Tu Diario Huánuco, 2026
A8: Institución / contexto: | B8: Tu Diario Huánuco (medio de comunicación digital), Huánuco
A9: Diseño: | B9: Preexperimental: G O1 X O2 (grupo único, pretest y postest)
A11: ID | B11: Fecha y hora de reporte | C11: Código participante | D11: Prioridad | E11: Tipo | F11: Descripción | G11: Acción correctiva | H11: Fecha y hora de cierre | I11: Tiempo de resolución (h) | J11: Estado | K11: Responsable
A12: INC-01 | B12: 46313.799 | C12: GU-TDH-004 | D12: Media | E12: Acceso | F12: El service worker no cargaba la PWA. | G12: Reinstalar la PWA. | H12: 46313.819 | I12: =IF(OR(B12="",H12=""),"",ROUND((H12-B12)*24,1)) | J12: Cerrada | K12: A. Godoy
A13: INC-02 | B13: 46314.427 | C13: GU-TDH-010 | D13: Baja | E13: Uso | F13: Duda sobre cómo leer las citas del chat. | G13: Reenvío de la guía rápida. | H13: 46314.436 | I13: =IF(OR(B13="",H13=""),"",ROUND((H13-B13)*24,1)) | J13: Cerrada | K13: M. Trujillo
A14: INC-03 | B14: 46314.431 | C14: GU-TDH-006 | D14: Baja | E14: Acceso | F14: No abría el chat. | G14: Se envió el enlace directo. | H14: 46314.441 | I14: =IF(OR(B14="",H14=""),"",ROUND((H14-B14)*24,1)) | J14: Cerrada | K14: A. Godoy
A15: INC-04 | B15: 46315.67 | C15: Todos | D15: Alta | E15: Disponibilidad | F15: Latencia de Gemini mayor a 8 s. | G15: Se activó la caché de Redis. | H15: 46315.722 | I15: =IF(OR(B15="",H15=""),"",ROUND((H15-B15)*24,1)) | J15: Cerrada | K15: M. Trujillo
A16: INC-05 | B16: 46316.5 | C16: GU-TDH-015 | D16: Baja | E16: Seguimiento | F16: Sin accesos después del inicio. | G16: Recordatorio. Luego quedó como retiro. | H16: 46316.517 | I16: =IF(OR(B16="",H16=""),"",ROUND((H16-B16)*24,1)) | J16: Cerrada | K16: A. Godoy
A17: INC-06 | B17: 46317.46 | C17: GU-TDH-020 | D17: Baja | E17: Cuenta | F17: Olvidó el código de acceso. | G17: Reenvío del código por WhatsApp. | H17: 46317.465 | I17: =IF(OR(B17="",H17=""),"",ROUND((H17-B17)*24,1)) | J17: Cerrada | K17: A. Godoy
A18: INC-07 | B18: 46319.41 | C18: GU-TDH-025 | D18: Baja | E18: Acceso | F18: No lograba instalar la PWA en iOS. | G18: Mismo instructivo para todos. | H18: 46319.424 | I18: =IF(OR(B18="",H18=""),"",ROUND((H18-B18)*24,1)) | J18: Cerrada | K18: A. Godoy
I19: =IF(OR(B19="",H19=""),"",ROUND((H19-B19)*24,1))
I20: =IF(OR(B20="",H20=""),"",ROUND((H20-B20)*24,1))
I21: =IF(OR(B21="",H21=""),"",ROUND((H21-B21)*24,1))
I22: =IF(OR(B22="",H22=""),"",ROUND((H22-B22)*24,1))
I23: =IF(OR(B23="",H23=""),"",ROUND((H23-B23)*24,1))
I24: =IF(OR(B24="",H24=""),"",ROUND((H24-B24)*24,1))
I25: =IF(OR(B25="",H25=""),"",ROUND((H25-B25)*24,1))
I26: =IF(OR(B26="",H26=""),"",ROUND((H26-B26)*24,1))
I27: =IF(OR(B27="",H27=""),"",ROUND((H27-B27)*24,1))
I28: =IF(OR(B28="",H28=""),"",ROUND((H28-B28)*24,1))
I29: =IF(OR(B29="",H29=""),"",ROUND((H29-B29)*24,1))
I30: =IF(OR(B30="",H30=""),"",ROUND((H30-B30)*24,1))
... I51: =IF(OR(B51="",H51=""),"",ROUND((H51-B51)*24,1))
A53: Incidencias abiertas | C53: =COUNTIF(J12:J51,"Abierta")+COUNTIF(J12:J51,"En atención")
A54: Críticas abiertas | C54: =COUNTIFS(D12:D51,"Crítica",J12:J51,"<>Cerrada",A12:A51,"<>")
A55: Este registro es insumo de la Sesión 6 (fidelidad y control de incidencias). Toda corrección durante la intervención debe registrarse aquí; no se permiten cambios funcionales.

Sheet 08_Protocolo_condiciones
A1: UNIVERSIDAD DE HUÁNUCO · Programa Académico de Ingeniería de Sistemas e Informática · Seminario de Tesis III
A2: FORMATO 08 · PROTOCOLO DE INTERVENCIÓN Y CONDICIONES DE USO
A3: Define la «dosis» de X y deja constancia de las condiciones comunicadas
A6: A. DOSIS DE LA INTERVENCIÓN
A7: Parámetro | B7: Valor definido | C7: Unidad | D7: Cómo se registrará
A8: Duración total de la intervención | B8: 7 | C8: días | D8: Cronograma de la Sesión 1
A9: Frecuencia de uso esperada | B9: Al menos 3 sesiones en 7 días | C9: sesiones | D9: Logs
A10: Intensidad por sesión | B10: Al menos 10 minutos o 1 consulta RAG | C10: minutos | D10: Logs
A11: Fecha de inicio (T₀) | B11: 46314.375 | C11: fecha | D11: Acta de inicio
A12: Fecha prevista de cierre | B12: 46320.999 | C12: fecha | D12: Acta de cierre (S7)
A14: B. CONDICIONES DE USO COMUNICADAS
A15: Condición | B15: ¿Comunicada? | C15: Medio | D15: Fecha
A16: Horario de disponibilidad del sistema | B16: Sí | C16: WhatsApp y guía rápida | D16: 46313
A17: Tareas que realizará cada participante | B17: Sí | C17: WhatsApp y guía rápida | D17: 46313
A18: Canal y horario de soporte | B18: Sí | C18: WhatsApp y guía rápida | D18: 46313
A19: Duración de la intervención | B19: Sí | C19: WhatsApp y guía rápida | D19: 46313
A20: Datos que se registrarán (logs) | B20: Sí | C20: WhatsApp y guía rápida | D20: 46313
A21: Confidencialidad y uso de códigos | B21: Sí | C21: WhatsApp y guía rápida | D21: 46313
A22: No compartir cuentas ni contraseñas | B22: Sí | C22: WhatsApp y guía rápida | D22: 46313
A23: Derecho a retirarse sin perjuicio | B23: Sí | C23: WhatsApp y guía rápida | D23: 46313
A25: Condiciones comunicadas | B25: =COUNTIF(B16:B23,"Sí")&" de 8"

Sheet 09_Acta_inicio_T0
A1: UNIVERSIDAD DE HUÁNUCO · Programa Académico de Ingeniería de Sistemas e Informática · Seminario de Tesis III
A2: FORMATO 09 · ACTA DE INICIO DE LA INTERVENCIÓN (T₀)
A3: Registro formal del inicio de la variable independiente X
A6: Título de la tesis: | B6: Influencia de una aplicación multiplataforma de búsqueda semántica conversacional en la experiencia de lectores de Tu Diario Huánuco, 2026
A7: Tesista: | B7: Trujillo Avila, Marcel Alexander Javier; Godoy Condezo, Alejandro Jeanpier
A8: Institución / área: | B8: Tu Diario Huánuco (medio de comunicación digital), Huánuco
A9: Diseño de investigación: | B9: Preexperimental: G O1 X O2 (grupo único, pretest y postest)
A10: Solución tecnológica y versión: | B10: Aplicación multiplataforma de búsqueda semántica conversacional (PWA + RAG) — v1.0.0-frozen-2026-10-18
A11: Fecha de inicio (T₀): | B11: 46314.375
A12: Hora de inicio: | B12: 09:00
A13: Lugar: | B13: Remoto, dispositivo del participante
A14: Participantes del GE (códigos): | B14: 108 participantes del pretest (GU-TDH-002 a GU-TDH-125, sin GU-TDH-001).
A15: Grupo de comparación (códigos, si aplica): | B15: No aplica: grupo único
A16: Capacitación completada (% GE): | B16: ='06_Registro_capacitacion'!E125
A17: Condiciones de uso comunicadas: | B17: ='08_Protocolo_condiciones'!B25
A18: Soporte asignado (canal y horario): | B18: WhatsApp del estudio · Lun–Sáb 10:00–13:00 y 16:00–19:00
A19: Observaciones: | B19: Simulación de seminario, no es campo real. Los 108 códigos son los del pretest (sesiones 2 y 3). En las plantillas 4, 5 y 7 el grupo único se registra como GE; no hay GC. Tres retiros durante X: GU-TDH-015, GU-TDH-033 y GU-TDH-053.
A21: Se deja constancia de que la solución se encuentra operativa, configurada y accesible, y que se da inicio formal a la intervención conforme al protocolo aprobado.
A25: ______________________ | C25: ______________________ | E25: ______________________
A26: Tesista | C26: Responsable de la institución | E26: Asesor de tesis
A27: Nombre / DNI / Firma | C27: Nombre / DNI / Firma | E27: Nombre / DNI / Firma

Sheet 10_Rubrica_informe
A1: UNIVERSIDAD DE HUÁNUCO · Programa Académico de Ingeniería de Sistemas e Informática · Seminario de Tesis III
A2: FORMATO 10 · RÚBRICA DEL INFORME INICIAL
A3: Escala vigesimal · Logrado 17-20 · En proceso 11-16 · Inicio 0-10
A6: Tesista: | B6: Trujillo Avila, Marcel Alexander Javier; Godoy Condezo, Alejandro Jeanpier
A7: Título de la tesis: | B7: Influencia de una aplicación multiplataforma de búsqueda semántica conversacional en la experiencia de lectores de Tu Diario Huánuco, 2026
A8: Institución / contexto: | B8: Tu Diario Huánuco (medio de comunicación digital), Huánuco
A9: Diseño: | B9: Preexperimental: G O1 X O2 (grupo único, pretest y postest)
A11: Criterio | B11: Evidencia exigida | C11: Puntaje máximo | D11: Puntaje obtenido | E11: % logro
A12: Solución operativa, configurada y accesible | B12: Acta de instalación, URL o versión, ficha funcional | C12: 5 | D12: 5 | E12: =IF(D12="","",D12/C12)
A13: Seguridad, usuarios y roles | B13: Matriz de roles, controles de seguridad | C13: 3 | D13: 3 | E13: =IF(D13="","",D13/C13)
A14: Capacitación documentada | B14: Registro de capacitación y materiales | C14: 4 | D14: 4 | E14: =IF(D14="","",D14/C14)
A15: Protocolo y registro formal de inicio | B15: Dosis definida, condiciones y acta T₀ | C15: 5 | D15: 5 | E15: =IF(D15="","",D15/C15)
A16: Redacción y evidencias | B16: Informe ordenado, códigos, capturas sin datos personales | C16: 3 | D16: 3 | E16: =IF(D16="","",D16/C16)
A17: TOTAL | C17: =SUM(C12:C16) | D17: =SUM(D12:D16)
A18: Nivel de logro | D18: =IF(COUNT(D12:D16)=0,"",IF(D17>=17,"Logrado",IF(D17>=11,"En proceso","Inicio")))
A20: Pesos sugeridos por el docente (suman 20). Ingresa el puntaje obtenido en cada criterio sin exceder el máximo.

Sheet 11_Resumen
A1: UNIVERSIDAD DE HUÁNUCO · Programa Académico de Ingeniería de Sistemas e Informática · Seminario de Tesis III
A2: FORMATO 11 · TABLERO: ¿ESTOY LISTO PARA T₀?
A3: Se actualiza automáticamente con los formatos anteriores
A6: Indicador | B6: Valor | C6: Meta | D6: Estado
A7: Lista de cotejo cumplida | B7: ='01_Lista_cotejo'!C24 | C7: 1 | D7: =IF(B7>=C7,"✔ Cumple","✘ Pendiente")
A8: Requisitos críticos conformes | B8: ='04_Verificacion_funcional'!C35 | C8: 1 | D8: =IF(B8>=C8,"✔ Cumple","✘ Pendiente")
A9: GE capacitado | B9: ='06_Registro_capacitacion'!E125 | C9: 1 | D9: =IF(B9>=C9,"✔ Cumple","✘ Pendiente")
A10: Condiciones de uso comunicadas (de 8) | B10: =COUNTIF('08_Protocolo_condiciones'!B16:B23,"Sí") | C10: 8 | D10: =IF(B10>=C10,"✔ Cumple","✘ Pendiente")
A11: Incidencias críticas abiertas | B11: ='07_Registro_incidencias'!C54 | C11: 0 | D11: =IF(B11=C11,"✔ Cumple","✘ Pendiente")
A13: =IF(COUNTIF(D7:D11,"✔*")=5,"✔ LISTO PARA INICIAR LA INTERVENCIÓN (T₀)","✘ AÚN NO: completa los indicadores pendientes")
A16: Puntaje de autoevaluación del informe inicial | B16: ='10_Rubrica_informe'!D17 | C16: de 20
